Workbook
Name bimbing1: [1]Daftar!$Q$337:$Q$419
Name bimbing1: Daftar!$Q$315:$Q$397
Name bimbing2: [1]Daftar!$R$337:$R$419
Name bimbing2: Daftar!$R$315:$R$397
Name data: [2]Daftar!$A$5:$U$516
Name data: Daftar!$A$4:$AG$1724
Name dosen: 'Dosen JTE'!$A$5:$E$59
Name dosen: 'Dosen JTE (2)'!$A$5:$E$59
Name dosen: '[2]Dosen JTE'!$A$5:$E$53
Name dosen: rekap!$A$6:$F$45
Name dosen: 'Dosen JTE'!$A$5:$E$60
Name MHS: [3]MHS!$B$3:$C$774
Name penguji: [1]Daftar!$S$4:$U$246
Name penguji: Daftar!$S$4:$U$229

Sheet 000000000

Sheet Daftar
A1: DAFTAR SEMINAR PROPOSAL TUGAS AKHIR PERIODE TAHUN 2010 JURUSAN TEKNIK ELEKTRO FT UNRAM
A3: NO. | B3: TGL SURAT | C3: NAMA | D3: NIM | E3: JUDUL PROPOSAL TUGAS AKHIR | F3: PEMBIMBING 1 | G3: PEMBIMBING 2 | H3: PENGUJI 1 | I3: PENGUJI 2 | J3: PENGUJI 3 | K3: HARI | L3: TANGGAL | M3: WAKTU | N3: TEMPAT | P3: No. Srt Undangan | Q3: 1 | R3: 2 | S3: 3 | T3: 4 | U3: 5 | W3: TGL VALUE | X3: KBK | Y3: DOSEN PA | Z3: MULAI TA | AA3: AKHIR TA | AB3: PERPANJANGAN | AC3: KET | AM3: Hasil | AN3: Ujian | AS3: NAMA | AT3: NIM | AU3: NO.
A4: 1 | C4: =VLOOKUP(D4,'[4]mhs elektro-kecil'!$B$5:$C$1847,2,0) -> Muh. Azhari Zulfani | D4: F1B005048 | E4: Teknik Kompresi Menggunakan Algoritma LZ77 dengan Metode Pencarian Kamus Berbasis Queue untuk Kompresi Teks | F4: Dr. Rismon H. Sianipar, S.T., M.Eng. | G4: Budi Irmawati, S. Kom., M.T. | H4: I B K Widiartha, S.T., M.T. | I4: Heri Wijayanto, S.T., M.T. | J4: Muhamad Irwan, S.T., M.T. | K4: Kamis | L4: 40227 | M4: 10.00-12.00 | O4: Lulus | Q4: 33 | R4: 20 | S4: 27 | T4: 32 | U4: 39 | W4: =TEXT(L4,"dd mmmm yyyy") -> 18 Februari 2010 | X4: =IFERROR(VLOOKUP(D4,'[5]mhs elektro-kecil'!$B$5:$E$2500,3,0),"CEK") -> CEK | Y4: =IFERROR(VLOOKUP(D4,'[5]mhs elektro-kecil'!$B$5:$E$2500,4,0),"CEK") -> CEK | Z4: =L4 -> 40227 | AA4: =Z4+180 -> 40407 | AC4: Lulus | AI4: =MID(D4,5,2) -> 05 | AL4: =IF(MID(D4,5,2)="06",2006,IF(MID(D4,5,2)="07",2007,IF(MID(D4,5,2)="08",2008,IF(MID(D4,5,2)="09",2009,IF(MID(D4,5,2)="10",2010,IF(MID(D4,5,2)="11",2011,IF(MID(D4,5,2)="12",2012,IF(MID(D4,5,2)="05",2005,IF(MID(D4,5,2)="04",2004,IF(MID(D4,5,2)="03",2003,IF(MID(D4,5,2)="13",2013,IF(MID(D4,5,2)="14",2014,IF(MID(D4,5,2)="15",2015,IF(MID(D4,5,2)="16",2016,IF(MID(D4,5,2)="17",2017,IF(MID(D4,5,2)="18",2018,2019)))))))))))))))) -> 2005 | AM4: =COUNTIF([6]Daftar!$D$5:$D$851,D4) -> #VALUE! | AN4: =COUNTIF([7]daftar!$D$4:$D$885,D4) -> #VALUE! | AS4: =C4 -> Muh. Azhari Zulfani | AT4: =D4 -> F1B005048 | AU4: =A4 -> 1
A5: =A4+1 -> 2 | C5: =VLOOKUP(D5,'[4]mhs elektro-kecil'!$B$5:$C$1847,2,0) -> Dea Nur Asri | D5: F1B005010 | E5: Analisa Keandalan Sistem Pembangkit Interkoneksi (Studi Kasus PLTD Ampenan dan PLTD Paok Motong) | F5: Agung Budi Muljono, S.T., M.T. | G5: Supriyatna, S.T., M.T. | H5: Sabar Nababan, S.T., M.T. | I5: Muhammad Firad, S.T. | J5: Ni Made Seniari, S.T., M.T. | K5: Kamis | L5: 40227 | M5: 08.00-10.00 | O5: Lulus | Q5: 13 | R5: 2 | S5: 31 | T5: 11 | U5: 1 | W5: =TEXT(L5,"dd mmmm yyyy") -> 18 Februari 2010 | X5: =IFERROR(VLOOKUP(D5,'[5]mhs elektro-kecil'!$B$5:$E$2500,3,0),"CEK") -> CEK | Y5: =IFERROR(VLOOKUP(D5,'[5]mhs elektro-kecil'!$B$5:$E$2500,4,0),"CEK") -> CEK | Z5: =L5 -> 40227 | AA5: =Z5+180 -> 40407 | AC5: Lulus | AI5: =MID(D5,5,2) -> 05 | AL5: =IF(MID(D5,5,2)="06",2006,IF(MID(D5,5,2)="07",2007,IF(MID(D5,5,2)="08",2008,IF(MID(D5,5,2)="09",2009,IF(MID(D5,5,2)="10",2010,IF(MID(D5,5,2)="11",2011,IF(MID(D5,5,2)="12",2012,IF(MID(D5,5,2)="05",2005,IF(MID(D5,5,2)="04",2004,IF(MID(D5,5,2)="03",2003,IF(MID(D5,5,2)="13",2013,IF(MID(D5,5,2)="14",2014,IF(MID(D5,5,2)="15",2015,IF(MID(D5,5,2)="16",2016,IF(MID(D5,5,2)="17",2017,IF(MID(D5,5,2)="18",2018,2019)))))))))))))))) -> 2005 | AM5: =COUNTIF([6]Daftar!$D$5:$D$851,D5) -> #VALUE! | AN5: =COUNTIF([7]daftar!$D$4:$D$885,D5) -> #VALUE! | AS5: =C5 -> Dea Nur Asri | AT5: =D5 -> F1B005010 | AU5: =A5 -> 2
A6: =A5+1 -> 3 | C6: =VLOOKUP(D6,'[4]mhs elektro-kecil'!$B$5:$C$1847,2,0) -> Fitria Husniayati | D6: F1B005018 | E6: Analisis dan Simulasi Perbaikan Kualitas Daya pada Inverter Merk Usat dengan Pemasangan Filter Pasif | F6: I Made Ari Nrartha, S.T., M.T. | G6: Dr. Warindi, S.T., M.Eng. | H6: Rosmaliati, S.T., M.T. | I6: I Ketut Perdana Putra, S.T., M.T. | J6: Abdullah Zainuddin, S.T., M.T. | K6: Kamis | L6: 40227 | M6: 10.00-12.00 | O6: Lulus | Q6: 25 | R6: 37 | S6: 16 | T6: 23 | U6: 15 | W6: =TEXT(L6,"dd mmmm yyyy") -> 18 Februari 2010 | X6: =IFERROR(VLOOKUP(D6,'[5]mhs elektro-kecil'!$B$5:$E$2500,3,0),"CEK") -> CEK | Y6: =IFERROR(VLOOKUP(D6,'[5]mhs elektro-kecil'!$B$5:$E$2500,4,0),"CEK") -> CEK | Z6: =L6 -> 40227 | AA6: =Z6+180 -> 40407 | AC6: Lulus | AI6: =MID(D6,5,2) -> 05 | AL6: =IF(MID(D6,5,2)="06",2006,IF(MID(D6,5,2)="07",2007,IF(MID(D6,5,2)="08",2008,IF(MID(D6,5,2)="09",2009,IF(MID(D6,5,2)="10",2010,IF(MID(D6,5,2)="11",2011,IF(MID(D6,5,2)="12",2012,IF(MID(D6,5,2)="05",2005,IF(MID(D6,5,2)="04",2004,IF(MID(D6,5,2)="03",2003,IF(MID(D6,5,2)="13",2013,IF(MID(D6,5,2)="14",2014,IF(MID(D6,5,2)="15",2015,IF(MID(D6,5,2)="16",2016,IF(MID(D6,5,2)="17",2017,IF(MID(D6,5,2)="18",2018,2019)))))))))))))))) -> 2005 | AM6: =COUNTIF([6]Daftar!$D$5:$D$851,D6) -> #VALUE! | AN6: =COUNTIF([7]daftar!$D$4:$D$885,D6) -> #VALUE! | AS6: =C6 -> Fitria Husniayati | AT6: =D6 -> F1B005018 | AU6: =A6 -> 3
A7: =A6+1 -> 4 | C7: 7442 | D7: F1B005001 | E7: Pengaturan Kecepatan Motor DC Shunt dengan Buck Converter Menggunakan Metode Pulse Width Modulation Berbasis Mikrokontroler ATMEGA 8535 | F7: I Made Budi Suksmadana, S.T., M.T. | G7: I Made Ari Nrartha, S.T., M.T. | H7: Ida Bagus Fery Citarsa, S.T., M.T. | I7: Abdul Natsir, S.T., M.T. | J7: Bulkis Kanata, S.T., M.T. | K7: Jum'at | L7: 40228 | M7: 08.00-10.00 | O7: Lulus | Q7: 24 | R7: 25 | S7: 12 | T7: 14 | U7: 21 | W7: =TEXT(L7,"dd mmmm yyyy") -> 19 Februari 2010 | X7: =IFERROR(VLOOKUP(D7,'[5]mhs elektro-kecil'!$B$5:$E$2500,3,0),"CEK") -> CEK | Y7: =IFERROR(VLOOKUP(D7,'[5]mhs elektro-kecil'!$B$5:$E$2500,4,0),"CEK") -> CEK | Z7: =L7 -> 40228 | AA7: =Z7+180 -> 40408 | AC7: Lulus | AI7: =MID(D7,5,2) -> 05 | AL7: =IF(MID(D7,5,2)="06",2006,IF(MID(D7,5,2)="07",2007,IF(MID(D7,5,2)="08",2008,IF(MID(D7,5,2)="09",2009,IF(MID(D7,5,2)="10",2010,IF(MID(D7,5,2)="11",2011,IF(MID(D7,5,2)="12",2012,IF(MID(D7,5,2)="05",2005,IF(MID(D7,5,2)="04",2004,IF(MID(D7,5,2)="03",2003,IF(MID(D7,5,2)="13",2013,IF(MID(D7,5,2)="14",2014,IF(MID(D7,5,2)="15",2015,IF(MID(D7,5,2)="16",2016,IF(MID(D7,5,2)="17",2017,IF(MID(D7,5,2)="18",2018,2019)))))))))))))))) -> 2005 | AM7: =COUNTIF([6]Daftar!$D$5:$D$851,D7) -> #VALUE! | AN7: =COUNTIF([7]daftar!$D$4:$D$885,D7) -> #VALUE! | AS7: =C7 -> 7442 | AT7: =D7 -> F1B005001 | AU7: =A7 -> 4
A8: =A7+1 -> 5 | C8: =VLOOKUP(D8,'[4]mhs elektro-kecil'!$B$5:$C$1847,2,0) -> Fahri Alamsyah | D8: F1B003020 | E8: Rancang Bangun Pengatur Intesitas Cahaya Lampu Menggunakan Remote Control Infra Merah | F8: Paniran, S.T., M.T. | G8: Dr. Warindi, S.T., M.Eng. | H8: Sultan, S.T., M.T. | I8: I Ketut Wiryajati, S.T., M.T. | J8: Muhamad Syamsu Iqbal, S.T., M.T., Ph.D. | K8: Sabtu | L8: 40229 | M8: 10.00-12.00 | O8: Lulus | Q8: 28 | R8: 37 | S8: 5 | T8: 3 | U8: 18 | W8: =TEXT(L8,"dd mmmm yyyy") -> 20 Februari 2010 | X8: =IFERROR(VLOOKUP(D8,'[5]mhs elektro-kecil'!$B$5:$E$2500,3,0),"CEK") -> CEK | Y8: =IFERROR(VLOOKUP(D8,'[5]mhs elektro-kecil'!$B$5:$E$2500,4,0),"CEK") -> CEK | Z8: =L8 -> 40229 | AA8: =Z8+180 -> 40409 | AC8: Lulus | AI8: =MID(D8,5,2) -> 03 | AL8: =IF(MID(D8,5,2)="06",2006,IF(MID(D8,5,2)="07",2007,IF(MID(D8,5,2)="08",2008,IF(MID(D8,5,2)="09",2009,IF(MID(D8,5,2)="10",2010,IF(MID(D8,5,2)="11",2011,IF(MID(D8,5,2)="12",2012,IF(MID(D8,5,2)="05",2005,IF(MID(D8,5,2)="04",2004,IF(MID(D8,5,2)="03",2003,IF(MID(D8,5,2)="13",2013,IF(MID(D8,5,2)="14",2014,IF(MID(D8,5,2)="15",2015,IF(MID(D8,5,2)="16",2016,IF(MID(D8,5,2)="17",2017,IF(MID(D8,5,2)="18",2018,2019)))))))))))))))) -> 2003 | AM8: =COUNTIF([6]Daftar!$D$5:$D$851,D8) -> #VALUE! | AN8: =COUNTIF([7]daftar!$D$4:$D$885,D8) -> #VALUE! | AS8: =C8 -> Fahri Alamsyah | AT8: =D8 -> F1B003020 | AU8: =A8 -> 5
A9: =A8+1 -> 6 | C9: =VLOOKUP(D9,'[4]mhs elektro-kecil'!$B$5:$C$1847,2,0) -> Sri Kurniawati | D9: F1B005070 | E9: Merancang dan membuat Aplikasi Game Edukasi untuk Siswa Sekolah Dasar, Studi Kasus pada Mata Pelajaran Bahasa Indonesia | F9: Heri Wijayanto, S.T., M.T. | G9: Ir. Sri Endang Anjarwani, M.Kom. | H9: Dr. Misbahuddin, S.T., M.T. | I9: Sudi M. Al Sasongko, S.T., M.T. | J9: Dr. Ida Ayu Sri Adnyani, S.T., M.Erg. | K9: Sabtu | L9: 40229 | M9: 08.00-10.00 | O9: Lulus | Q9: 32 | R9: 38 | S9: 7 | T9: 6 | U9: 10 | W9: =TEXT(L9,"dd mmmm yyyy") -> 20 Februari 2010 | X9: =IFERROR(VLOOKUP(D9,'[5]mhs elektro-kecil'!$B$5:$E$2500,3,0),"CEK") -> CEK | Y9: =IFERROR(VLOOKUP(D9,'[5]mhs elektro-kecil'!$B$5:$E$2500,4,0),"CEK") -> CEK | Z9: =L9 -> 40229 | AA9: =Z9+180 -> 40409 | AC9: Lulus | AI9: =MID(D9,5,2) -> 05 | AL9: =IF(MID(D9,5,2)="06",2006,IF(MID(D9,5,2)="07",2007,IF(MID(D9,5,2)="08",2008,IF(MID(D9,5,2)="09",2009,IF(MID(D9,5,2)="10",2010,IF(MID(D9,5,2)="11",2011,IF(MID(D9,5,2)="12",2012,IF(MID(D9,5,2)="05",2005,IF(MID(D9,5,2)="04",2004,IF(MID(D9,5,2)="03",2003,IF(MID(D9,5,2)="13",2013,IF(MID(D9,5,2)="14",2014,IF(MID(D9,5,2)="15",2015,IF(MID(D9,5,2)="16",2016,IF(MID(D9,5,2)="17",2017,IF(MID(D9,5,2)="18",2018,2019)))))))))))))))) -> 2005 | AM9: =COUNTIF([6]Daftar!$D$5:$D$851,D9) -> #VALUE! | AN9: =COUNTIF([7]daftar!$D$4:$D$885,D9) -> #VALUE! | AS9: =C9 -> Sri Kurniawati | AT9: =D9 -> F1B005070 | AU9: =A9 -> 6
A10: =A9+1 -> 7 | C10: =VLOOKUP(D10,'[4]mhs elektro-kecil'!$B$5:$C$1847,2,0) -> Faisaludin | D10: F1B005016 | E10: Rancang Bangun Voltage Source Inverter (VSI) untuk Aplikasi Pembangkit Listrik Tenaga Surya (PLTS) | F10: Dr. Warindi, S.T., M.Eng. | G10: I Made Ari Nrartha, S.T., M.T. | H10: Syafarudin Ch, S.T., M.T. | I10: Supriono, S.T., M.T. | J10: I Made Budi Suksmadana, S.T., M.T. | K10: Sabtu | L10: 40229 | M10: 08.00-10.00 | O10: Lulus | Q10: 37 | R10: 25 | S10: 4 | T10: 29 | U10: 24 | W10: =TEXT(L10,"dd mmmm yyyy") -> 20 Februari 2010 | X10: =IFERROR(VLOOKUP(D10,'[5]mhs elektro-kecil'!$B$5:$E$2500,3,0),"CEK") -> CEK | Y10: =IFERROR(VLOOKUP(D10,'[5]mhs elektro-kecil'!$B$5:$E$2500,4,0),"CEK") -> CEK | Z10: =L10 -> 40229 | AA10: =Z10+180 -> 40409 | AB10: =AA10+180 -> 40589 | AD10: 40589 | AI10: =MID(D10,5,2) -> 05 | AL10: =IF(MID(D10,5,2)="06",2006,IF(MID(D10,5,2)="07",2007,IF(MID(D10,5,2)="08",2008,IF(MID(D10,5,2)="09",2009,IF(MID(D10,5,2)="10",2010,IF(MID(D10,5,2)="11",2011,IF(MID(D10,5,2)="12",2012,IF(MID(D10,5,2)="05",2005,IF(MID(D10,5,2)="04",2004,IF(MID(D10,5,2)="03",2003,IF(MID(D10,5,2)="13",2013,IF(MID(D10,5,2)="14",2014,IF(MID(D10,5,2)="15",2015,IF(MID(D10,5,2)="16",2016,IF(MID(D10,5,2)="17",2017,IF(MID(D10,5,2)="18",2018,2019)))))))))))))))) -> 2005 | AM10: =COUNTIF([6]Daftar!$D$5:$D$851,D10) -> #VALUE! | AN10: =COUNTIF([7]daftar!$D$4:$D$885,D10) -> #VALUE! | AS10: =C10 -> Faisaludin | AT10: =D10 -> F1B005016 | AU10: =A10 -> 7
A11: =A10+1 -> 8 | C11: =VLOOKUP(D11,'[4]mhs elektro-kecil'!$B$5:$C$1847,2,0) -> Agra Ananggadipa | D11: F1B005003 | E11: Penggunaan Algoritma Partikel Swarm Optimization Untuk Optimasi Luas Penampang Konduktor pada Jaringan Distribusi Radial Penyulang Airlangga | F11: Rosmaliati, S.T., M.T. | G11: Dr. Misbahuddin, S.T., M.T. | H11: Agung Budi Muljono, S.T., M.T. | I11: Abdul Natsir, S.T., M.T. | J11: Supriyatna, S.T., M.T. | K11: Rabu | L11: 40233 | M11: 08.00-10.00 | O11: Lulus | Q11: 16 | R11: 7 | S11: 13 | T11: 14 | U11: 2 | W11: =TEXT(L11,"dd mmmm yyyy") -> 24 Februari 2010 | X11: =IFERROR(VLOOKUP(D11,'[5]mhs elektro-kecil'!$B$5:$E$2500,3,0),"CEK") -> CEK | Y11: =IFERROR(VLOOKUP(D11,'[5]mhs elektro-kecil'!$B$5:$E$2500,4,0),"CEK") -> CEK | Z11: =L11 -> 40233 | AA11: =Z11+180 -> 40413 | AC11: Lulus | AI11: =MID(D11,5,2) -> 05 | AL11: =IF(MID(D11,5,2)="06",2006,IF(MID(D11,5,2)="07",2007,IF(MID(D11,5,2)="08",2008,IF(MID(D11,5,2)="09",2009,IF(MID(D11,5,2)="10",2010,IF(MID(D11,5,2)="11",2011,IF(MID(D11,5,2)="12",2012,IF(MID(D11,5,2)="05",2005,IF(MID(D11,5,2)="04",2004,IF(MID(D11,5,2)="03",2003,IF(MID(D11,5,2)="13",2013,IF(MID(D11,5,2)="14",2014,IF(MID(D11,5,2)="15",2015,IF(MID(D11,5,2)="16",2016,IF(MID(D11,5,2)="17",2017,IF(MID(D11,5,2)="18",2018,2019)))))))))))))))) -> 2005 | AM11: =COUNTIF([6]Daftar!$D$5:$D$851,D11) -> #VALUE! | AN11: =COUNTIF([7]daftar!$D$4:$D$885,D11) -> #VALUE! | AS11: =C11 -> Agra Ananggadipa | AT11: =D11 -> F1B005003 | AU11: =A11 -> 8
A12: =A11+1 -> 9 | C12: =VLOOKUP(D12,'[4]mhs elektro-kecil'!$B$5:$C$1847,2,0) -> Qitmir Hayatullah | D12: F1B003052 | E12: Perhitungan Posisi Matahari sebagai Alternatif Pembuatan Alat Pengendali Solar Tracker | F12: Syafarudin Ch, S.T., M.T. | G12: Dr. Warindi, S.T., M.Eng. | H12: Muhammad Firad, S.T. | I12: Sultan, S.T., M.T. | J12: Sabar Nababan, S.T., M.T. | K12: Sabtu | L12: 40233 | M12: 08.00-10.00 | O12: Lulus | Q12: 4 | R12: 37 | S12: 11 | T12: 5 | U12: 31 | W12: =TEXT(L12,"dd mmmm yyyy") -> 24 Februari 2010 | X12: =IFERROR(VLOOKUP(D12,'[5]mhs elektro-kecil'!$B$5:$E$2500,3,0),"CEK") -> CEK | Y12: =IFERROR(VLOOKUP(D12,'[5]mhs elektro-kecil'!$B$5:$E$2500,4,0),"CEK") -> CEK | Z12: =L12 -> 40233 | AA12: =Z12+180 -> 40413 | AC12: Lulus | AI12: =MID(D12,5,2) -> 03 | AL12: =IF(MID(D12,5,2)="06",2006,IF(MID(D12,5,2)="07",2007,IF(MID(D12,5,2)="08",2008,IF(MID(D12,5,2)="09",2009,IF(MID(D12,5,2)="10",2010,IF(MID(D12,5,2)="11",2011,IF(MID(D12,5,2)="12",2012,IF(MID(D12,5,2)="05",2005,IF(MID(D12,5,2)="04",2004,IF(MID(D12,5,2)="03",2003,IF(MID(D12,5,2)="13",2013,IF(MID(D12,5,2)="14",2014,IF(MID(D12,5,2)="15",2015,IF(MID(D12,5,2)="16",2016,IF(MID(D12,5,2)="17",2017,IF(MID(D12,5,2)="18",2018,2019)))))))))))))))) -> 2003 | AM12: =COUNTIF([6]Daftar!$D$5:$D$851,D12) -> #VALUE! | AN12: =COUNTIF([7]daftar!$D$4:$D$885,D12) -> #VALUE! | AS12: =C12 -> Qitmir Hayatullah | AT12: =D12 -> F1B003052 | AU12: =A12 -> 9
A13: =A12+1 -> 10 | C13: =VLOOKUP(D13,'[4]mhs elektro-kecil'!$B$5:$C$1847,2,0) -> I Dewa Made Ady Indrawan | D13: F1B005024 | E13: Sistem Informasi Pemesanan Tiket Online Berbasis Java Server Pages (JSP) | F13: Heri Wijayanto, S.T., M.T. | G13: Ir. Sri Endang Anjarwani, M.Kom. | H13: Budi Irmawati, S. Kom., M.T. | I13: I B K Widiartha, S.T., M.T. | J13: Muhamad Irwan, S.T., M.T. | K13: Sabtu | L13: 40243 | M13: 08.00-10.00 | O13: Lulus | Q13: 32 | R13: 38 | S13: 20 | T13: 27 | U13: 39 | W13: =TEXT(L13,"dd mmmm yyyy") -> 06 Maret 2010 | X13: =IFERROR(VLOOKUP(D13,'[5]mhs elektro-kecil'!$B$5:$E$2500,3,0),"CEK") -> CEK | Y13: =IFERROR(VLOOKUP(D13,'[5]mhs elektro-kecil'!$B$5:$E$2500,4,0),"CEK") -> CEK | Z13: =L13 -> 40243 | AA13: =Z13+180 -> 40423 | AC13: Lulus | AI13: =MID(D13,5,2) -> 05 | AL13: =IF(MID(D13,5,2)="06",2006,IF(MID(D13,5,2)="07",2007,IF(MID(D13,5,2)="08",2008,IF(MID(D13,5,2)="09",2009,IF(MID(D13,5,2)="10",2010,IF(MID(D13,5,2)="11",2011,IF(MID(D13,5,2)="12",2012,IF(MID(D13,5,2)="05",2005,IF(MID(D13,5,2)="04",2004,IF(MID(D13,5,2)="03",2003,IF(MID(D13,5,2)="13",2013,IF(MID(D13,5,2)="14",2014,IF(MID(D13,5,2)="15",2015,IF(MID(D13,5,2)="16",2016,IF(MID(D13,5,2)="17",2017,IF(MID(D13,5,2)="18",2018,2019)))))))))))))))) -> 2005 | AM13: =COUNTIF([6]Daftar!$D$5:$D$851,D13) -> #VALUE! | AN13: =COUNTIF([7]daftar!$D$4:$D$885,D13) -> #VALUE! | AS13: =C13 -> I Dewa Made Ady Indrawan | AT13: =D13 -> F1B005024 | AU13: =A13 -> 10
A14: =A13+1 -> 11 | C14: =VLOOKUP(D14,'[4]mhs elektro-kecil'!$B$5:$C$1847,2,0) -> Siti Septi | D14: F1B005068 | E14: Pengaruh Faktor Meteorologi Terhadap Lokasi Penempatan Pembangkit Listrik Tenaga Surya (PLTS) di Pulau Lombok | F14: Rosmaliati, S.T., M.T. | G14: Ida Bagus Fery Citarsa, S.T., M.T. | H14: Ni Made Seniari, S.T., M.T. | I14: Supriono, S.T., M.T. | J14: I Ketut Wiryajati, S.T., M.T. | K14: Sabtu | L14: 40243 | M14: 08.00-10.00 | O14: Lulus | Q14: 16 | R14: 12 | S14: 1 | T14: 29 | U14: 3 | W14: =TEXT(L14,"dd mmmm yyyy") -> 06 Maret 2010 | X14: =IFERROR(VLOOKUP(D14,'[5]mhs elektro-kecil'!$B$5:$E$2500,3,0),"CEK") -> CEK | Y14: =IFERROR(VLOOKUP(D14,'[5]mhs elektro-kecil'!$B$5:$E$2500,4,0),"CEK") -> CEK | Z14: =L14 -> 40243 | AA14: =Z14+180 -> 40423 | AB14: =AA14+180 -> 40603 | AC14: Lulus | AD14: 40603 | AI14: =MID(D14,5,2) -> 05 | AL14: =IF(MID(D14,5,2)="06",2006,IF(MID(D14,5,2)="07",2007,IF(MID(D14,5,2)="08",2008,IF(MID(D14,5,2)="09",2009,IF(MID(D14,5,2)="10",2010,IF(MID(D14,5,2)="11",2011,IF(MID(D14,5,2)="12",2012,IF(MID(D14,5,2)="05",2005,IF(MID(D14,5,2)="04",2004,IF(MID(D14,5,2)="03",2003,IF(MID(D14,5,2)="13",2013,IF(MID(D14,5,2)="14",2014,IF(MID(D14,5,2)="15",2015,IF(MID(D14,5,2)="16",2016,IF(MID(D14,5,2)="17",2017,IF(MID(D14,5,2)="18",2018,2019)))))))))))))))) -> 2005 | AM14: =COUNTIF([6]Daftar!$D$5:$D$851,D14) -> #VALUE! | AN14: =COUNTIF([7]daftar!$D$4:$D$885,D14) -> #VALUE! | AS14: =C14 -> Siti Septi | AT14: =D14 -> F1B005068 | AU14: =A14 -> 11
A15: =A14+1 -> 12 | C15: =VLOOKUP(D15,'[4]mhs elektro-kecil'!$B$5:$C$1847,2,0) -> Fithra Mubarak | D15: F1B005017 | E15: Optimasi Kinerja Navigasi Robot Berbasis Mikrokontroller Seri AVR Atmega 8535 Menggunakan Metode Logika Fuzzy | F15: I Made Budi Suksmadana, S.T., M.T. | G15: Paniran, S.T., M.T. | H15: Syafarudin Ch, S.T., M.T. | I15: Bulkis Kanata, S.T., M.T. | J15: Ir. Sri Endang Anjarwani, M.Kom. | K15: Sabtu | L15: 40257 | M15: 08.00-10.00 | O15: Lulus | Q15: 24 | R15: 28 | S15: 4 | T15: 21 | U15: 38 | W15: =TEXT(L15,"dd mmmm yyyy") -> 20 Maret 2010 | X15: =IFERROR(VLOOKUP(D15,'[5]mhs elektro-kecil'!$B$5:$E$2151,3,0),"CEK") -> CEK | Y15: =IFERROR(VLOOKUP(D15,'[5]mhs elektro-kecil'!$B$5:$E$2151,4,0),"CEK") -> CEK | Z15: =L15 -> 40257 | AA15: =Z15+180 -> 40437 | AC15: Lulus | AI15: =MID(D15,5,2) -> 05 | AL15: =IF(MID(D15,5,2)="06",2006,IF(MID(D15,5,2)="07",2007,IF(MID(D15,5,2)="08",2008,IF(MID(D15,5,2)="09",2009,IF(MID(D15,5,2)="10",2010,IF(MID(D15,5,2)="11",2011,IF(MID(D15,5,2)="12",2012,IF(MID(D15,5,2)="05",2005,IF(MID(D15,5,2)="04",2004,IF(MID(D15,5,2)="03",2003,IF(MID(D15,5,2)="13",2013,IF(MID(D15,5,2)="14",2014,IF(MID(D15,5,2)="15",2015,IF(MID(D15,5,2)="16",2016,IF(MID(D15,5,2)="17",2017,IF(MID(D15,5,2)="18",2018,2019)))))))))))))))) -> 2005 | AM15: =COUNTIF([6]Daftar!$D$5:$D$851,D15) -> #VALUE! | AN15: =COUNTIF([7]daftar!$D$4:$D$885,D15) -> #VALUE! | AS15: =C15 -> Fithra Mubarak | AT15: =D15 -> F1B005017 | AU15: =A15 -> 12
A16: =A15+1 -> 13 | C16: =VLOOKUP(D16,'[4]mhs elektro-kecil'!$B$5:$C$1847,2,0) -> Rematomatra Rahmansyah | D16: F1B005062 | E16: Implementasi Algoritma LZW Menggunakan Metode Pencarian Kamus Berbasis Hash Table untuk Kompresi File Teks | F16: Dr. Rismon H. Sianipar, S.T., M.Eng. | G16: Ir. Sri Endang Anjarwani, M.Kom. | H16: Heri Wijayanto, S.T., M.T. | I16: Paniran, S.T., M.T. | J16: Budi Irmawati, S. Kom., M.T. | K16: Sabtu | L16: 40264 | M16: 10.00-12.00 | O16: Lulus | Q16: 33 | R16: 38 | S16: 32 | T16: 28 | U16: 20 | W16: =TEXT(L16,"dd mmmm yyyy") -> 27 Maret 2010 | X16: =IFERROR(VLOOKUP(D16,'[5]mhs elektro-kecil'!$B$5:$E$2151,3,0),"CEK") -> CEK | Y16: =IFERROR(VLOOKUP(D16,'[5]mhs elektro-kecil'!$B$5:$E$2151,4,0),"CEK") -> CEK | Z16: =L16 -> 40264 | AA16: =Z16+180 -> 40444 | AC16: Lulus | AI16: =MID(D16,5,2) -> 05 | AL16: =IF(MID(D16,5,2)="06",2006,IF(MID(D16,5,2)="07",2007,IF(MID(D16,5,2)="08",2008,IF(MID(D16,5,2)="09",2009,IF(MID(D16,5,2)="10",2010,IF(MID(D16,5,2)="11",2011,IF(MID(D16,5,2)="12",2012,IF(MID(D16,5,2)="05",2005,IF(MID(D16,5,2)="04",2004,IF(MID(D16,5,2)="03",2003,IF(MID(D16,5,2)="13",2013,IF(MID(D16,5,2)="14",2014,IF(MID(D16,5,2)="15",2015,IF(MID(D16,5,2)="16",2016,IF(MID(D16,5,2)="17",2017,IF(MID(D16,5,2)="18",2018,2019)))))))))))))))) -> 2005 | AM16: =COUNTIF([6]Daftar!$D$5:$D$851,D16) -> #VALUE! | AN16: =COUNTIF([7]daftar!$D$4:$D$885,D16) -> #VALUE! | AS16: =C16 -> Rematomatra Rahmansyah | AT16: =D16 -> F1B005062 | AU16: =A16 -> 13
A17: =A16+1 -> 14 | C17: =VLOOKUP(D17,'[4]mhs elektro-kecil'!$B$5:$C$1847,2,0) -> Aditya Putra | D17: F1B005002 | E17: Perancangan Game Edukasi Matematika SD Menggunakan Macromedia Flash | F17: Dr. Rismon H. Sianipar, S.T., M.Eng. | G17: Ir. Sri Endang Anjarwani, M.Kom. | H17: Made Sutha Yadnya, S.T., M.T. | I17: I B K Widiartha, S.T., M.T. | J17: Budi Irmawati, S. Kom., M.T. | K17: Sabtu | L17: 40271 | M17: 10.00-12.00 | O17: Lulus | Q17: 33 | R17: 38 | S17: 19 | T17: 27 | U17: 20 | W17: =TEXT(L17,"dd mmmm yyyy") -> 03 April 2010 | X17: =IFERROR(VLOOKUP(D17,'[5]mhs elektro-kecil'!$B$5:$E$2151,3,0),"CEK") -> CEK | Y17: =IFERROR(VLOOKUP(D17,'[5]mhs elektro-kecil'!$B$5:$E$2151,4,0),"CEK") -> CEK | Z17: =L17 -> 40271 | AA17: =Z17+180 -> 40451 | AC17: Lulus | AI17: =MID(D17,5,2) -> 05 | AL17: =IF(MID(D17,5,2)="06",2006,IF(MID(D17,5,2)="07",2007,IF(MID(D17,5,2)="08",2008,IF(MID(D17,5,2)="09",2009,IF(MID(D17,5,2)="10",2010,IF(MID(D17,5,2)="11",2011,IF(MID(D17,5,2)="12",2012,IF(MID(D17,5,2)="05",2005,IF(MID(D17,5,2)="04",2004,IF(MID(D17,5,2)="03",2003,IF(MID(D17,5,2)="13",2013,IF(MID(D17,5,2)="14",2014,IF(MID(D17,5,2)="15",2015,IF(MID(D17,5,2)="16",2016,IF(MID(D17,5,2)="17",2017,IF(MID(D17,5,2)="18",2018,2019)))))))))))))))) -> 2005 | AM17: =COUNTIF([6]Daftar!$D$5:$D$851,D17) -> #VALUE! | AN17: =COUNTIF([7]daftar!$D$4:$D$885,D17) -> #VALUE! | AS17: =C17 -> Aditya Putra | AT17: =D17 -> F1B005002 | AU17: =A17 -> 14
A18: =A17+1 -> 15 | B18: 40282 | C18: =VLOOKUP(D18,'[4]mhs elektro-kecil'!$B$5:$C$1847,2,0) -> Alpan Hadi | D18: F1B005005 | E18: Pengatur Posisi Ketinggian Tiang Mikrofof Otomatis Berbasis Mikrokontroler Seri AVR ATMega 8535 | F18: Paniran, S.T., M.T. | G18: Syafarudin Ch, S.T., M.T. | H18: Abdullah Zainuddin, S.T., M.T. | I18: Sudi M. Al Sasongko, S.T., M.T. | J18: Djul Fikry Budiman, S.T., M.T. | K18: Senin | L18: 40289 | M18: 10.00-12.00 | N18: D2 | O18: Lulus | Q18: 28 | R18: 4 | S18: 15 | T18: 6 | U18: 35 | W18: =TEXT(L18,"dd mmmm yyyy") -> 21 April 2010 | X18: =IFERROR(VLOOKUP(D18,'[5]mhs elektro-kecil'!$B$5:$E$2151,3,0),"CEK") -> CEK | Y18: =IFERROR(VLOOKUP(D18,'[5]mhs elektro-kecil'!$B$5:$E$2151,4,0),"CEK") -> CEK | Z18: =L18 -> 40289 | AA18: =Z18+180 -> 40469 | AC18: Lulus | AI18: =MID(D18,5,2) -> 05 | AL18: =IF(MID(D18,5,2)="06",2006,IF(MID(D18,5,2)="07",2007,IF(MID(D18,5,2)="08",2008,IF(MID(D18,5,2)="09",2009,IF(MID(D18,5,2)="10",2010,IF(MID(D18,5,2)="11",2011,IF(MID(D18,5,2)="12",2012,IF(MID(D18,5,2)="05",2005,IF(MID(D18,5,2)="04",2004,IF(MID(D18,5,2)="03",2003,IF(MID(D18,5,2)="13",2013,IF(MID(D18,5,2)="14",2014,IF(MID(D18,5,2)="15",2015,IF(MID(D18,5,2)="16",2016,IF(MID(D18,5,2)="17",2017,IF(MID(D18,5,2)="18",2018,2019)))))))))))))))) -> 2005 | AM18: =COUNTIF([6]Daftar!$D$5:$D$851,D18) -> #VALUE! | AN18: =COUNTIF([7]daftar!$D$4:$D$885,D18) -> #VALUE! | AS18: =C18 -> Alpan Hadi | AT18: =D18 -> F1B005005 | AU18: =A18 -> 15
A19: =A18+1 -> 16 | B19: 40301 | C19: =VLOOKUP(D19,'[4]mhs elektro-kecil'!$B$5:$C$1847,2,0) -> Muhammad Wahyudi | D19: F1B005053 | E19: Rancang Bangun Alat Pengendali Penerangan Ruangan Menggunakan Metode Fuzzy Logic Berbasis Mikrokontroler ATMEGA8535 | F19: I Made Budi Suksmadana, S.T., M.T. | G19: Dr. Misbahuddin, S.T., M.T. | H19: Paniran, S.T., M.T. | I19: Sultan, S.T., M.T. | J19: I Ketut Wiryajati, S.T., M.T. | K19: Sabtu | L19: 40306 | M19: 08.00-10.00 | N19: R. Studio | O19: Lulus | Q19: 24 | R19: 7 | S19: 28 | T19: 5 | U19: 3 | W19: =TEXT(L19,"dd mmmm yyyy") -> 08 Mei 2010 | X19: =IFERROR(VLOOKUP(D19,'[5]mhs elektro-kecil'!$B$5:$E$2151,3,0),"CEK") -> CEK | Y19: =IFERROR(VLOOKUP(D19,'[5]mhs elektro-kecil'!$B$5:$E$2151,4,0),"CEK") -> CEK | Z19: =L19 -> 40306 | AA19: =Z19+180 -> 40486 | AB19: =AA19+180 -> 40666 | AC19: Lulus | AI19: =MID(D19,5,2) -> 05 | AL19: =IF(MID(D19,5,2)="06",2006,IF(MID(D19,5,2)="07",2007,IF(MID(D19,5,2)="08",2008,IF(MID(D19,5,2)="09",2009,IF(MID(D19,5,2)="10",2010,IF(MID(D19,5,2)="11",2011,IF(MID(D19,5,2)="12",2012,IF(MID(D19,5,2)="05",2005,IF(MID(D19,5,2)="04",2004,IF(MID(D19,5,2)="03",2003,IF(MID(D19,5,2)="13",2013,IF(MID(D19,5,2)="14",2014,IF(MID(D19,5,2)="15",2015,IF(MID(D19,5,2)="16",2016,IF(MID(D19,5,2)="17",2017,IF(MID(D19,5,2)="18",2018,2019)))))))))))))))) -> 2005 | AM19: =COUNTIF([6]Daftar!$D$5:$D$851,D19) -> #VALUE! | AN19: =COUNTIF([7]daftar!$D$4:$D$885,D19) -> #VALUE! | AS19: =C19 -> Muhammad Wahyudi | AT19: =D19 -> F1B005053 | AU19: =A19 -> 16
A20: =A19+1 -> 17 | B20: 40305 | C20: =VLOOKUP(D20,'[4]mhs elektro-kecil'!$B$5:$C$1847,2,0) -> Satriasyah Haris S. | D20: F1B003062 | E20: Analisa Kelayakan Implementasi Internet Protokol Television (IP-Tv) Berbasis Perangkat Lunak Open Source | F20: Dr. Misbahuddin, S.T., M.T. | G20: Heri Wijayanto, S.T., M.T. | H20: Muhamad Syamsu Iqbal, S.T., M.T., Ph.D. | I20: I B K Widiartha, S.T., M.T. | J20: Muhamad Irwan, S.T., M.T. | K20: Sabtu | L20: 40306 | M20: 10.00-12.00 | N20: R. Studio | O20: Lulus | Q20: 7 | R20: 32 | S20: 18 | T20: 27 | U20: 39 | W20: =TEXT(L20,"dd mmmm yyyy") -> 08 Mei 2010 | X20: =IFERROR(VLOOKUP(D20,'[5]mhs elektro-kecil'!$B$5:$E$2151,3,0),"CEK") -> CEK | Y20: =IFERROR(VLOOKUP(D20,'[5]mhs elektro-kecil'!$B$5:$E$2151,4,0),"CEK") -> CEK | Z20: =L20 -> 40306 | AA20: =Z20+180 -> 40486 | AC20: Lulus | AI20: =MID(D20,5,2) -> 03 | AL20: =IF(MID(D20,5,2)="06",2006,IF(MID(D20,5,2)="07",2007,IF(MID(D20,5,2)="08",2008,IF(MID(D20,5,2)="09",2009,IF(MID(D20,5,2)="10",2010,IF(MID(D20,5,2)="11",2011,IF(MID(D20,5,2)="12",2012,IF(MID(D20,5,2)="05",2005,IF(MID(D20,5,2)="04",2004,IF(MID(D20,5,2)="03",2003,IF(MID(D20,5,2)="13",2013,IF(MID(D20,5,2)="14",2014,IF(MID(D20,5,2)="15",2015,IF(MID(D20,5,2)="16",2016,IF(MID(D20,5,2)="17",2017,IF(MID(D20,5,2)="18",2018,2019)))))))))))))))) -> 2003 | AM20: =COUNTIF([6]Daftar!$D$5:$D$851,D20) -> #VALUE! | AN20: =COUNTIF([7]daftar!$D$4:$D$885,D20) -> #VALUE! | AS20: =C20 -> Satriasyah Haris S. | AT20: =D20 -> F1B003062 | AU20: =A20 -> 17
A21: =A20+1 -> 18 | B21: 40308 | C21: =VLOOKUP(D21,'[4]mhs elektro-kecil'!$B$5:$C$1847,2,0) -> Trie Adriany Sofiana | D21: F1B006083 | E21: Penentuan Posisi Sensor Mitigasi Curah Hujan untuk Komunikasi LMDS dengan Metode SST (Synthetic Storm Technique) di Mataram | F21: Made Sutha Yadnya, S.T., M.T. | G21: Djul Fikry Budiman, S.T., M.T. | H21: Sudi M. Al Sasongko, S.T., M.T. | I21: Muhamad Syamsu Iqbal, S.T., M.T., Ph.D. | J21: Bulkis Kanata, S.T., M.T. | K21: Sabtu | L21: 40313 | M21: 10.00-12.00 | N21: R. Lab. Elka & Digital | O21: Lulus | Q21: 19 | R21: 35 | S21: 6 | T21: 18 | U21: 21 | W21: =TEXT(L21,"dd mmmm yyyy") -> 15 Mei 2010 | X21: =IFERROR(VLOOKUP(D21,'[5]mhs elektro-kecil'!$B$5:$E$2151,3,0),"CEK") -> CEK | Y21: =IFERROR(VLOOKUP(D21,'[5]mhs elektro-kecil'!$B$5:$E$2151,4,0),"CEK") -> CEK | Z21: =L21 -> 40313 | AA21: =Z21+180 -> 40493 | AC21: Lulus | AI21: =MID(D21,5,2) -> 06 | AL21: =IF(MID(D21,5,2)="06",2006,IF(MID(D21,5,2)="07",2007,IF(MID(D21,5,2)="08",2008,IF(MID(D21,5,2)="09",2009,IF(MID(D21,5,2)="10",2010,IF(MID(D21,5,2)="11",2011,IF(MID(D21,5,2)="12",2012,IF(MID(D21,5,2)="05",2005,IF(MID(D21,5,2)="04",2004,IF(MID(D21,5,2)="03",2003,IF(MID(D21,5,2)="13",2013,IF(MID(D21,5,2)="14",2014,IF(MID(D21,5,2)="15",2015,IF(MID(D21,5,2)="16",2016,IF(MID(D21,5,2)="17",2017,IF(MID(D21,5,2)="18",2018,2019)))))))))))))))) -> 2006 | AM21: =COUNTIF([6]Daftar!$D$5:$D$851,D21) -> #VALUE! | AN21: =COUNTIF([7]daftar!$D$4:$D$885,D21) -> #VALUE! | AS21: =C21 -> Trie Adriany Sofiana | AT21: =D21 -> F1B006083 | AU21: =A21 -> 18
A22: =A21+1 -> 19 | B22: 40329 | C22: =VLOOKUP(D22,'[4]mhs elektro-kecil'!$B$5:$C$1847,2,0) -> Isnu Handibrata Eko Putra | D22: F1B006042 | E22: Analisis Stabilitas Transien pada Sistem Tenaga Listrik Pulau Lombok Menggunakan Kriteria Luas Sama dan Jaringan Syaraf Tiruan | F22: Abdul Natsir, S.T., M.T. | G22: I Made Ari Nrartha, S.T., M.T. | H22: Rosmaliati, S.T., M.T. | I22: I Ketut Perdana Putra, S.T., M.T. | J22: Supriono, S.T., M.T. | K22: Sabtu | L22: 40334 | M22: 08.00-10.00 | N22: R. D2 | O22: Lulus | Q22: 14 | R22: 25 | S22: 16 | T22: 23 | U22: 29 | W22: =TEXT(L22,"dd mmmm yyyy") -> 05 Juni 2010 | X22: =IFERROR(VLOOKUP(D22,'[5]mhs elektro-kecil'!$B$5:$E$2151,3,0),"CEK") -> CEK | Y22: =IFERROR(VLOOKUP(D22,'[5]mhs elektro-kecil'!$B$5:$E$2151,4,0),"CEK") -> CEK | Z22: =L22 -> 40334 | AA22: =Z22+180 -> 40514 | AC22: Lulus | AI22: =MID(D22,5,2) -> 06 | AL22: =IF(MID(D22,5,2)="06",2006,IF(MID(D22,5,2)="07",2007,IF(MID(D22,5,2)="08",2008,IF(MID(D22,5,2)="09",2009,IF(MID(D22,5,2)="10",2010,IF(MID(D22,5,2)="11",2011,IF(MID(D22,5,2)="12",2012,IF(MID(D22,5,2)="05",2005,IF(MID(D22,5,2)="04",2004,IF(MID(D22,5,2)="03",2003,IF(MID(D22,5,2)="13",2013,IF(MID(D22,5,2)="14",2014,IF(MID(D22,5,2)="15",2015,IF(MID(D22,5,2)="16",2016,IF(MID(D22,5,2)="17",2017,IF(MID(D22,5,2)="18",2018,2019)))))))))))))))) -> 2006 | AM22: =COUNTIF([6]Daftar!$D$5:$D$851,D22) -> #VALUE! | AN22: =COUNTIF([7]daftar!$D$4:$D$885,D22) -> #VALUE! | AS22: =C22 -> Isnu Handibrata Eko Putra | AT22: =D22 -> F1B006042 | AU22: =A22 -> 19
A23: =A22+1 -> 20 | B23: 40329 | C23: =VLOOKUP(D23,'[4]mhs elektro-kecil'!$B$5:$C$1847,2,0) -> Agus Nugroho | D23: F1B002003 | E23: Rancang Bangun Pembangkit Listrik Tenaga Angin (PLTB) dengan Menggunakan Turbin Savonius | F23: Sabar Nababan, S.T., M.T. | G23: Agung Budi Muljono, S.T., M.T. | H23: Ni Made Seniari, S.T., M.T. | I23: Supriyatna, S.T., M.T. | J23: I Ketut Perdana Putra, S.T., M.T. | K23: Sabtu | L23: 40334 | M23: 10.00-12.00 | N23: R. D2 | O23: Lulus | Q23: 31 | R23: 13 | S23: 1 | T23: 2 | U23: 23 | W23: =TEXT(L23,"dd mmmm yyyy") -> 05 Juni 2010 | X23: =IFERROR(VLOOKUP(D23,'[5]mhs elektro-kecil'!$B$5:$E$2151,3,0),"CEK") -> CEK | Y23: =IFERROR(VLOOKUP(D23,'[5]mhs elektro-kecil'!$B$5:$E$2151,4,0),"CEK") -> CEK | Z23: =L23 -> 40334 | AA23: =Z23+180 -> 40514 | AB23: =AA23+180 -> 40694 | AC23: Lulus | AI23: =MID(D23,5,2) -> 02 | AL23: =IF(MID(D23,5,2)="06",2006,IF(MID(D23,5,2)="07",2007,IF(MID(D23,5,2)="08",2008,IF(MID(D23,5,2)="09",2009,IF(MID(D23,5,2)="10",2010,IF(MID(D23,5,2)="11",2011,IF(MID(D23,5,2)="12",2012,IF(MID(D23,5,2)="05",2005,IF(MID(D23,5,2)="04",2004,IF(MID(D23,5,2)="03",2003,IF(MID(D23,5,2)="13",2013,IF(MID(D23,5,2)="14",2014,IF(MID(D23,5,2)="15",2015,IF(MID(D23,5,2)="16",2016,IF(MID(D23,5,2)="17",2017,IF(MID(D23,5,2)="18",2018,2019)))))))))))))))) -> 2019 | AM23: =COUNTIF([6]Daftar!$D$5:$D$851,D23) -> #VALUE! | AN23: =COUNTIF([7]daftar!$D$4:$D$885,D23) -> #VALUE! | AS23: =C23 -> Agus Nugroho | AT23: =D23 -> F1B002003 | AU23: =A23 -> 20
A24: =A23+1 -> 21 | B24: 40329 | C24: =VLOOKUP(D24,'[4]mhs elektro-kecil'!$B$5:$C$1847,2,0) -> Parlinawati | D24: F1B005059 | E24: Simulasi dan Analisis Perbandingan Kinerja Sistem OFCDM Berbasis Wavelet terhadap Sistem OFCDM Berbasis FFT | F24: Sudi M. Al Sasongko, S.T., M.T. | G24: I Made Budi Suksmadana, S.T., M.T. | H24: Abdullah Zainuddin, S.T., M.T. | I24: Made Sutha Yadnya, S.T., M.T. | J24: Muhamad Syamsu Iqbal, S.T., M.T., Ph.D. | K24: Sabtu | L24: 40334 | M24: 10.00-12.00 | N24: R. Studio | O24: Lulus | Q24: 6 | R24: 24 | S24: 15 | T24: 19 | U24: 18 | W24: =TEXT(L24,"dd mmmm yyyy") -> 05 Juni 2010 | X24: =IFERROR(VLOOKUP(D24,'[5]mhs elektro-kecil'!$B$5:$E$2151,3,0),"CEK") -> CEK | Y24: =IFERROR(VLOOKUP(D24,'[5]mhs elektro-kecil'!$B$5:$E$2151,4,0),"CEK") -> CEK | Z24: =L24 -> 40334 | AA24: =Z24+180 -> 40514 | AB24: =AA24+180 -> 40694 | AI24: =MID(D24,5,2) -> 05 | AL24: =IF(MID(D24,5,2)="06",2006,IF(MID(D24,5,2)="07",2007,IF(MID(D24,5,2)="08",2008,IF(MID(D24,5,2)="09",2009,IF(MID(D24,5,2)="10",2010,IF(MID(D24,5,2)="11",2011,IF(MID(D24,5,2)="12",2012,IF(MID(D24,5,2)="05",2005,IF(MID(D24,5,2)="04",2004,IF(MID(D24,5,2)="03",2003,IF(MID(D24,5,2)="13",2013,IF(MID(D24,5,2)="14",2014,IF(MID(D24,5,2)="15",2015,IF(MID(D24,5,2)="16",2016,IF(MID(D24,5,2)="17",2017,IF(MID(D24,5,2)="18",2018,2019)))))))))))))))) -> 2005 | AM24: =COUNTIF([6]Daftar!$D$5:$D$851,D24) -> #VALUE! | AN24: =COUNTIF([7]daftar!$D$4:$D$885,D24) -> #VALUE! | AS24: =C24 -> Parlinawati | AT24: =D24 -> F1B005059 | AU24: =A24 -> 21
A25: =A24+1 -> 22 | B25: 40329 | C25: =VLOOKUP(D25,'[4]mhs elektro-kecil'!$B$5:$C$1847,2,0) -> Eddy Kurniawan | D25: F1B003014 | E25: Data Encryption Standard (DES) Cryptosystem Berfungsi sebagai Fungsi Hash untuk Menguji Integritas Sinyal Audio | F25: Dr. Rismon H. Sianipar, S.T., M.Eng. | G25: Heri Wijayanto, S.T., M.T. | H25: I B K Widiartha, S.T., M.T. | I25: Muhamad Irwan, S.T., M.T. | J25: Budi Irmawati, S. Kom., M.T. | K25: Rabu | L25: 40338 | M25: 10.00-12.00 | N25: R. WLTI | O25: Lulus | Q25: 33 | R25: 32 | S25: 27 | T25: 39 | U25: 20 | W25: =TEXT(L25,"dd mmmm yyyy") -> 09 Juni 2010 | X25: =IFERROR(VLOOKUP(D25,'[5]mhs elektro-kecil'!$B$5:$E$2151,3,0),"CEK") -> CEK | Y25: =IFERROR(VLOOKUP(D25,'[5]mhs elektro-kecil'!$B$5:$E$2151,4,0),"CEK") -> CEK | Z25: =L25 -> 40338 | AA25: =Z25+180 -> 40518 | AC25: Lulus | AI25: =MID(D25,5,2) -> 03 | AL25: =IF(MID(D25,5,2)="06",2006,IF(MID(D25,5,2)="07",2007,IF(MID(D25,5,2)="08",2008,IF(MID(D25,5,2)="09",2009,IF(MID(D25,5,2)="10",2010,IF(MID(D25,5,2)="11",2011,IF(MID(D25,5,2)="12",2012,IF(MID(D25,5,2)="05",2005,IF(MID(D25,5,2)="04",2004,IF(MID(D25,5,2)="03",2003,IF(MID(D25,5,2)="13",2013,IF(MID(D25,5,2)="14",2014,IF(MID(D25,5,2)="15",2015,IF(MID(D25,5,2)="16",2016,IF(MID(D25,5,2)="17",2017,IF(MID(D25,5,2)="18",2018,2019)))))))))))))))) -> 2003 | AM25: =COUNTIF([6]Daftar!$D$5:$D$851,D25) -> #VALUE! | AN25: =COUNTIF([7]daftar!$D$4:$D$885,D25) -> #VALUE! | AS25: =C25 -> Eddy Kurniawan | AT25: =D25 -> F1B003014 | AU25: =A25 -> 22
A26: =A25+1 -> 23 | B26: 40338 | C26: =VLOOKUP(D26,'[4]mhs elektro-kecil'!$B$5:$C$1847,2,0) -> I Gusti Ayu Ita Kusmira | D26: F1B006034 | E26: Economi Dispatch Menggunakan Algoritma Genetika (Studi Kasus : Sistem Kelistrikan Lombok) | F26: Agung Budi Muljono, S.T., M.T. | G26: I Made Ari Nrartha, S.T., M.T. | H26: Dr.rer.nat. Teti Zubaidah, S.T., M.T. | I26: Ida Bagus Fery Citarsa, S.T., M.T. | J26: Supriyatna, S.T., M.T. | K26: Sabtu | L26: 40341 | M26: 08.00-10.00 | N26: R. D2 | O26: Lulus | Q26: 13 | R26: 25 | S26: 22 | T26: 12 | U26: 2 | W26: =TEXT(L26,"dd mmmm yyyy") -> 12 Juni 2010 | X26: =IFERROR(VLOOKUP(D26,'[5]mhs elektro-kecil'!$B$5:$E$2151,3,0),"CEK") -> CEK | Y26: =IFERROR(VLOOKUP(D26,'[5]mhs elektro-kecil'!$B$5:$E$2151,4,0),"CEK") -> CEK | Z26: =L26 -> 40341 | AA26: =Z26+180 -> 40521 | AC26: Lulus | AI26: =MID(D26,5,2) -> 06 | AL26: =IF(MID(D26,5,2)="06",2006,IF(MID(D26,5,2)="07",2007,IF(MID(D26,5,2)="08",2008,IF(MID(D26,5,2)="09",2009,IF(MID(D26,5,2)="10",2010,IF(MID(D26,5,2)="11",2011,IF(MID(D26,5,2)="12",2012,IF(MID(D26,5,2)="05",2005,IF(MID(D26,5,2)="04",2004,IF(MID(D26,5,2)="03",2003,IF(MID(D26,5,2)="13",2013,IF(MID(D26,5,2)="14",2014,IF(MID(D26,5,2)="15",2015,IF(MID(D26,5,2)="16",2016,IF(MID(D26,5,2)="17",2017,IF(MID(D26,5,2)="18",2018,2019)))))))))))))))) -> 2006 | AM26: =COUNTIF([6]Daftar!$D$5:$D$851,D26) -> #VALUE! | AN26: =COUNTIF([7]daftar!$D$4:$D$885,D26) -> #VALUE! | AS26: =C26 -> I Gusti Ayu Ita Kusmira | AT26: =D26 -> F1B006034 | AU26: =A26 -> 23
A27: =A26+1 -> 24 | B27: 40338 | C27: =VLOOKUP(D27,'[4]mhs elektro-kecil'!$B$5:$C$1847,2,0) -> Dedek Hudayana | D27: F1B005011 | E27: Alat Pengontrol dan Pemonitor Lingkungan Rumah Kaca pada Tanaman Kamboja Jepang di Dinas Pertanian Narmada Berbasiskan Mikrokontroler ATMEGA8535 | F27: Paniran, S.T., M.T. | G27: Supriono, S.T., M.T. | H27: I Ketut Wiryajati, S.T., M.T. | I27: Muhammad Firad, S.T. | J27: Lalu A. Syamsul Irfan A., S.T., M.Eng. | K27: Sabtu | L27: 40341 | M27: 08.00-10.00 | N27: R. Studio | O27: Lulus | Q27: 28 | R27: 29 | S27: 3 | T27: 11 | U27: 40 | W27: =TEXT(L27,"dd mmmm yyyy") -> 12 Juni 2010 | X27: =IFERROR(VLOOKUP(D27,'[5]mhs elektro-kecil'!$B$5:$E$2151,3,0),"CEK") -> CEK | Y27: =IFERROR(VLOOKUP(D27,'[5]mhs elektro-kecil'!$B$5:$E$2151,4,0),"CEK") -> CEK | Z27: =L27 -> 40341 | AA27: =Z27+180 -> 40521 | AC27: Lulus | AI27: =MID(D27,5,2) -> 05 | AL27: =IF(MID(D27,5,2)="06",2006,IF(MID(D27,5,2)="07",2007,IF(MID(D27,5,2)="08",2008,IF(MID(D27,5,2)="09",2009,IF(MID(D27,5,2)="10",2010,IF(MID(D27,5,2)="11",2011,IF(MID(D27,5,2)="12",2012,IF(MID(D27,5,2)="05",2005,IF(MID(D27,5,2)="04",2004,IF(MID(D27,5,2)="03",2003,IF(MID(D27,5,2)="13",2013,IF(MID(D27,5,2)="14",2014,IF(MID(D27,5,2)="15",2015,IF(MID(D27,5,2)="16",2016,IF(MID(D27,5,2)="17",2017,IF(MID(D27,5,2)="18",2018,2019)))))))))))))))) -> 2005 | AM27: =COUNTIF([6]Daftar!$D$5:$D$851,D27) -> #VALUE! | AN27: =COUNTIF([7]daftar!$D$4:$D$885,D27) -> #VALUE! | AS27: =C27 -> Dedek Hudayana | AT27: =D27 -> F1B005011 | AU27: =A27 -> 24
A28: =A27+1 -> 25 | B28: 40357 | C28: =VLOOKUP(D28,'[4]mhs elektro-kecil'!$B$5:$C$1847,2,0) -> Kamarudin | D28: F1B005033 | E28: Perancangan Sistem Pengaman Sepeda Motor Menggunakan Telepon Seluler (Handphone) Berbasis Mikrokontroller ATMEGA 8535 | F28: Supriono, S.T., M.T. | G28: I Made Budi Suksmadana, S.T., M.T. | H28: Syafarudin Ch, S.T., M.T. | I28: Sabar Nababan, S.T., M.T. | J28: Muhamad Irwan, S.T., M.T. | K28: Kamis | L28: 40360 | M28: 08.00-10.00 | N28: R. Studio | O28: Lulus | Q28: 29 | R28: 24 | S28: 4 | T28: 31 | U28: 39 | W28: =TEXT(L28,"dd mmmm yyyy") -> 01 Juli 2010 | X28: =IFERROR(VLOOKUP(D28,'[5]mhs elektro-kecil'!$B$5:$E$2151,3,0),"CEK") -> CEK | Y28: =IFERROR(VLOOKUP(D28,'[5]mhs elektro-kecil'!$B$5:$E$2151,4,0),"CEK") -> CEK | Z28: =L28 -> 40360 | AA28: =Z28+180 -> 40540 | AC28: Lulus | AI28: =MID(D28,5,2) -> 05 | AL28: =IF(MID(D28,5,2)="06",2006,IF(MID(D28,5,2)="07",2007,IF(MID(D28,5,2)="08",2008,IF(MID(D28,5,2)="09",2009,IF(MID(D28,5,2)="10",2010,IF(MID(D28,5,2)="11",2011,IF(MID(D28,5,2)="12",2012,IF(MID(D28,5,2)="05",2005,IF(MID(D28,5,2)="04",2004,IF(MID(D28,5,2)="03",2003,IF(MID(D28,5,2)="13",2013,IF(MID(D28,5,2)="14",2014,IF(MID(D28,5,2)="15",2015,IF(MID(D28,5,2)="16",2016,IF(MID(D28,5,2)="17",2017,IF(MID(D28,5,2)="18",2018,2019)))))))))))))))) -> 2005 | AM28: =COUNTIF([6]Daftar!$D$5:$D$851,D28) -> #VALUE! | AN28: =COUNTIF([7]daftar!$D$4:$D$885,D28) -> #VALUE! | AS28: =C28 -> Kamarudin | AT28: =D28 -> F1B005033 | AU28: =A28 -> 25
A29: =A28+1 -> 26 | B29: 40373 | C29: =VLOOKUP(D29,'[4]mhs elektro-kecil'!$B$5:$C$1847,2,0) -> Henry Sayyidiman | D29: F1B006030 | E29: Optimalisasi Kapasitas Pembangkit Tersebar dalam Mengurangi Rugi Saluran dan Meningkatkan Profil Tegangan Menggunakan Particle Swarm Optimization | F29: I Made Ari Nrartha, S.T., M.T. | G29: Agung Budi Muljono, S.T., M.T. | H29: Abdul Natsir, S.T., M.T. | I29: Ida Bagus Fery Citarsa, S.T., M.T. | J29: Dr. Misbahuddin, S.T., M.T. | K29: Sabtu | L29: 40376 | M29: 10.00-12.00 | N29: R. D2 | O29: Lulus | Q29: 25 | R29: 13 | S29: 14 | T29: 12 | U29: 7 | W29: =TEXT(L29,"dd mmmm yyyy") -> 17 Juli 2010 | X29: =IFERROR(VLOOKUP(D29,'[5]mhs elektro-kecil'!$B$5:$E$2151,3,0),"CEK") -> CEK | Y29: =IFERROR(VLOOKUP(D29,'[5]mhs elektro-kecil'!$B$5:$E$2151,4,0),"CEK") -> CEK | Z29: =L29 -> 40376 | AA29: =Z29+180 -> 40556 | AC29: Lulus | AI29: =MID(D29,5,2) -> 06 | AL29: =IF(MID(D29,5,2)="06",2006,IF(MID(D29,5,2)="07",2007,IF(MID(D29,5,2)="08",2008,IF(MID(D29,5,2)="09",2009,IF(MID(D29,5,2)="10",2010,IF(MID(D29,5,2)="11",2011,IF(MID(D29,5,2)="12",2012,IF(MID(D29,5,2)="05",2005,IF(MID(D29,5,2)="04",2004,IF(MID(D29,5,2)="03",2003,IF(MID(D29,5,2)="13",2013,IF(MID(D29,5,2)="14",2014,IF(MID(D29,5,2)="15",2015,IF(MID(D29,5,2)="16",2016,IF(MID(D29,5,2)="17",2017,IF(MID(D29,5,2)="18",2018,2019)))))))))))))))) -> 2006 | AM29: =COUNTIF([6]Daftar!$D$5:$D$851,D29) -> #VALUE! | AN29: =COUNTIF([7]daftar!$D$4:$D$885,D29) -> #VALUE! | AS29: =C29 -> Henry Sayyidiman | AT29: =D29 -> F1B006030 | AU29: =A29 -> 26
A30: =A29+1 -> 27 | B30: 40373 | C30: =VLOOKUP(D30,'[4]mhs elektro-kecil'!$B$5:$C$1847,2,0) -> Ria Fitriani | D30: F1B003057 | E30: Analisa Proteksi Sistem Kelistrikan Lombok pada Express Feeder Ampenan - Paokmotong | F30: Supriyatna, S.T., M.T. | G30: Supriono, S.T., M.T. | H30: Dr.rer.nat. Teti Zubaidah, S.T., M.T. | I30: Sultan, S.T., M.T. | J30: Ni Made Seniari, S.T., M.T. | K30: Sabtu | L30: 40376 | M30: 08.00-10.00 | N30: R. Studio | O30: Lulus | Q30: 2 | R30: 29 | S30: 22 | T30: 5 | U30: 1 | W30: =TEXT(L30,"dd mmmm yyyy") -> 17 Juli 2010 | X30: =IFERROR(VLOOKUP(D30,'[5]mhs elektro-kecil'!$B$5:$E$2151,3,0),"CEK") -> CEK | Y30: =IFERROR(VLOOKUP(D30,'[5]mhs elektro-kecil'!$B$5:$E$2151,4,0),"CEK") -> CEK | Z30: =L30 -> 40376 | AA30: =Z30+180 -> 40556 | AC30: Lulus | AI30: =MID(D30,5,2) -> 03 | AL30: =IF(MID(D30,5,2)="06",2006,IF(MID(D30,5,2)="07",2007,IF(MID(D30,5,2)="08",2008,IF(MID(D30,5,2)="09",2009,IF(MID(D30,5,2)="10",2010,IF(MID(D30,5,2)="11",2011,IF(MID(D30,5,2)="12",2012,IF(MID(D30,5,2)="05",2005,IF(MID(D30,5,2)="04",2004,IF(MID(D30,5,2)="03",2003,IF(MID(D30,5,2)="13",2013,IF(MID(D30,5,2)="14",2014,IF(MID(D30,5,2)="15",2015,IF(MID(D30,5,2)="16",2016,IF(MID(D30,5,2)="17",2017,IF(MID(D30,5,2)="18",2018,2019)))))))))))))))) -> 2003 | AM30: =COUNTIF([6]Daftar!$D$5:$D$851,D30) -> #VALUE! | AN30: =COUNTIF([7]daftar!$D$4:$D$885,D30) -> #VALUE! | AS30: =C30 -> Ria Fitriani | AT30: =D30 -> F1B003057 | AU30: =A30 -> 27
A31: =A30+1 -> 28 | B31: 40406 | C31: =VLOOKUP(D31,'[4]mhs elektro-kecil'!$B$5:$C$1847,2,0) -> I Gde Aditya P S | D31: F1B004032 | E31: Sistem Proteksi Keamanan Ruangan dan Pengendali Lampu Berbasis SMS | F31: Supriono, S.T., M.T. | G31: I Made Budi Suksmadana, S.T., M.T. | H31: I Ketut Wiryajati, S.T., M.T. | I31: Syafarudin Ch, S.T., M.T. | J31: Paniran, S.T., M.T. | K31: Rabu | L31: 40408 | M31: 10.00-12.00 | N31: R. Studio | O31: Lulus | Q31: 29 | R31: 24 | S31: 3 | T31: 4 | U31: 28 | W31: =TEXT(L31,"dd mmmm yyyy") -> 18 Agustus 2010 | X31: =IFERROR(VLOOKUP(D31,'[5]mhs elektro-kecil'!$B$5:$E$2151,3,0),"CEK") -> CEK | Y31: =IFERROR(VLOOKUP(D31,'[5]mhs elektro-kecil'!$B$5:$E$2151,4,0),"CEK") -> CEK | Z31: =L31 -> 40408 | AA31: =Z31+180 -> 40588 | AC31: Lulus | AI31: =MID(D31,5,2) -> 04 | AL31: =IF(MID(D31,5,2)="06",2006,IF(MID(D31,5,2)="07",2007,IF(MID(D31,5,2)="08",2008,IF(MID(D31,5,2)="09",2009,IF(MID(D31,5,2)="10",2010,IF(MID(D31,5,2)="11",2011,IF(MID(D31,5,2)="12",2012,IF(MID(D31,5,2)="05",2005,IF(MID(D31,5,2)="04",2004,IF(MID(D31,5,2)="03",2003,IF(MID(D31,5,2)="13",2013,IF(MID(D31,5,2)="14",2014,IF(MID(D31,5,2)="15",2015,IF(MID(D31,5,2)="16",2016,IF(MID(D31,5,2)="17",2017,IF(MID(D31,5,2)="18",2018,2019)))))))))))))))) -> 2004 | AM31: =COUNTIF([6]Daftar!$D$5:$D$851,D31) -> #VALUE! | AN31: =COUNTIF([7]daftar!$D$4:$D$885,D31) -> #VALUE! | AS31: =C31 -> I Gde Aditya P S | AT31: =D31 -> F1B004032 | AU31: =A31 -> 28
A32: =A31+1 -> 29 | B32: 40403 | C32: =VLOOKUP(D32,'[4]mhs elektro-kecil'!$B$5:$C$1847,2,0) -> Edi Waskita Putra | D32: F1B003015 | E32: Rancang Bangun Sistem Absensi Mengajar Dosen dengan SMS Gateway | F32: Dr. Misbahuddin, S.T., M.T. | G32: Heri Wijayanto, S.T., M.T. | H32: Budi Irmawati, S. Kom., M.T. | I32: I B K Widiartha, S.T., M.T. | J32: Ir. Sri Endang Anjarwani, M.Kom. | K32: Rabu | L32: 40408 | M32: 08.00-10.00 | N32: R. D2 | O32: Lulus | Q32: 7 | R32: 32 | S32: 20 | T32: 27 | U32: 38 | W32: =TEXT(L32,"dd mmmm yyyy") -> 18 Agustus 2010 | X32: =IFERROR(VLOOKUP(D32,'[5]mhs elektro-kecil'!$B$5:$E$2151,3,0),"CEK") -> CEK | Y32: =IFERROR(VLOOKUP(D32,'[5]mhs elektro-kecil'!$B$5:$E$2151,4,0),"CEK") -> CEK | Z32: =L32 -> 40408 | AA32: =Z32+180 -> 40588 | AC32: Lulus | AI32: =MID(D32,5,2) -> 03 | AL32: =IF(MID(D32,5,2)="06",2006,IF(MID(D32,5,2)="07",2007,IF(MID(D32,5,2)="08",2008,IF(MID(D32,5,2)="09",2009,IF(MID(D32,5,2)="10",2010,IF(MID(D32,5,2)="11",2011,IF(MID(D32,5,2)="12",2012,IF(MID(D32,5,2)="05",2005,IF(MID(D32,5,2)="04",2004,IF(MID(D32,5,2)="03",2003,IF(MID(D32,5,2)="13",2013,IF(MID(D32,5,2)="14",2014,IF(MID(D32,5,2)="15",2015,IF(MID(D32,5,2)="16",2016,IF(MID(D32,5,2)="17",2017,IF(MID(D32,5,2)="18",2018,2019)))))))))))))))) -> 2003 | AM32: =COUNTIF([6]Daftar!$D$5:$D$851,D32) -> #VALUE! | AN32: =COUNTIF([7]daftar!$D$4:$D$885,D32) -> #VALUE! | AS32: =C32 -> Edi Waskita Putra | AT32: =D32 -> F1B003015 | AU32: =A32 -> 29
A33: =A32+1 -> 30 | B33: 40410 | C33: =VLOOKUP(D33,'[4]mhs elektro-kecil'!$B$5:$C$1847,2,0) -> Donny Adithia | D33: F1B005013 | E33: Rancang Bangun prototipe Pembangkit Listrik Gelombang Laut dengan Sistem Rakit | F33: Syafarudin Ch, S.T., M.T. | G33: Abdul Natsir, S.T., M.T. | H33: Ni Made Seniari, S.T., M.T. | I33: Ida Bagus Fery Citarsa, S.T., M.T. | J33: Rosmaliati, S.T., M.T. | K33: Selasa | L33: 40414 | M33: 08.00-10.00 | N33: R. Studio | O33: Lulus | Q33: 4 | R33: 14 | S33: 1 | T33: 12 | U33: 16 | W33: =TEXT(L33,"dd mmmm yyyy") -> 24 Agustus 2010 | X33: =IFERROR(VLOOKUP(D33,'[5]mhs elektro-kecil'!$B$5:$E$2151,3,0),"CEK") -> CEK | Y33: =IFERROR(VLOOKUP(D33,'[5]mhs elektro-kecil'!$B$5:$E$2151,4,0),"CEK") -> CEK | Z33: =L33 -> 40414 | AA33: =Z33+180 -> 40594 | AC33: Lulus | AI33: =MID(D33,5,2) -> 05 | AL33: =IF(MID(D33,5,2)="06",2006,IF(MID(D33,5,2)="07",2007,IF(MID(D33,5,2)="08",2008,IF(MID(D33,5,2)="09",2009,IF(MID(D33,5,2)="10",2010,IF(MID(D33,5,2)="11",2011,IF(MID(D33,5,2)="12",2012,IF(MID(D33,5,2)="05",2005,IF(MID(D33,5,2)="04",2004,IF(MID(D33,5,2)="03",2003,IF(MID(D33,5,2)="13",2013,IF(MID(D33,5,2)="14",2014,IF(MID(D33,5,2)="15",2015,IF(MID(D33,5,2)="16",2016,IF(MID(D33,5,2)="17",2017,IF(MID(D33,5,2)="18",2018,2019)))))))))))))))) -> 2005 | AM33: =COUNTIF([6]Daftar!$D$5:$D$851,D33) -> #VALUE! | AN33: =COUNTIF([7]daftar!$D$4:$D$885,D33) -> #VALUE! | AS33: =C33 -> Donny Adithia | AT33: =D33 -> F1B005013 | AU33: =A33 -> 30
A34: =A33+1 -> 31 | B34: 40450 | C34: =VLOOKUP(D34,'[4]mhs elektro-kecil'!$B$5:$C$1847,2,0) -> Supandi | D34: F1B005071 | E34: Economic Dispatch Menggunakan Algoritma Partikel Swarm Optimization | F34: I Made Ari Nrartha, S.T., M.T. | G34: Sultan, S.T., M.T. | H34: Supriyatna, S.T., M.T. | I34: Agung Budi Muljono, S.T., M.T. | J34: Sabar Nababan, S.T., M.T. | K34: Sabtu | L34: 40453 | M34: 08.00-10.00 | N34: R. Studio | O34: Lulus | Q34: 25 | R34: 5 | S34: 2 | T34: 13 | U34: 31 | W34: =TEXT(L34,"dd mmmm yyyy") -> 02 Oktober 2010 | X34: =IFERROR(VLOOKUP(D34,'[5]mhs elektro-kecil'!$B$5:$E$2151,3,0),"CEK") -> CEK | Y34: =IFERROR(VLOOKUP(D34,'[5]mhs elektro-kecil'!$B$5:$E$2151,4,0),"CEK") -> CEK | Z34: =L34 -> 40453 | AA34: =Z34+180 -> 40633 | AB34: =AA34+180 -> 40813 | AI34: =MID(D34,5,2) -> 05 | AL34: =IF(MID(D34,5,2)="06",2006,IF(MID(D34,5,2)="07",2007,IF(MID(D34,5,2)="08",2008,IF(MID(D34,5,2)="09",2009,IF(MID(D34,5,2)="10",2010,IF(MID(D34,5,2)="11",2011,IF(MID(D34,5,2)="12",2012,IF(MID(D34,5,2)="05",2005,IF(MID(D34,5,2)="04",2004,IF(MID(D34,5,2)="03",2003,IF(MID(D34,5,2)="13",2013,IF(MID(D34,5,2)="14",2014,IF(MID(D34,5,2)="15",2015,IF(MID(D34,5,2)="16",2016,IF(MID(D34,5,2)="17",2017,IF(MID(D34,5,2)="18",2018,2019)))))))))))))))) -> 2005 | AM34: =COUNTIF([6]Daftar!$D$5:$D$851,D34) -> #VALUE! | AN34: =COUNTIF([7]daftar!$D$4:$D$885,D34) -> #VALUE! | AS34: =C34 -> Supandi | AT34: =D34 -> F1B005071 | AU34: =A34 -> 31
A35: =A34+1 -> 32 | B35: 40454 | C35: =VLOOKUP(D35,'[4]mhs elektro-kecil'!$B$5:$C$1847,2,0) -> Prasetyadiguna | D35: F1B004063 | E35: Design Realisasi Power Splitter Mikrostrip pada Pemancar TV Kampus dengan Model Eksponensial Menggunakan HFSS | F35: Sudi M. Al Sasongko, S.T., M.T. | G35: Abdullah Zainuddin, S.T., M.T. | H35: Djul Fikry Budiman, S.T., M.T. | I35: Muhamad Syamsu Iqbal, S.T., M.T., Ph.D. | J35: Bulkis Kanata, S.T., M.T. | K35: Rabu | L35: 40457 | M35: 09.30-11.30 | N35: Lab. Telkom | O35: Lulus | Q35: 6 | R35: 15 | S35: 35 | T35: 18 | U35: 21 | W35: =TEXT(L35,"dd mmmm yyyy") -> 06 Oktober 2010 | X35: =IFERROR(VLOOKUP(D35,'[5]mhs elektro-kecil'!$B$5:$E$2151,3,0),"CEK") -> CEK | Y35: =IFERROR(VLOOKUP(D35,'[5]mhs elektro-kecil'!$B$5:$E$2151,4,0),"CEK") -> CEK | Z35: =L35 -> 40457 | AA35: =Z35+180 -> 40637 | AB35: =AA35+180 -> 40817 | AI35: =MID(D35,5,2) -> 04 | AL35: =IF(MID(D35,5,2)="06",2006,IF(MID(D35,5,2)="07",2007,IF(MID(D35,5,2)="08",2008,IF(MID(D35,5,2)="09",2009,IF(MID(D35,5,2)="10",2010,IF(MID(D35,5,2)="11",2011,IF(MID(D35,5,2)="12",2012,IF(MID(D35,5,2)="05",2005,IF(MID(D35,5,2)="04",2004,IF(MID(D35,5,2)="03",2003,IF(MID(D35,5,2)="13",2013,IF(MID(D35,5,2)="14",2014,IF(MID(D35,5,2)="15",2015,IF(MID(D35,5,2)="16",2016,IF(MID(D35,5,2)="17",2017,IF(MID(D35,5,2)="18",2018,2019)))))))))))))))) -> 2004 | AM35: =COUNTIF([6]Daftar!$D$5:$D$851,D35) -> #VALUE! | AN35: =COUNTIF([7]daftar!$D$4:$D$885,D35) -> #VALUE! | AS35: =C35 -> Prasetyadiguna | AT35: =D35 -> F1B004063 | AU35: =A35 -> 32
A36: =A35+1 -> 33 | B36: 40454 | C36: =VLOOKUP(D36,'[4]mhs elektro-kecil'!$B$5:$C$1847,2,0) -> Amir Hasanudin Fauzi | D36: F1B006008 | E36: Pattern Matching Method Based On Aho-Corasick Algorithm to Detect Malicious Code | F36: Dr. Rismon H. Sianipar, S.T., M.Eng. | G36: Heri Wijayanto, S.T., M.T. | H36: Budi Irmawati, S. Kom., M.T. | I36: I B K Widiartha, S.T., M.T. | J36: Muhamad Irwan, S.T., M.T. | K36: Rabu | L36: 40457 | M36: 07.30-09.30 | N36: Lab. Komputer | O36: Lulus | Q36: 33 | R36: 32 | S36: 20 | T36: 27 | U36: 39 | W36: =TEXT(L36,"dd mmmm yyyy") -> 06 Oktober 2010 | X36: =IFERROR(VLOOKUP(D36,'[5]mhs elektro-kecil'!$B$5:$E$2151,3,0),"CEK") -> CEK | Y36: =IFERROR(VLOOKUP(D36,'[5]mhs elektro-kecil'!$B$5:$E$2151,4,0),"CEK") -> CEK | Z36: =L36 -> 40457 | AA36: =Z36+180 -> 40637 | AC36: Lulus | AI36: =MID(D36,5,2) -> 06 | AL36: =IF(MID(D36,5,2)="06",2006,IF(MID(D36,5,2)="07",2007,IF(MID(D36,5,2)="08",2008,IF(MID(D36,5,2)="09",2009,IF(MID(D36,5,2)="10",2010,IF(MID(D36,5,2)="11",2011,IF(MID(D36,5,2)="12",2012,IF(MID(D36,5,2)="05",2005,IF(MID(D36,5,2)="04",2004,IF(MID(D36,5,2)="03",2003,IF(MID(D36,5,2)="13",2013,IF(MID(D36,5,2)="14",2014,IF(MID(D36,5,2)="15",2015,IF(MID(D36,5,2)="16",2016,IF(MID(D36,5,2)="17",2017,IF(MID(D36,5,2)="18",2018,2019)))))))))))))))) -> 2006 | AM36: =COUNTIF([6]Daftar!$D$5:$D$851,D36) -> #VALUE! | AN36: =COUNTIF([7]daftar!$D$4:$D$885,D36) -> #VALUE! | AS36: =C36 -> Amir Hasanudin Fauzi | AT36: =D36 -> F1B006008 | AU36: =A36 -> 33
A37: =A36+1 -> 34 | B37: 40483 | C37: =VLOOKUP(D37,'[4]mhs elektro-kecil'!$B$5:$C$1847,2,0) -> Siswadi | D37: F1B005067 | E37: Prototype Pengendalian System Buka Tutup Gerbang dan Berpengunci Otomatis Menggunakan Mikrokontroller ATMEGA 8535 | F37: Paniran, S.T., M.T. | G37: Supriono, S.T., M.T. | H37: Syafarudin Ch, S.T., M.T. | I37: I Made Budi Suksmadana, S.T., M.T. | J37: Ida Bagus Fery Citarsa, S.T., M.T. | K37: Kamis | L37: 40486 | M37: 08.00-10.00 | N37: R. D2 | O37: Lulus | Q37: 28 | R37: 29 | S37: 4 | T37: 24 | U37: 12 | W37: =TEXT(L37,"dd mmmm yyyy") -> 04 November 2010 | X37: =IFERROR(VLOOKUP(D37,'[5]mhs elektro-kecil'!$B$5:$E$2151,3,0),"CEK") -> CEK | Y37: =IFERROR(VLOOKUP(D37,'[5]mhs elektro-kecil'!$B$5:$E$2151,4,0),"CEK") -> CEK | Z37: =L37 -> 40486 | AA37: =Z37+180 -> 40666 | AB37: =AA37+180 -> 40846 | AI37: =MID(D37,5,2) -> 05 | AL37: =IF(MID(D37,5,2)="06",2006,IF(MID(D37,5,2)="07",2007,IF(MID(D37,5,2)="08",2008,IF(MID(D37,5,2)="09",2009,IF(MID(D37,5,2)="10",2010,IF(MID(D37,5,2)="11",2011,IF(MID(D37,5,2)="12",2012,IF(MID(D37,5,2)="05",2005,IF(MID(D37,5,2)="04",2004,IF(MID(D37,5,2)="03",2003,IF(MID(D37,5,2)="13",2013,IF(MID(D37,5,2)="14",2014,IF(MID(D37,5,2)="15",2015,IF(MID(D37,5,2)="16",2016,IF(MID(D37,5,2)="17",2017,IF(MID(D37,5,2)="18",2018,2019)))))))))))))))) -> 2005 | AM37: =COUNTIF([6]Daftar!$D$5:$D$851,D37) -> #VALUE! | AN37: =COUNTIF([7]daftar!$D$4:$D$885,D37) -> #VALUE! | AS37: =C37 -> Siswadi | AT37: =D37 -> F1B005067 | AU37: =A37 -> 34
A38: =A37+1 -> 35 | B38: 40483 | C38: =VLOOKUP(D38,'[4]mhs elektro-kecil'!$B$5:$C$1847,2,0) -> Fetty Nursofy Ristianty | D38: F1B006024 | E38: Simulasi Analisa Unjuk Kerja Transmisi Paket Data pada Jaringan GSM (Global System For Mobile) Menggunakan Network Simulator - 2 (NS2) | F38: Muhamad Syamsu Iqbal, S.T., M.T., Ph.D. | G38: Heri Wijayanto, S.T., M.T. | H38: Sudi M. Al Sasongko, S.T., M.T. | I38: Dr. Misbahuddin, S.T., M.T. | J38: Muhamad Irwan, S.T., M.T. | K38: Kamis | L38: 40486 | M38: 10.00-12.00 | N38: R. D2 | O38: Lulus | Q38: 18 | R38: 32 | S38: 6 | T38: 7 | U38: 39 | W38: =TEXT(L38,"dd mmmm yyyy") -> 04 November 2010 | X38: =IFERROR(VLOOKUP(D38,'[5]mhs elektro-kecil'!$B$5:$E$2151,3,0),"CEK") -> CEK | Y38: =IFERROR(VLOOKUP(D38,'[5]mhs elektro-kecil'!$B$5:$E$2151,4,0),"CEK") -> CEK | Z38: =L38 -> 40486 | AA38: =Z38+180 -> 40666 | AC38: Lulus | AI38: =MID(D38,5,2) -> 06 | AL38: =IF(MID(D38,5,2)="06",2006,IF(MID(D38,5,2)="07",2007,IF(MID(D38,5,2)="08",2008,IF(MID(D38,5,2)="09",2009,IF(MID(D38,5,2)="10",2010,IF(MID(D38,5,2)="11",2011,IF(MID(D38,5,2)="12",2012,IF(MID(D38,5,2)="05",2005,IF(MID(D38,5,2)="04",2004,IF(MID(D38,5,2)="03",2003,IF(MID(D38,5,2)="13",2013,IF(MID(D38,5,2)="14",2014,IF(MID(D38,5,2)="15",2015,IF(MID(D38,5,2)="16",2016,IF(MID(D38,5,2)="17",2017,IF(MID(D38,5,2)="18",2018,2019)))))))))))))))) -> 2006 | AM38: =COUNTIF([6]Daftar!$D$5:$D$851,D38) -> #VALUE! | AN38: =COUNTIF([7]daftar!$D$4:$D$885,D38) -> #VALUE! | AS38: =C38 -> Fetty Nursofy Ristianty | AT38: =D38 -> F1B006024 | AU38: =A38 -> 35
A39: =A38+1 -> 36 | B39: 40498 | C39: =VLOOKUP(D39,'[4]mhs elektro-kecil'!$B$5:$C$1847,2,0) -> En Mahsyar | D39: F1B006021 | E39: Perencanaan Instalasi Listrik yang Optimal dalam Menekan Pengaruh Interferensi Gelombang Elektromagnetik di Observatorium Geomagnetik Lombok (OGL) | F39: Dr.rer.nat. Teti Zubaidah, S.T., M.T. | G39: Sultan, S.T., M.T. | H39: Abdul Natsir, S.T., M.T. | I39: Rosmaliati, S.T., M.T. | J39: I Made Ari Nrartha, S.T., M.T. | K39: Sabtu | L39: 40502 | M39: 08.00-10.00 | N39: R. D2 | O39: Lulus | Q39: 22 | R39: 5 | S39: 14 | T39: 16 | U39: 25 | W39: =TEXT(L39,"dd mmmm yyyy") -> 20 November 2010 | X39: =IFERROR(VLOOKUP(D39,'[5]mhs elektro-kecil'!$B$5:$E$2151,3,0),"CEK") -> CEK | Y39: =IFERROR(VLOOKUP(D39,'[5]mhs elektro-kecil'!$B$5:$E$2151,4,0),"CEK") -> CEK | Z39: =L39 -> 40502 | AA39: =Z39+180 -> 40682 | AB39: =AA39+180 -> 40862 | AI39: =MID(D39,5,2) -> 06 | AL39: =IF(MID(D39,5,2)="06",2006,IF(MID(D39,5,2)="07",2007,IF(MID(D39,5,2)="08",2008,IF(MID(D39,5,2)="09",2009,IF(MID(D39,5,2)="10",2010,IF(MID(D39,5,2)="11",2011,IF(MID(D39,5,2)="12",2012,IF(MID(D39,5,2)="05",2005,IF(MID(D39,5,2)="04",2004,IF(MID(D39,5,2)="03",2003,IF(MID(D39,5,2)="13",2013,IF(MID(D39,5,2)="14",2014,IF(MID(D39,5,2)="15",2015,IF(MID(D39,5,2)="16",2016,IF(MID(D39,5,2)="17",2017,IF(MID(D39,5,2)="18",2018,2019)))))))))))))))) -> 2006 | AM39: =COUNTIF([6]Daftar!$D$5:$D$851,D39) -> #VALUE! | AN39: =COUNTIF([7]daftar!$D$4:$D$885,D39) -> #VALUE! | AS39: =C39 -> En Mahsyar | AT39: =D39 -> F1B006021 | AU39: =A39 -> 36
A40: =A39+1 -> 37 | B40: 40498 | C40: =VLOOKUP(D40,'[4]mhs elektro-kecil'!$B$5:$C$1847,2,0) -> Akbar Satryantho | D40: F1B005004 | E40: Sistem Kontrol dan Monitoring Meteo Payload Roket sebagai Aplikasi Pemantau Suhu dan Kelembaban diudara Menggunakan Teknologi Wireless YS-1020 | F40: I Made Budi Suksmadana, S.T., M.T. | G40: Paniran, S.T., M.T. | H40: Supriono, S.T., M.T. | I40: Syafarudin Ch, S.T., M.T. | J40: Muhamad Irwan, S.T., M.T. | K40: Sabtu | L40: 40502 | M40: 10.00-12.00 | N40: R. D2 | O40: Lulus | Q40: 24 | R40: 28 | S40: 29 | T40: 4 | U40: 39 | W40: =TEXT(L40,"dd mmmm yyyy") -> 20 November 2010 | X40: =IFERROR(VLOOKUP(D40,'[5]mhs elektro-kecil'!$B$5:$E$2151,3,0),"CEK") -> CEK | Y40: =IFERROR(VLOOKUP(D40,'[5]mhs elektro-kecil'!$B$5:$E$2151,4,0),"CEK") -> CEK | Z40: =L40 -> 40502 | AA40: =Z40+180 -> 40682 | AC40: Lulus | AI40: =MID(D40,5,2) -> 05 | AL40: =IF(MID(D40,5,2)="06",2006,IF(MID(D40,5,2)="07",2007,IF(MID(D40,5,2)="08",2008,IF(MID(D40,5,2)="09",2009,IF(MID(D40,5,2)="10",2010,IF(MID(D40,5,2)="11",2011,IF(MID(D40,5,2)="12",2012,IF(MID(D40,5,2)="05",2005,IF(MID(D40,5,2)="04",2004,IF(MID(D40,5,2)="03",2003,IF(MID(D40,5,2)="13",2013,IF(MID(D40,5,2)="14",2014,IF(MID(D40,5,2)="15",2015,IF(MID(D40,5,2)="16",2016,IF(MID(D40,5,2)="17",2017,IF(MID(D40,5,2)="18",2018,2019)))))))))))))))) -> 2005 | AM40: =COUNTIF([6]Daftar!$D$5:$D$851,D40) -> #VALUE! | AN40: =COUNTIF([7]daftar!$D$4:$D$885,D40) -> #VALUE! | AS40: =C40 -> Akbar Satryantho | AT40: =D40 -> F1B005004 | AU40: =A40 -> 37
A41: =A40+1 -> 38 | B41: 40501 | C41: =VLOOKUP(D41,'[4]mhs elektro-kecil'!$B$5:$C$1847,2,0) -> Rosiawan | D41: F1B006073 | E41: Pengukuran dan Analisa Pengaruh Interferensi terhadap Quality of Service (QOS) pada Standar Jaringan 802.11B | F41: Abdullah Zainuddin, S.T., M.T. | G41: Sudi M. Al Sasongko, S.T., M.T. | H41: Muhamad Syamsu Iqbal, S.T., M.T., Ph.D. | I41: Djul Fikry Budiman, S.T., M.T. | J41: Lalu A. Syamsul Irfan A., S.T., M.Eng. | K41: Sabtu | L41: 40502 | M41: 10.00-12.00 | N41: R. Studio | O41: Lulus | Q41: 15 | R41: 6 | S41: 18 | T41: 35 | U41: 40 | W41: =TEXT(L41,"dd mmmm yyyy") -> 20 November 2010 | X41: =IFERROR(VLOOKUP(D41,'[5]mhs elektro-kecil'!$B$5:$E$2151,3,0),"CEK") -> CEK | Y41: =IFERROR(VLOOKUP(D41,'[5]mhs elektro-kecil'!$B$5:$E$2151,4,0),"CEK") -> CEK | Z41: =L41 -> 40502 | AA41: =Z41+180 -> 40682 | AC41: Lulus | AI41: =MID(D41,5,2) -> 06 | AL41: =IF(MID(D41,5,2)="06",2006,IF(MID(D41,5,2)="07",2007,IF(MID(D41,5,2)="08",2008,IF(MID(D41,5,2)="09",2009,IF(MID(D41,5,2)="10",2010,IF(MID(D41,5,2)="11",2011,IF(MID(D41,5,2)="12",2012,IF(MID(D41,5,2)="05",2005,IF(MID(D41,5,2)="04",2004,IF(MID(D41,5,2)="03",2003,IF(MID(D41,5,2)="13",2013,IF(MID(D41,5,2)="14",2014,IF(MID(D41,5,2)="15",2015,IF(MID(D41,5,2)="16",2016,IF(MID(D41,5,2)="17",2017,IF(MID(D41,5,2)="18",2018,2019)))))))))))))))) -> 2006 | AM41: =COUNTIF([6]Daftar!$D$5:$D$851,D41) -> #VALUE! | AN41: =COUNTIF([7]daftar!$D$4:$D$885,D41) -> #VALUE! | AS41: =C41 -> Rosiawan | AT41: =D41 -> F1B006073 | AU41: =A41 -> 38
...

Sheet u kon
A8: Nomor | B8: : | D8: /UN18.F6./TE/EP/2020 | J8: =VLOOKUP(N8,data,2,M80) -> 6 Juli 2020 | N8: 759
A9: Lamp. | B9: : | C9: 1 (satu) eksemplar
A10: H a l | B10: : | C10: Undangan Seminar Proposal Tugas Akhir
A13: Yth. Bapak/Ibu | D13: : | E13: ………………………………………………..
A14: Dosen Pembimbing & Penguji Seminar Proposal Tugas akhir
A15: Mataram
A18: Sesuai dengan permohonan mahasiswa atas nama :
A20: N a m a | D20: : | E20: =VLOOKUP($N$8,data,3,0) -> M. Rivaldi Harjian
A21: N I M | D21: : | E21: =VLOOKUP($N$8,data,4,0) -> F1B016055
A22: Judul Proposal TA | D22: : | E22: =VLOOKUP(N8,data,5,0) -> Analisis Keandalan Sistem Distribusi 20 KV Pada Gardu Induk Kuta PT. PLN Unit Layanan Pelanggan Praya Menggunakan Metode Section Technique Dan FMEA (Failure Model And Effect Analysis)
A25: Tentang permohonan Seminar Proposal Tugas Akhir, maka dengan ini ditugaskan sebagai Tim Penguji Seminar proposal Tugas Akhir sebagai berikut :
A28: 1 | C28: =VLOOKUP($N$8,data,6,0) -> Supriyatna, S.T., M.T. | I28: Pembimbing Utama
A29: 2 | C29: =VLOOKUP($N$8,data,7,0) -> Ir. Agung Budi Muljono, S.T., M.T., IPU. | I29: Pembimbing Pendamping
A30: 3 | C30: =VLOOKUP($N$8,data,8,0) -> Dr. rer. nat. Teti Zubaidah, S.T., M.T. | I30: Penguji 1
A31: 4 | C31: =VLOOKUP($N$8,data,9,0) -> Dr. Ir. I Made Ginarsa, S.T., M.T., IPU. | I31: Penguji 2
A32: 5 | C32: =VLOOKUP($N$8,data,10,0) -> Ir. I Made Ari Nrartha, S.T., M.T. | I32: Penguji 3
A34: Seminar Proposal Tugas Akhir akan dilaksanakan pada :
A36: Hari | B36: : | C36: =VLOOKUP($N$8,data,11,0) -> Rabu
A37: Tanggal | B37: : | C37: =VLOOKUP($N$8,data,12,0) -> 44020
A38: Waktu | B38: : | C38: =VLOOKUP($N$8,data,13,0) -> 13.30-15.00
A39: Tempat | B39: : | C39: =VLOOKUP($N$8,data,14,0) -> Secara online dengan aplikasi Zoom
A41: Demikian atas perhatian dan kerjasamanya disampaikan, terima kasih.
N43: Ketua,
H44: Sekretaris I,
R45: Sekretaris I,
N47: Sudi Mariyanto Al Sasongko, ST., MT.
H48: Dr. Misbahuddin, S.T., M.T. | N48: NIP. 19670526 199703 1 001
H49: NIP 196810051997031001 | N49: Sekretaris I, | R49: Syafaruddin Ch., ST., MT.
A50: Catatan : | R50: NIP. 19690612 199702 1 001
A51: - Jika bapak/ibu dosen Pembimbing dan Penguji berhalangan hadir, agar melapor ke Ketua/Sekretaris
A52: JTE paling lambat H-3 (baik lapor secara langsung atau melalui perwakilan/mahasiswa)
A53: - Jika Ketua Tim Penguji yang ditunjuk berhalangan/terlambat datang, maka Ketua Tim Penguji dapat | N53: Dr. Misbahuddin, S.T., M.T. | R53: Ketua,
A54: digantikan oleh penguji 2 dan 3, atau berdasarkan kesepakatan | N54: NIP 196810051997031001
R57: Muhamad Syamsu Iqbal, S.T., M.T., Ph.D.
R58: NIP 197202221999031002

Sheet u jadi
A7: Nomor | B7: : | C7: =VLOOKUP($N$7,data,16,0) -> 301 | D7: /UN18.F6./TE/EP/2025 | J7: =VLOOKUP(N7,data,2,0) -> 45849 | N7: 1348 | O7: 890
A8: Lamp. | B8: : | C8: 1 (satu) eksemplar | N8: 0
A9: H a l | B9: : | C9: Undangan Seminar Proposal Tugas Akhir
A12: Yth. Bapak/Ibu | D12: : | E12: ………………………………………………..
A13: Dosen Pembimbing & Penguji Seminar Proposal Tugas akhir
A14: Mataram
