Workbook

Sheet ELEKTRO
A1: DAFTAR PEMBAGIAN DOSEN WALI MAHASISWA
A2: JURUSAN TEKNIK ELEKTRO - REGULER
A3: ANGKATAN TAHUN 2018
A5: NO | B5: NIM | C5: NAMA | D5: DOSEN WALI | E5: NIP
A6: 1 | B6: F1B018001 | C6: AHMAD FAZLIN ARDIAN | D6: Ni Made Seniari, ST., MT. | E6: 19700320 199702 2 001 | G6: 1 | I6: =VLOOKUP(G6,[1]Sheet2!$A$6:$F$43,5,0) -> "197003201997022001"
A7: =A6+1 -> 2 | B7: F1B018002 | C7: AHMAD UMAR | D7: Ni Made Seniari, ST., MT. | E7: 19700320 199702 2 001 | G7: =G6 -> 1 | I7: =VLOOKUP(G7,[1]Sheet2!$A$6:$F$43,5,0) -> "197003201997022001"
A8: =A7+1 -> 3 | B8: F1B018003 | C8: ALDYKA FALERA | D8: Ni Made Seniari, ST., MT. | E8: 19700320 199702 2 001 | G8: =G7 -> 1 | I8: =VLOOKUP(G8,[1]Sheet2!$A$6:$F$43,5,0) -> "197003201997022001"
A9: =A8+1 -> 4 | B9: F1B018004 | C9: ALFAN FADHILA RAMDHANI | D9: Supriyatna, ST., MT. | E9: 19710607 199702 1 002 | G9: 2 | I9: =VLOOKUP(G9,[1]Sheet2!$A$6:$F$43,5,0) -> "197106071997021002"
A10: =A9+1 -> 5 | B10: F1B018005 | C10: ALFATH MAULANA | D10: Supriyatna, ST., MT. | E10: 19710607 199702 1 002 | G10: =G9 -> 2 | I10: =VLOOKUP(G10,[1]Sheet2!$A$6:$F$43,5,0) -> "197106071997021002"
A11: =A10+1 -> 6 | B11: F1B018006 | C11: ANDIKA PRAKOSO | D11: Supriyatna, ST., MT. | E11: 19710607 199702 1 002 | G11: =G10 -> 2 | I11: =VLOOKUP(G11,[1]Sheet2!$A$6:$F$43,5,0) -> "197106071997021002"
A12: =A11+1 -> 7 | B12: F1B018007 | C12: ANGGA DANISTIAN | D12: I Ketut Wiryajati, ST., MT. | E12: 19660424 199702 1 001 | G12: 3 | I12: =VLOOKUP(G12,[1]Sheet2!$A$6:$F$43,5,0) -> "196604241997021001"
A13: =A12+1 -> 8 | B13: F1B018008 | C13: ANGGA ROJALI | D13: I Ketut Wiryajati, ST., MT. | E13: 19660424 199702 1 001 | G13: =G12 -> 3 | I13: =VLOOKUP(G13,[1]Sheet2!$A$6:$F$43,5,0) -> "196604241997021001"
A14: =A13+1 -> 9 | B14: F1B018009 | C14: ARI SATRIA | D14: I Ketut Wiryajati, ST., MT. | E14: 19660424 199702 1 001 | G14: =G13 -> 3 | I14: =VLOOKUP(G14,[1]Sheet2!$A$6:$F$43,5,0) -> "196604241997021001"
A15: =A14+1 -> 10 | B15: F1B018010 | C15: BADRUL MUHAYAT | D15: Syafaruddin Ch., ST., MT. | E15: 19690612 199702 1 001 | G15: 4 | I15: =VLOOKUP(G15,[1]Sheet2!$A$6:$F$43,5,0) -> "196906121997021001"
A16: =A15+1 -> 11 | B16: F1B018011 | C16: BAGI HARTAWAN | D16: Syafaruddin Ch., ST., MT. | E16: 19690612 199702 1 001 | G16: =G15 -> 4 | I16: =VLOOKUP(G16,[1]Sheet2!$A$6:$F$43,5,0) -> "196906121997021001"
A17: =A16+1 -> 12 | B17: F1B018012 | C17: BAIK ZOHRATUL WARDAH | D17: Syafaruddin Ch., ST., MT. | E17: 19690612 199702 1 001 | G17: =G16 -> 4 | I17: =VLOOKUP(G17,[1]Sheet2!$A$6:$F$43,5,0) -> "196906121997021001"
A18: =A17+1 -> 13 | B18: F1B018013 | C18: BRIAN ABIYASA AJI PRATAMA | D18: Sultan, ST., MT. | E18: 19671231 199702 1 001 | G18: 5 | I18: =VLOOKUP(G18,[1]Sheet2!$A$6:$F$43,5,0) -> "196712311997021001"
A19: =A18+1 -> 14 | B19: F1B018014 | C19: DEWA MADE ANOM DIRGANTARA | D19: Sultan, ST., MT. | E19: 19671231 199702 1 001 | G19: =G18 -> 5 | I19: =VLOOKUP(G19,[1]Sheet2!$A$6:$F$43,5,0) -> "196712311997021001"
A20: =A19+1 -> 15 | B20: F1B018015 | C20: DIO YUDHA PRAWIRA BAKARY | D20: Sultan, ST., MT. | E20: 19671231 199702 1 001 | G20: =G19 -> 5 | I20: =VLOOKUP(G20,[1]Sheet2!$A$6:$F$43,5,0) -> "196712311997021001"
A21: =A20+1 -> 16 | B21: F1B018016 | C21: DIWAN ZINI ARSI | D21: Sudi M. Al Sasongko, ST., MT. | E21: 19670526 199703 1 001 | G21: 6 | I21: =VLOOKUP(G21,[1]Sheet2!$A$6:$F$43,5,0) -> "196705261997031001"
A22: =A21+1 -> 17 | B22: F1B018017 | C22: EKA RIZKY ADHANSYAH ALATHAS | D22: Sudi M. Al Sasongko, ST., MT. | E22: 19670526 199703 1 001 | G22: 6 | I22: =VLOOKUP(G22,[1]Sheet2!$A$6:$F$43,5,0) -> "196705261997031001"
A23: =A22+1 -> 18 | B23: F1B018018 | C23: EVANIA ERNESTIN CHANDRA | D23: Sudi M. Al Sasongko, ST., MT. | E23: 19670526 199703 1 001 | G23: =G22 -> 6 | I23: =VLOOKUP(G23,[1]Sheet2!$A$6:$F$43,5,0) -> "196705261997031001"
A24: =A23+1 -> 19 | B24: F1B018019 | C24: FAHRU RAHMAN | D24: Dr. Misbahuddin, ST., MT. | E24: 19681005 199703 1 001 | G24: 7 | I24: =VLOOKUP(G24,[1]Sheet2!$A$6:$F$43,5,0) -> "196810051997031001"
A25: =A24+1 -> 20 | B25: F1B018020 | C25: FIDYAH AJENG WULANDARI | D25: Dr. Misbahuddin, ST., MT. | E25: 19681005 199703 1 001 | G25: =G24 -> 7 | I25: =VLOOKUP(G25,[1]Sheet2!$A$6:$F$43,5,0) -> "196810051997031001"
A26: =A25+1 -> 21 | B26: F1B018021 | C26: FIKRI | D26: Dr. Misbahuddin, ST., MT. | E26: 19681005 199703 1 001 | G26: =G25 -> 7 | I26: =VLOOKUP(G26,[1]Sheet2!$A$6:$F$43,5,0) -> "196810051997031001"
A27: =A26+1 -> 22 | B27: F1B018022 | C27: FRANSISKUS XAVERIUS ARIO SETYOAJIE | D27: I Nyoman Wahyu S., ST., M.Sc., Ph.D. | E27: 19700908 199802 1 001 | G27: 8 | I27: =VLOOKUP(G27,[1]Sheet2!$A$6:$F$43,5,0) -> "197009081998021001"
A28: =A27+1 -> 23 | B28: F1B018023 | C28: HAFIZAH | D28: I Nyoman Wahyu S., ST., M.Sc., Ph.D. | E28: 19700908 199802 1 001 | G28: =G27 -> 8 | I28: =VLOOKUP(G28,[1]Sheet2!$A$6:$F$43,5,0) -> "197009081998021001"
A29: =A28+1 -> 24 | B29: F1B018024 | C29: HAQQI FITRAH AMRI | D29: I Nyoman Wahyu S., ST., M.Sc., Ph.D. | E29: 19700908 199802 1 001 | G29: =G28 -> 8 | I29: =VLOOKUP(G29,[1]Sheet2!$A$6:$F$43,5,0) -> "197009081998021001"
A30: =A29+1 -> 25 | B30: F1B018025 | C30: I GUSTI BAGUS ADI PRAMANA | D30: Cahyo Mustiko O.M., ST., M.Sc., Ph.D. | E30: 19691028 199802 1 001 | G30: 9 | I30: =VLOOKUP(G30,[1]Sheet2!$A$6:$F$43,5,0) -> "196910281998021001"
A31: =A30+1 -> 26 | B31: F1B018026 | C31: I MADE DWI ANDIKA SAPUTRA | D31: Cahyo Mustiko O.M., ST., M.Sc., Ph.D. | E31: 19691028 199802 1 001 | G31: =G30 -> 9 | I31: =VLOOKUP(G31,[1]Sheet2!$A$6:$F$43,5,0) -> "196910281998021001"
A32: =A31+1 -> 27 | B32: F1B018027 | C32: I MADE GDE YUDI DARMAWAN | D32: Cahyo Mustiko O.M., ST., M.Sc., Ph.D. | E32: 19691028 199802 1 001 | G32: =G31 -> 9 | I32: =VLOOKUP(G32,[1]Sheet2!$A$6:$F$43,5,0) -> "196910281998021001"
A33: =A32+1 -> 28 | B33: F1B018028 | C33: ILHAM ZAHIDIN | D33: Dr. Ida Ayu Sri Adnyani, ST., MErg. | E33: 19700823 199802 2 001 | G33: 10 | I33: =VLOOKUP(G33,[1]Sheet2!$A$6:$F$43,5,0) -> "197008231998022001"
A34: =A33+1 -> 29 | B34: F1B018029 | C34: IMAM EFENDI | D34: Dr. Ida Ayu Sri Adnyani, ST., MErg. | E34: 19700823 199802 2 001 | G34: =G33 -> 10 | I34: =VLOOKUP(G34,[1]Sheet2!$A$6:$F$43,5,0) -> "197008231998022001"
A35: =A34+1 -> 30 | B35: F1B018030 | C35: ISLAHUL ANWAR | D35: Dr. Ida Ayu Sri Adnyani, ST., MErg. | E35: 19700823 199802 2 001 | G35: =G34 -> 10 | I35: =VLOOKUP(G35,[1]Sheet2!$A$6:$F$43,5,0) -> "197008231998022001"
A36: =A35+1 -> 31 | B36: F1B018031 | C36: KAROMATUL HIKMAH | D36: Ida Bagus Fery Citarsa, ST., MT. | E36: 19740226 199803 1 004 | G36: 12 | I36: =VLOOKUP(G36,[1]Sheet2!$A$6:$F$43,5,0) -> "197402261998031004"
A37: =A36+1 -> 32 | B37: F1B018032 | C37: KHAERUL KUSUMA | D37: Ida Bagus Fery Citarsa, ST., MT. | E37: 19740226 199803 1 004 | G37: =G36 -> 12 | I37: =VLOOKUP(G37,[1]Sheet2!$A$6:$F$43,5,0) -> "197402261998031004"
A38: =A37+1 -> 33 | B38: F1B018033 | C38: KOMANG DANDY SURYA ADRIAWAN | D38: Ida Bagus Fery Citarsa, ST., MT. | E38: 19740226 199803 1 004 | G38: =G37 -> 12 | I38: =VLOOKUP(G38,[1]Sheet2!$A$6:$F$43,5,0) -> "197402261998031004"
A39: =A38+1 -> 34 | B39: F1B018034 | C39: LALU WIR HANAN HADI | D39: Agung Budi Muljono, ST., MT. | E39: 19710211 199803 1 002 | G39: 13 | I39: =VLOOKUP(G39,[1]Sheet2!$A$6:$F$43,5,0) -> "197102111998031002"
A40: =A39+1 -> 35 | B40: F1B018035 | C40: M. WAWAN KURNIAWAN | D40: Agung Budi Muljono, ST., MT. | E40: 19710211 199803 1 002 | G40: =G39 -> 13 | I40: =VLOOKUP(G40,[1]Sheet2!$A$6:$F$43,5,0) -> "197102111998031002"
A41: =A40+1 -> 36 | B41: F1B018036 | C41: MARIA GABRIELA FALENSIA WATU | D41: Agung Budi Muljono, ST., MT. | E41: 19710211 199803 1 002 | G41: =G40 -> 13 | I41: =VLOOKUP(G41,[1]Sheet2!$A$6:$F$43,5,0) -> "197102111998031002"
...

Sheet ELEKTRO SORE
A1: DAFTAR PEMBAGIAN DOSEN WALI MAHASISWA
A2: JURUSAN TEKNIK ELEKTRO - NON REGULER
A3: ANGKATAN TAHUN 2018
A5: NO | B5: NIM | C5: NAMA | D5: DOSEN WALI | E5: NIP | L5: NR
A6: 1 | B6: F1B118001 | C6: ANDI AZBAR | D6: Ni Made Seniari, ST., MT. | E6: 19700320 199702 2 001 | G6: 1 | I6: =VLOOKUP(G6,[1]Sheet2!$A$6:$F$43,5,0) -> "197003201997022001" | K6: Dr. Ida Ayu Sri Adnyani, ST., MErg. | L6: =COUNTIF($D$6:$D$70,K6) -> 2 | M6: =COUNTIF(ELEKTRO!$D$6:$D$105,'ELEKTRO SORE'!K6) -> 3 | N6: 2 | O6: 5 | Q6: 1 | R6: 1
A7: =A6+1 -> 2 | B7: F1B118002 | C7: DANI ANWAR MUSADDAT | D7: Ni Made Seniari, ST., MT. | E7: 19700320 199702 2 001 | G7: =G6 -> 1 | I7: =VLOOKUP(G7,[1]Sheet2!$A$6:$F$43,5,0) -> "197003201997022001" | K7: Abdul Natsir, ST., MT. | L7: =COUNTIF($D$6:$D$70,K7) -> 2 | M7: =COUNTIF(ELEKTRO!$D$6:$D$105,'ELEKTRO SORE'!K7) -> 3 | N7: 2 | O7: 4 | Q7: =Q6+1 -> 2
A8: =A7+1 -> 3 | B8: F1B118003 | C8: RODY SAFRI IRAWANSYAH | D8: Supriyatna, ST., MT. | E8: 19710607 199702 1 002 | G8: 2 | I8: =VLOOKUP(G8,[1]Sheet2!$A$6:$F$43,5,0) -> "197106071997021002" | K8: Cahyo Mustiko O.M., ST., M.Sc., Ph.D. | L8: =COUNTIF($D$6:$D$70,K8) -> 2 | M8: =COUNTIF(ELEKTRO!$D$6:$D$105,'ELEKTRO SORE'!K8) -> 3 | N8: 4 | O8: 3 | Q8: =Q7+1 -> 3
A9: =A8+1 -> 4 | B9: F1B118004 | C9: ADAM HADI WIBOWO | D9: Supriyatna, ST., MT. | E9: 19710607 199702 1 002 | G9: =G8 -> 2 | I9: =VLOOKUP(G9,[1]Sheet2!$A$6:$F$43,5,0) -> "197106071997021002" | K9: Supriono, ST., MT. | L9: =COUNTIF($D$6:$D$70,K9) -> 2 | M9: =COUNTIF(ELEKTRO!$D$6:$D$105,'ELEKTRO SORE'!K9) -> 3 | N9: 4 | O9: 3 | Q9: =Q8+1 -> 4
A10: =A9+1 -> 5 | B10: F1B118005 | C10: AFRIZAL ALIMUDIN | D10: I Ketut Wiryajati, ST., MT. | E10: 19660424 199702 1 001 | G10: 3 | I10: =VLOOKUP(G10,[1]Sheet2!$A$6:$F$43,5,0) -> "196604241997021001" | K10: Abdullah Zainuddin, ST., MT. | L10: =COUNTIF($D$6:$D$70,K10) -> 2 | M10: =COUNTIF(ELEKTRO!$D$6:$D$105,'ELEKTRO SORE'!K10) -> 3 | N10: 3 | O10: 3 | Q10: =Q9+1 -> 5
A11: =A10+1 -> 6 | B11: F1B118006 | C11: AHMAD ZULKUSWARI | D11: I Ketut Wiryajati, ST., MT. | E11: 19660424 199702 1 001 | G11: =G10 -> 3 | I11: =VLOOKUP(G11,[1]Sheet2!$A$6:$F$43,5,0) -> "196604241997021001" | K11: Bulkis Kanata, ST., MT. | L11: =COUNTIF($D$6:$D$70,K11) -> 2 | M11: =COUNTIF(ELEKTRO!$D$6:$D$105,'ELEKTRO SORE'!K11) -> 3 | N11: 3 | O11: 3 | Q11: =Q10+1 -> 6
A12: =A11+1 -> 7 | B12: F1B118007 | C12: ALFIYANI ADILAH | D12: Syafaruddin Ch., ST., MT. | E12: 19690612 199702 1 001 | G12: 4 | I12: =VLOOKUP(G12,[1]Sheet2!$A$6:$F$43,5,0) -> "196906121997021001" | K12: Ni Made Seniari, ST., MT. | L12: =COUNTIF($D$6:$D$70,K12) -> 2 | M12: =COUNTIF(ELEKTRO!$D$6:$D$105,'ELEKTRO SORE'!K12) -> 3 | N12: 2 | O12: 3 | Q12: =Q11+1 -> 7
A13: =A12+1 -> 8 | B13: F1B118008 | C13: AMRINA ROSYIDA | D13: Syafaruddin Ch., ST., MT. | E13: 19690612 199702 1 001 | G13: =G12 -> 4 | I13: =VLOOKUP(G13,[1]Sheet2!$A$6:$F$43,5,0) -> "196906121997021001" | K13: Supriyatna, ST., MT. | L13: =COUNTIF($D$6:$D$70,K13) -> 2 | M13: =COUNTIF(ELEKTRO!$D$6:$D$105,'ELEKTRO SORE'!K13) -> 3 | N13: 2 | O13: 3 | Q13: =Q12+1 -> 8
A14: =A13+1 -> 9 | B14: F1B118009 | C14: ANDI TRI RAMDHANY | D14: Sultan, ST., MT. | E14: 19671231 199702 1 001 | G14: 5 | I14: =VLOOKUP(G14,[1]Sheet2!$A$6:$F$43,5,0) -> "196712311997021001" | K14: I Ketut Wiryajati, ST., MT. | L14: =COUNTIF($D$6:$D$70,K14) -> 2 | M14: =COUNTIF(ELEKTRO!$D$6:$D$105,'ELEKTRO SORE'!K14) -> 3 | N14: 2 | O14: 3 | Q14: =Q13+1 -> 9
A15: =A14+1 -> 10 | B15: F1B118010 | C15: ANDRI WAHYUDI | D15: Sultan, ST., MT. | E15: 19671231 199702 1 001 | G15: =G14 -> 5 | I15: =VLOOKUP(G15,[1]Sheet2!$A$6:$F$43,5,0) -> "196712311997021001" | K15: Syafaruddin Ch., ST., MT. | L15: =COUNTIF($D$6:$D$70,K15) -> 2 | M15: =COUNTIF(ELEKTRO!$D$6:$D$105,'ELEKTRO SORE'!K15) -> 3 | N15: 2 | O15: 3 | Q15: =Q14+1 -> 10
A16: =A15+1 -> 11 | B16: F1B118011 | C16: ARINDA SAFIRA | D16: Sudi M. Al Sasongko, ST., MT. | E16: 19670526 199703 1 001 | G16: 6 | I16: =VLOOKUP(G16,[1]Sheet2!$A$6:$F$43,5,0) -> "196705261997031001" | K16: Sultan, ST., MT. | L16: =COUNTIF($D$6:$D$70,K16) -> 2 | M16: =COUNTIF(ELEKTRO!$D$6:$D$105,'ELEKTRO SORE'!K16) -> 3 | N16: 2 | O16: 3 | Q16: =Q15+1 -> 11
A17: =A16+1 -> 12 | B17: F1B118012 | C17: AYNUL YAQIN | D17: Sudi M. Al Sasongko, ST., MT. | E17: 19670526 199703 1 001 | G17: =G16 -> 6 | I17: =VLOOKUP(G17,[1]Sheet2!$A$6:$F$43,5,0) -> "196705261997031001" | K17: Sudi M. Al Sasongko, ST., MT. | L17: =COUNTIF($D$6:$D$70,K17) -> 2 | M17: =COUNTIF(ELEKTRO!$D$6:$D$105,'ELEKTRO SORE'!K17) -> 3 | N17: 2 | O17: 3 | Q17: =Q16+1 -> 12
A18: =A17+1 -> 13 | B18: F1B118013 | C18: BOY TIMOTIUS HUTAURUK | D18: Dr. Misbahuddin, ST., MT. | E18: 19681005 199703 1 001 | G18: 7 | I18: =VLOOKUP(G18,[1]Sheet2!$A$6:$F$43,5,0) -> "196810051997031001" | K18: Dr. Misbahuddin, ST., MT. | L18: =COUNTIF($D$6:$D$70,K18) -> 2 | M18: =COUNTIF(ELEKTRO!$D$6:$D$105,'ELEKTRO SORE'!K18) -> 3 | N18: 2 | O18: 3 | Q18: =Q17+1 -> 13
A19: =A18+1 -> 14 | B19: F1B118014 | C19: DEA HILFIANA | D19: Dr. Misbahuddin, ST., MT. | E19: 19681005 199703 1 001 | G19: =G18 -> 7 | I19: =VLOOKUP(G19,[1]Sheet2!$A$6:$F$43,5,0) -> "196810051997031001" | K19: I Nyoman Wahyu S., ST., M.Sc., Ph.D. | L19: =COUNTIF($D$6:$D$70,K19) -> 2 | M19: =COUNTIF(ELEKTRO!$D$6:$D$105,'ELEKTRO SORE'!K19) -> 3 | N19: 2 | O19: 3 | Q19: =Q18+1 -> 14
A20: =A19+1 -> 15 | B20: F1B118015 | C20: DECKY ARDHYADWIPA JANUSTANTO | D20: I Nyoman Wahyu S., ST., M.Sc., Ph.D. | E20: 19700908 199802 1 001 | G20: 8 | I20: =VLOOKUP(G20,[1]Sheet2!$A$6:$F$43,5,0) -> "197009081998021001" | K20: Ida Bagus Fery Citarsa, ST., MT. | L20: =COUNTIF($D$6:$D$70,K20) -> 2 | M20: =COUNTIF(ELEKTRO!$D$6:$D$105,'ELEKTRO SORE'!K20) -> 3 | N20: 2 | O20: 3 | Q20: =Q19+1 -> 15
A21: =A20+1 -> 16 | B21: F1B118016 | C21: DIDIN SETIAWAN | D21: I Nyoman Wahyu S., ST., M.Sc., Ph.D. | E21: 19700908 199802 1 001 | G21: =G20 -> 8 | I21: =VLOOKUP(G21,[1]Sheet2!$A$6:$F$43,5,0) -> "197009081998021001" | K21: Agung Budi Muljono, ST., MT. | L21: =COUNTIF($D$6:$D$70,K21) -> 2 | M21: =COUNTIF(ELEKTRO!$D$6:$D$105,'ELEKTRO SORE'!K21) -> 3 | N21: 2 | O21: 3 | Q21: =Q20+1 -> 16
A22: =A21+1 -> 17 | B22: F1B118017 | C22: ENRICO ANANTA PRATAMA | D22: Cahyo Mustiko O.M., ST., M.Sc., Ph.D. | E22: 19691028 199802 1 001 | G22: 9 | I22: =VLOOKUP(G22,[1]Sheet2!$A$6:$F$43,5,0) -> "196910281998021001" | K22: Muhamad Syamsu Iqbal, ST., MT., Ph.D. | L22: =COUNTIF($D$6:$D$70,K22) -> 2 | M22: =COUNTIF(ELEKTRO!$D$6:$D$105,'ELEKTRO SORE'!K22) -> 3 | N22: 2 | O22: 3 | Q22: =Q21+1 -> 17
A23: =A22+1 -> 18 | B23: F1B118018 | C23: GALLAN EKA RAMADHANI | D23: Cahyo Mustiko O.M., ST., M.Sc., Ph.D. | E23: 19691028 199802 1 001 | G23: =G22 -> 9 | I23: =VLOOKUP(G23,[1]Sheet2!$A$6:$F$43,5,0) -> "196910281998021001" | K23: Made Sutha Yadnya, ST., MT. | L23: =COUNTIF($D$6:$D$70,K23) -> 2 | M23: =COUNTIF(ELEKTRO!$D$6:$D$105,'ELEKTRO SORE'!K23) -> 3 | N23: 2 | O23: 3 | Q23: =Q22+1 -> 18
A24: =A23+1 -> 19 | B24: F1B118019 | C24: GURUH KHEDAR NURMAHSYA | D24: Dr. Ida Ayu Sri Adnyani, ST., MErg. | E24: 19700823 199802 2 001 | G24: 10 | I24: =VLOOKUP(G24,[1]Sheet2!$A$6:$F$43,5,0) -> "197008231998022001" | K24: Dr. rer.nat. Teti Zubaidah, ST., MT. | L24: =COUNTIF($D$6:$D$70,K24) -> 2 | M24: =COUNTIF(ELEKTRO!$D$6:$D$105,'ELEKTRO SORE'!K24) -> 3 | N24: 2 | O24: 3 | Q24: =Q23+1 -> 19
A25: =A24+1 -> 20 | B25: F1B118020 | C25: I KOMANG YOGA TRI PRANATA | D25: Dr. Ida Ayu Sri Adnyani, ST., MErg. | E25: 19700823 199802 2 001 | G25: =G24 -> 10 | I25: =VLOOKUP(G25,[1]Sheet2!$A$6:$F$43,5,0) -> "197008231998022001" | K25: I Made Ari Nrartha, ST., MT. | L25: =COUNTIF($D$6:$D$70,K25) -> 2 | M25: =COUNTIF(ELEKTRO!$D$6:$D$105,'ELEKTRO SORE'!K25) -> 3 | N25: 2 | O25: 3 | Q25: =Q24+1 -> 20
A26: =A25+1 -> 21 | B26: F1B118021 | C26: IDA AYU NYOMAN ISWARI WIKAPTI | D26: Ida Bagus Fery Citarsa, ST., MT. | E26: 19740226 199803 1 004 | G26: 12 | I26: =VLOOKUP(G26,[1]Sheet2!$A$6:$F$43,5,0) -> "197402261998031004" | K26: Dr. I Made Ginarsa, ST., MT. | L26: =COUNTIF($D$6:$D$70,K26) -> 2 | M26: =COUNTIF(ELEKTRO!$D$6:$D$105,'ELEKTRO SORE'!K26) -> 3 | N26: 2 | O26: 3 | Q26: =Q25+1 -> 21
A27: =A26+1 -> 22 | B27: F1B118022 | C27: IDA BAGUS ADITYA LAKSAMANA DHARMA | D27: Ida Bagus Fery Citarsa, ST., MT. | E27: 19740226 199803 1 004 | G27: =G26 -> 12 | I27: =VLOOKUP(G27,[1]Sheet2!$A$6:$F$43,5,0) -> "197402261998031004" | K27: Paniran, ST., MT. | L27: =COUNTIF($D$6:$D$70,K27) -> 2 | M27: =COUNTIF(ELEKTRO!$D$6:$D$105,'ELEKTRO SORE'!K27) -> 3 | N27: 2 | O27: 3 | Q27: =Q26+1 -> 22
A28: =A27+1 -> 23 | B28: F1B118023 | C28: JEFRI HAWARI | D28: Agung Budi Muljono, ST., MT. | E28: 19710211 199803 1 002 | G28: 13 | I28: =VLOOKUP(G28,[1]Sheet2!$A$6:$F$43,5,0) -> "197102111998031002" | K28: Sabar Nababan, ST., MT. | L28: =COUNTIF($D$6:$D$70,K28) -> 2 | M28: =COUNTIF(ELEKTRO!$D$6:$D$105,'ELEKTRO SORE'!K28) -> 3 | N28: 2 | O28: 3 | Q28: =Q27+1 -> 23
A29: =A28+1 -> 24 | B29: F1B118024 | C29: KASFUL GHOUSY | D29: Agung Budi Muljono, ST., MT. | E29: 19710211 199803 1 002 | G29: =G28 -> 13 | I29: =VLOOKUP(G29,[1]Sheet2!$A$6:$F$43,5,0) -> "197102111998031002" | K29: Sayidiman, ST., M.Eng | L29: =COUNTIF($D$6:$D$70,K29) -> 2 | M29: =COUNTIF(ELEKTRO!$D$6:$D$105,'ELEKTRO SORE'!K29) -> 3 | N29: 2 | O29: 3 | Q29: =Q28+1 -> 24
A30: =A29+1 -> 25 | B30: F1B118025 | C30: KRIS AGUS SALIM | D30: Abdul Natsir, ST., MT. | E30: 19720509 199803 1 002 | G30: 14 | I30: =VLOOKUP(G30,[1]Sheet2!$A$6:$F$43,5,0) -> "197205091998031002" | K30: Djulfikry Budiman, ST., MT. | L30: =COUNTIF($D$6:$D$70,K30) -> 2 | M30: =COUNTIF(ELEKTRO!$D$6:$D$105,'ELEKTRO SORE'!K30) -> 3 | N30: 2 | O30: 3 | Q30: =Q29+1 -> 25
A31: =A30+1 -> 26 | B31: F1B118026 | C31: LALU BIJE KALIH DENI RUPAWAN | D31: Abdul Natsir, ST., MT. | E31: 19720509 199803 1 002 | G31: =G30 -> 14 | I31: =VLOOKUP(G31,[1]Sheet2!$A$6:$F$43,5,0) -> "197205091998031002" | K31: Muhamad Irwan. ST., MT. | L31: =COUNTIF($D$6:$D$70,K31) -> 2 | M31: =COUNTIF(ELEKTRO!$D$6:$D$105,'ELEKTRO SORE'!K31) -> 3 | N31: 2 | O31: 3 | Q31: =Q30+1 -> 26
A32: =A31+1 -> 27 | B32: F1B118027 | C32: M. ALFIN JUFASHA | D32: Abdullah Zainuddin, ST., MT. | E32: 19721026 199803 1 002 | G32: 15 | I32: =VLOOKUP(G32,[1]Sheet2!$A$6:$F$43,5,0) -> "197210261998031002" | K32: Suthami Ariessaputra, ST., M.Eng. | L32: =COUNTIF($D$6:$D$70,K32) -> 2 | M32: =COUNTIF(ELEKTRO!$D$6:$D$105,'ELEKTRO SORE'!K32) -> 3 | N32: 2 | O32: 3 | Q32: =Q31+1 -> 27
A33: =A32+1 -> 28 | B33: F1B118028 | C33: MICHAEL STEFLEN LEPONG | D33: Abdullah Zainuddin, ST., MT. | E33: 19721026 199803 1 002 | G33: =G32 -> 15 | I33: =VLOOKUP(G33,[1]Sheet2!$A$6:$F$43,5,0) -> "197210261998031002" | K33: Budi Darmawan, ST., M.Eng. | L33: =COUNTIF($D$6:$D$70,K33) -> 2 | M33: =COUNTIF(ELEKTRO!$D$6:$D$105,'ELEKTRO SORE'!K33) -> 3 | N33: 2 | O33: 3 | Q33: =Q32+1 -> 28
A34: =A33+1 -> 29 | B34: F1B118029 | C34: MOHAMAD ABDUL AZIS | D34: Muhamad Syamsu Iqbal, ST., MT., Ph.D. | E34: 19720222 199903 1 002 | G34: 18 | I34: =VLOOKUP(G34,[1]Sheet2!$A$6:$F$43,5,0) -> "197202221999031002" | K34: Dr. Rismon H. Sianipar, ST., M.Eng. | L34: =COUNTIF($D$6:$D$70,K34) -> 0 | M34: =COUNTIF(ELEKTRO!$D$6:$D$105,'ELEKTRO SORE'!K34) -> 3 | N34: 0 | O34: 3 | Q34: =Q33+1 -> 29
A35: =A34+1 -> 30 | B35: F1B118030 | C35: MUHAMAD RENALDI ALFARISHI | D35: Muhamad Syamsu Iqbal, ST., MT., Ph.D. | E35: 19720222 199903 1 002 | G35: 18 | I35: =VLOOKUP(G35,[1]Sheet2!$A$6:$F$43,5,0) -> "197202221999031002" | K35: L. A. Syamsul Irfan Akbar, ST., M.Eng. | L35: =COUNTIF($D$6:$D$70,K35) -> 0 | M35: =COUNTIF(ELEKTRO!$D$6:$D$105,'ELEKTRO SORE'!K35) -> 3 | N35: 0 | O35: 3 | Q35: =Q34+1 -> 30
A36: =A35+1 -> 31 | B36: F1B118031 | C36: MUHAMAD RIZKI PERDAMAIAN | D36: Made Sutha Yadnya, ST., MT. | E36: 19720117 199903 1 001 | G36: 19 | I36: =VLOOKUP(G36,[1]Sheet2!$A$6:$F$43,5,0) -> "197201171999031001" | K36: Giri Wahyu Wiriasto, ST., MT. | L36: =COUNTIF($D$6:$D$70,K36) -> 0 | M36: =COUNTIF(ELEKTRO!$D$6:$D$105,'ELEKTRO SORE'!K36) -> 3 | N36: 0 | O36: 3 | Q36: =Q35+1 -> 31
A37: =A36+1 -> 32 | B37: F1B118032 | C37: MUHAMMAD AHMAL RIZKI | D37: Made Sutha Yadnya, ST., MT. | E37: 19720117 199903 1 001 | G37: 19 | I37: =VLOOKUP(G37,[1]Sheet2!$A$6:$F$43,5,0) -> "197201171999031001" | K37: I Made Budi Suksmadana, ST., MT. | L37: =COUNTIF($D$6:$D$70,K37) -> 2 | M37: =COUNTIF(ELEKTRO!$D$6:$D$105,'ELEKTRO SORE'!K37) -> 2 | N37: 3 | O37: 2 | Q37: =Q36+1 -> 32
A38: =A37+1 -> 33 | B38: F1B118033 | C38: MUHAMMAD AHMILURRIZQI DAHLAN | D38: Bulkis Kanata, ST., MT. | E38: 19730723 199903 2 001 | G38: 20 | I38: =VLOOKUP(G38,[1]Sheet2!$A$6:$F$43,5,0) -> "197307231999032001" | K38: A. Sjamsjiar Rachman, ST., MT. | L38: =COUNTIF($D$6:$D$70,K38) -> 0 | M38: =COUNTIF(ELEKTRO!$D$6:$D$105,'ELEKTRO SORE'!K38) -> 2 | N38: 0 | O38: 2 | Q38: =Q37+1 -> 33
A39: =A38+1 -> 34 | B39: F1B118034 | C39: MUHAMMAD FATTAAKHUN NIZAR | D39: Bulkis Kanata, ST., MT. | E39: 19730723 199903 2 001 | G39: =G38 -> 20 | I39: =VLOOKUP(G39,[1]Sheet2!$A$6:$F$43,5,0) -> "197307231999032001" | K39: Muhammad Firad, ST. | L39: =COUNTIF($D$6:$D$70,K39) -> 0 | M39: =COUNTIF(ELEKTRO!$D$6:$D$105,'ELEKTRO SORE'!K39) -> 0 | N39: 0 | O39: 0
A40: =A39+1 -> 35 | B40: F1B118035 | C40: MUHAMMAD FEBRIAN ULMAYADI PRATAMA | D40: Dr. rer.nat. Teti Zubaidah, ST., MT. | E40: 19741119 199903 2 001 | G40: 21 | I40: =VLOOKUP(G40,[1]Sheet2!$A$6:$F$43,5,0) -> "197411191999032001" | K40: Rosmaliati, ST., MT. | L40: =COUNTIF($D$6:$D$70,K40) -> 0 | M40: =COUNTIF(ELEKTRO!$D$6:$D$105,'ELEKTRO SORE'!K40) -> 0 | N40: 0 | O40: 0
A41: =A40+1 -> 36 | B41: F1B118036 | C41: MUHAMMAD NAZARUL MADANI | D41: Dr. rer.nat. Teti Zubaidah, ST., MT. | E41: 19741119 199903 2 001 | G41: =G40 -> 21 | I41: =VLOOKUP(G41,[1]Sheet2!$A$6:$F$43,5,0) -> "197411191999032001" | K41: I Ketut Perdana Putra, ST., MT. | L41: =COUNTIF($D$6:$D$70,K41) -> 0 | M41: =COUNTIF(ELEKTRO!$D$6:$D$105,'ELEKTRO SORE'!K41) -> 0 | N41: 0 | O41: 0
...
