Workbook

Sheet Worksheet
A1: NIM | B1: Nama Mahasiswa | C1: Kode MK | D1: Mata Kuliah | E1: Semester | F1: Kelas | G1: Nilai Huruf | H1: Nilai Indeks | I1: Nilai Angka | J1: Kode Prodi
A2: F1B113013 | B2: I NENGAH AGUS YOGI A | C2: ES1215 | D2: ALGORITMA DAN PEMROGRAMAN | E2: 20171 | F2: S | G2: B | H2: 3 | I2: 0 | J2: 20201 | K2: =COUNTIF('rEKAP kls MK'!$A$2:$A$35,Worksheet!C2) -> 1 | L2: =IF(A1<>A2,A2,"") -> F1B113013 | M2: =IF(B1<>B2,B2,"") -> I NENGAH AGUS YOGI A | O2: =IF(D1<>D2,D2,"") -> ALGORITMA DAN PEMROGRAMAN | P2: =IF(F1<>F2,F2,"") -> S
A3: F1B113015 | B3: IMAM RAHMATULLAH S | C3: ES1215 | D3: ALGORITMA DAN PEMROGRAMAN | E3: 20171 | F3: S | G3: C+ | H3: 2.5 | I3: 0 | J3: 20201 | K3: =COUNTIF('rEKAP kls MK'!$A$2:$A$35,Worksheet!C3) -> 1 | L3: =IF(A2<>A3,A3,"") -> F1B113015 | M3: =IF(B2<>B3,B3,"") -> IMAM RAHMATULLAH S | O3: =IF(D2<>D3,D3,"") | P3: =IF(F2<>F3,F3,"")
A4: F1B113016 | B4: JUZI SYUKRAN | C4: ES1215 | D4: ALGORITMA DAN PEMROGRAMAN | E4: 20171 | F4: S | G4: B | H4: 3 | I4: 0 | J4: 20201 | K4: =COUNTIF('rEKAP kls MK'!$A$2:$A$35,Worksheet!C4) -> 1 | L4: =IF(A3<>A4,A4,"") -> F1B113016 | M4: =IF(B3<>B4,B4,"") -> JUZI SYUKRAN | O4: =IF(D3<>D4,D4,"") | P4: =IF(F3<>F4,F4,"")
A5: F1B113021 | B5: LALU MUHAMMAD IBNU N | C5: ES1215 | D5: ALGORITMA DAN PEMROGRAMAN | E5: 20171 | F5: S | G5: A | H5: 4 | I5: 0 | J5: 20201 | K5: =COUNTIF('rEKAP kls MK'!$A$2:$A$35,Worksheet!C5) -> 1 | L5: =IF(A4<>A5,A5,"") -> F1B113021 | M5: =IF(B4<>B5,B5,"") -> LALU MUHAMMAD IBNU N | O5: =IF(D4<>D5,D5,"") | P5: =IF(F4<>F5,F5,"")
A6: F1B113022 | B6: LAZARUS CHRISTIAN P | C6: ES1215 | D6: ALGORITMA DAN PEMROGRAMAN | E6: 20171 | F6: S | G6: B | H6: 3 | I6: 0 | J6: 20201 | K6: =COUNTIF('rEKAP kls MK'!$A$2:$A$35,Worksheet!C6) -> 1 | L6: =IF(A5<>A6,A6,"") -> F1B113022 | M6: =IF(B5<>B6,B6,"") -> LAZARUS CHRISTIAN P | O6: =IF(D5<>D6,D6,"") | P6: =IF(F5<>F6,F6,"")
A7: F1B113026 | B7: MUHAMAD ARDI RAHMAN | C7: ES1215 | D7: ALGORITMA DAN PEMROGRAMAN | E7: 20171 | F7: S | G7: A | H7: 4 | I7: 0 | J7: 20201 | K7: =COUNTIF('rEKAP kls MK'!$A$2:$A$35,Worksheet!C7) -> 1 | L7: =IF(A6<>A7,A7,"") -> F1B113026 | M7: =IF(B6<>B7,B7,"") -> MUHAMAD ARDI RAHMAN | O7: =IF(D6<>D7,D7,"") | P7: =IF(F6<>F7,F7,"")
A8: F1B113029 | B8: RANGGA FAJAR MAULANA | C8: ES1215 | D8: ALGORITMA DAN PEMROGRAMAN | E8: 20171 | F8: S | G8: B+ | H8: 3.5 | I8: 0 | J8: 20201 | K8: =COUNTIF('rEKAP kls MK'!$A$2:$A$35,Worksheet!C8) -> 1 | L8: =IF(A7<>A8,A8,"") -> F1B113029 | M8: =IF(B7<>B8,B8,"") -> RANGGA FAJAR MAULANA | O8: =IF(D7<>D8,D8,"") | P8: =IF(F7<>F8,F8,"")
A9: F1B113030 | B9: RIZAL ADI SAPUTRA | C9: ES1215 | D9: ALGORITMA DAN PEMROGRAMAN | E9: 20171 | F9: S | G9: A | H9: 4 | I9: 0 | J9: 20201 | K9: =COUNTIF('rEKAP kls MK'!$A$2:$A$35,Worksheet!C9) -> 1 | L9: =IF(A8<>A9,A9,"") -> F1B113030 | M9: =IF(B8<>B9,B9,"") -> RIZAL ADI SAPUTRA | O9: =IF(D8<>D9,D9,"") | P9: =IF(F8<>F9,F9,"")
A10: F1B113032 | B10: SAMSUL AZWARI | C10: ES1215 | D10: ALGORITMA DAN PEMROGRAMAN | E10: 20171 | F10: S | G10: B+ | H10: 3.5 | I10: 0 | J10: 20201 | K10: =COUNTIF('rEKAP kls MK'!$A$2:$A$35,Worksheet!C10) -> 1 | L10: =IF(A9<>A10,A10,"") -> F1B113032 | M10: =IF(B9<>B10,B10,"") -> SAMSUL AZWARI | O10: =IF(D9<>D10,D10,"") | P10: =IF(F9<>F10,F10,"")
A11: F1B113033 | B11: SERLY MARLINA | C11: ES1215 | D11: ALGORITMA DAN PEMROGRAMAN | E11: 20171 | F11: S | G11: A | H11: 4 | I11: 0 | J11: 20201 | K11: =COUNTIF('rEKAP kls MK'!$A$2:$A$35,Worksheet!C11) -> 1 | L11: =IF(A10<>A11,A11,"") -> F1B113033 | M11: =IF(B10<>B11,B11,"") -> SERLY MARLINA | O11: =IF(D10<>D11,D11,"") | P11: =IF(F10<>F11,F11,"")
A12: F1B113034 | B12: SHIR AJIE ASMORO | C12: ES1215 | D12: ALGORITMA DAN PEMROGRAMAN | E12: 20171 | F12: S | G12: B | H12: 3 | I12: 0 | J12: 20201 | K12: =COUNTIF('rEKAP kls MK'!$A$2:$A$35,Worksheet!C12) -> 1 | L12: =IF(A11<>A12,A12,"") -> F1B113034 | M12: =IF(B11<>B12,B12,"") -> SHIR AJIE ASMORO | O12: =IF(D11<>D12,D12,"") | P12: =IF(F11<>F12,F12,"")
A13: F1B114001 | B13: ADI PURNA | C13: ES1215 | D13: ALGORITMA DAN PEMROGRAMAN | E13: 20171 | F13: S | G13: B | H13: 3 | I13: 0 | J13: 20201 | K13: =COUNTIF('rEKAP kls MK'!$A$2:$A$35,Worksheet!C13) -> 1 | L13: =IF(A12<>A13,A13,"") -> F1B114001 | M13: =IF(B12<>B13,B13,"") -> ADI PURNA | O13: =IF(D12<>D13,D13,"") | P13: =IF(F12<>F13,F13,"")
... A27: F1B116016 | B27: LALU MOHAMAD FAESAL RAHMAN | C27: ES1215 | D27: ALGORITMA DAN PEMROGRAMAN | E27: 20171 | F27: S | G27: D+ | H27: 1.5 | I27: 0 | J27: 20201 | K27: =COUNTIF('rEKAP kls MK'!$A$2:$A$35,Worksheet!C27) -> 1 | L27: =IF(A26<>A27,A27,"") -> F1B116016 | M27: =IF(B26<>B27,B27,"") -> LALU MOHAMAD FAESAL RAHMAN | O27: =IF(D26<>D27,D27,"") | P27: =IF(F26<>F27,F27,"")
A28: F1B116017 | B28: MAULANA ADI PRASETIO | C28: ES1215 | D28: ALGORITMA DAN PEMROGRAMAN | E28: 20171 | F28: S | G28: C | H28: 2 | I28: 0 | J28: 20201 | K28: =COUNTIF('rEKAP kls MK'!$A$2:$A$35,Worksheet!C28) -> 1
A29: F1B116020 | B29: Muhammad Zarrin Al Mansyury | C29: ES1215 | D29: ALGORITMA DAN PEMROGRAMAN | E29: 20171 | F29: S | G29: C+ | H29: 2.5 | I29: 0 | J29: 20201 | K29: =COUNTIF('rEKAP kls MK'!$A$2:$A$35,Worksheet!C29) -> 1 | L29: =IF(A28<>A29,A29,"") -> F1B116020 | M29: =IF(B28<>B29,B29,"") -> Muhammad Zarrin Al Mansyury | O29: =IF(D28<>D29,D29,"") | P29: =IF(F28<>F29,F29,"")
A30: F1B116021 | B30: NELIN AYU NIRWANA | C30: ES1215 | D30: ALGORITMA DAN PEMROGRAMAN | E30: 20171 | F30: S | G30: D | H30: 1 | I30: 0 | J30: 20201 | K30: =COUNTIF('rEKAP kls MK'!$A$2:$A$35,Worksheet!C30) -> 1 | L30: =IF(A29<>A30,A30,"") -> F1B116021 | M30: =IF(B29<>B30,B30,"") -> NELIN AYU NIRWANA | O30: =IF(D29<>D30,D30,"") | P30: =IF(F29<>F30,F30,"")
A31: F1B116022 | B31: NOVA HENDRI KURNIAWAN | C31: ES1215 | D31: ALGORITMA DAN PEMROGRAMAN | E31: 20171 | F31: S | G31: A | H31: 4 | I31: 0 | J31: 20201 | K31: =COUNTIF('rEKAP kls MK'!$A$2:$A$35,Worksheet!C31) -> 1 | L31: =IF(A30<>A31,A31,"") -> F1B116022 | M31: =IF(B30<>B31,B31,"") -> NOVA HENDRI KURNIAWAN | O31: =IF(D30<>D31,D31,"") | P31: =IF(F30<>F31,F31,"")
A32: F1B116024 | B32: RENA RAMDINAWATI | C32: ES1215 | D32: ALGORITMA DAN PEMROGRAMAN | E32: 20171 | F32: S | G32: C | H32: 2 | I32: 0 | J32: 20201 | K32: =COUNTIF('rEKAP kls MK'!$A$2:$A$35,Worksheet!C32) -> 1 | L32: =IF(A31<>A32,A32,"") -> F1B116024 | M32: =IF(B31<>B32,B32,"") -> RENA RAMDINAWATI | O32: =IF(D31<>D32,D32,"") | P32: =IF(F31<>F32,F32,"")
A33: F1B116025 | B33: RISMAN ALFIAN LUTHFI | C33: ES1215 | D33: ALGORITMA DAN PEMROGRAMAN | E33: 20171 | F33: S | G33: B | H33: 3 | I33: 0 | J33: 20201 | K33: =COUNTIF('rEKAP kls MK'!$A$2:$A$35,Worksheet!C33) -> 1 | L33: =IF(A32<>A33,A33,"") -> F1B116025 | M33: =IF(B32<>B33,B33,"") -> RISMAN ALFIAN LUTHFI | O33: =IF(D32<>D33,D33,"") | P33: =IF(F32<>F33,F33,"")
A34: F1B116027 | B34: ROYHAN ADEKA SAPUTRA | C34: ES1215 | D34: ALGORITMA DAN PEMROGRAMAN | E34: 20171 | F34: S | G34: C | H34: 2 | I34: 0 | J34: 20201 | K34: =COUNTIF('rEKAP kls MK'!$A$2:$A$35,Worksheet!C34) -> 1 | L34: =IF(A33<>A34,A34,"") -> F1B116027 | M34: =IF(B33<>B34,B34,"") -> ROYHAN ADEKA SAPUTRA | O34: =IF(D33<>D34,D34,"") | P34: =IF(F33<>F34,F34,"")
A35: F1B116029 | B35: TAUFIK ZUBAIDILLAH | C35: ES1215 | D35: ALGORITMA DAN PEMROGRAMAN | E35: 20171 | F35: S | G35: C+ | H35: 2.5 | I35: 0 | J35: 20201 | K35: =COUNTIF('rEKAP kls MK'!$A$2:$A$35,Worksheet!C35) -> 1 | L35: =IF(A34<>A35,A35,"") -> F1B116029 | M35: =IF(B34<>B35,B35,"") -> TAUFIK ZUBAIDILLAH | O35: =IF(D34<>D35,D35,"") | P35: =IF(F34<>F35,F35,"")
A36: F1B116030 | B36: Yanuardi | C36: ES1215 | D36: ALGORITMA DAN PEMROGRAMAN | E36: 20171 | F36: S | G36: C | H36: 2 | I36: 0 | J36: 20201 | K36: =COUNTIF('rEKAP kls MK'!$A$2:$A$35,Worksheet!C36) -> 1 | L36: =IF(A35<>A36,A36,"") -> F1B116030 | M36: =IF(B35<>B36,B36,"") -> Yanuardi | O36: =IF(D35<>D36,D36,"") | P36: =IF(F35<>F36,F36,"")
A37: F1B116032 | B37: Yuma | C37: ES1215 | D37: ALGORITMA DAN PEMROGRAMAN | E37: 20171 | F37: S | G37: B | H37: 3 | I37: 0 | J37: 20201 | K37: =COUNTIF('rEKAP kls MK'!$A$2:$A$35,Worksheet!C37) -> 1 | L37: =IF(A36<>A37,A37,"") -> F1B116032 | M37: =IF(B36<>B37,B37,"") -> Yuma | O37: =IF(D36<>D37,D37,"") | P37: =IF(F36<>F37,F37,"")
A38: F1B116033 | B38: Yusril Bagas Sevyanto | C38: ES1215 | D38: ALGORITMA DAN PEMROGRAMAN | E38: 20171 | F38: S | G38: B | H38: 3 | I38: 0 | J38: 20201 | K38: =COUNTIF('rEKAP kls MK'!$A$2:$A$35,Worksheet!C38) -> 1 | L38: =IF(A37<>A38,A38,"") -> F1B116033 | M38: =IF(B37<>B38,B38,"") -> Yusril Bagas Sevyanto | O38: =IF(D37<>D38,D38,"") | P38: =IF(F37<>F38,F38,"")
A39: F1B116034 | B39: YUSRON ALIF SETIAWAN | C39: ES1215 | D39: ALGORITMA DAN PEMROGRAMAN | E39: 20171 | F39: S | G39: C | H39: 2 | I39: 0 | J39: 20201 | K39: =COUNTIF('rEKAP kls MK'!$A$2:$A$35,Worksheet!C39) -> 1 | L39: =IF(A38<>A39,A39,"") -> F1B116034 | M39: =IF(B38<>B39,B39,"") -> YUSRON ALIF SETIAWAN | O39: =IF(D38<>D39,D39,"") | P39: =IF(F38<>F39,F39,"")
A40: F1B115002 | B40: AGUS SUPRIADI | C40: EA3101 | D40: ANALISA SISTEM TENAGA I | E40: 20171 | F40: S | G40: C | H40: 2 | I40: 0 | J40: 20201 | K40: =COUNTIF('rEKAP kls MK'!$A$2:$A$35,Worksheet!C40) -> 1 | L40: =IF(A39<>A40,A40,"") -> F1B115002 | M40: =IF(B39<>B40,B40,"") -> AGUS SUPRIADI | O40: =IF(D39<>D40,D40,"") -> ANALISA SISTEM TENAGA I | P40: =IF(F39<>F40,F40,"")
... A89: F1B117037 | B89: TEJAMAN MULKI | C89: TPBU04203 | D89: BAHASA INDONESIA | E89: 20171 | F89: TPB | G89: B+ | H89: 3.5 | I89: 0 | J89: 20201 | K89: =COUNTIF('rEKAP kls MK'!$A$2:$A$35,Worksheet!C89) -> 0 | L89: =IF(A88<>A89,A89,"") -> F1B117037 | M89: =IF(B88<>B89,B89,"") -> TEJAMAN MULKI | O89: =IF(D88<>D89,D89,"") | P89: =IF(F88<>F89,F89,"")
A90: F1B117038 | B90: VENI ASTUTI | C90: TPBU04203 | D90: BAHASA INDONESIA | E90: 20171 | F90: TPB | G90: B | H90: 3 | I90: 0 | J90: 20201 | K90: =COUNTIF('rEKAP kls MK'!$A$2:$A$35,Worksheet!C90) -> 0
A91: F1B117039 | B91: WAHYU SIOPANO | C91: TPBU04203 | D91: BAHASA INDONESIA | E91: 20171 | F91: TPB | G91: B | H91: 3 | I91: 0 | J91: 20201 | K91: =COUNTIF('rEKAP kls MK'!$A$2:$A$35,Worksheet!C91) -> 0 | L91: =IF(A90<>A91,A91,"") -> F1B117039 | M91: =IF(B90<>B91,B91,"") -> WAHYU SIOPANO | O91: =IF(D90<>D91,D91,"") | P91: =IF(F90<>F91,F91,"")
A92: F1B117040 | B92: WILLY HISBULLOH FAUZY FIRDAUS | C92: TPBU04203 | D92: BAHASA INDONESIA | E92: 20171 | F92: TPB | G92: B+ | H92: 3.5 | I92: 0 | J92: 20201 | K92: =COUNTIF('rEKAP kls MK'!$A$2:$A$35,Worksheet!C92) -> 0 | L92: =IF(A91<>A92,A92,"") -> F1B117040 | M92: =IF(B91<>B92,B92,"") -> WILLY HISBULLOH FAUZY FIRDAUS | O92: =IF(D91<>D92,D92,"") | P92: =IF(F91<>F92,F92,"")
A93: F1B117041 | B93: WILLY PRADIYANTO | C93: TPBU04203 | D93: BAHASA INDONESIA | E93: 20171 | F93: TPB | G93: B+ | H93: 3.5 | I93: 0 | J93: 20201 | K93: =COUNTIF('rEKAP kls MK'!$A$2:$A$35,Worksheet!C93) -> 0 | L93: =IF(A92<>A93,A93,"") -> F1B117041 | M93: =IF(B92<>B93,B93,"") -> WILLY PRADIYANTO | O93: =IF(D92<>D93,D93,"") | P93: =IF(F92<>F93,F93,"")
A94: F1B111041 | B94: M. Ahsanul Khaliq | C94: TPBU05201 | D94: BAHASA INGGRIS I | E94: 20171 | F94: TPB | G94: B+ | H94: 3.5 | I94: 0 | J94: 20201 | K94: =COUNTIF('rEKAP kls MK'!$A$2:$A$35,Worksheet!C94) -> 0 | L94: =IF(A93<>A94,A94,"") -> F1B111041 | M94: =IF(B93<>B94,B94,"") -> M. Ahsanul Khaliq | O94: =IF(D93<>D94,D94,"") -> BAHASA INGGRIS I | P94: =IF(F93<>F94,F94,"")
A95: F1B111047 | B95: M. Sofyan Hakim | C95: TPBU05201 | D95: BAHASA INGGRIS I | E95: 20171 | F95: TPB | G95: B+ | H95: 3.5 | I95: 0 | J95: 20201 | K95: =COUNTIF('rEKAP kls MK'!$A$2:$A$35,Worksheet!C95) -> 0 | L95: =IF(A94<>A95,A95,"") -> F1B111047 | M95: =IF(B94<>B95,B95,"") -> M. Sofyan Hakim | O95: =IF(D94<>D95,D95,"") | P95: =IF(F94<>F95,F95,"")
A96: F1B111075 | B96: Sahbudin | C96: TPBU05201 | D96: BAHASA INGGRIS I | E96: 20171 | F96: TPB | G96: K | H96: 0 | I96: 0 | J96: 20201 | K96: =COUNTIF('rEKAP kls MK'!$A$2:$A$35,Worksheet!C96) -> 0 | L96: =IF(A95<>A96,A96,"") -> F1B111075 | M96: =IF(B95<>B96,B96,"") -> Sahbudin | O96: =IF(D95<>D96,D96,"") | P96: =IF(F95<>F96,F96,"")
A97: F1B112003 | B97: Aditya Kadarusman | C97: TPBU05201 | D97: BAHASA INGGRIS I | E97: 20171 | F97: TPB | G97: K | H97: 0 | I97: 0 | J97: 20201 | K97: =COUNTIF('rEKAP kls MK'!$A$2:$A$35,Worksheet!C97) -> 0 | L97: =IF(A96<>A97,A97,"") -> F1B112003 | M97: =IF(B96<>B97,B97,"") -> Aditya Kadarusman | O97: =IF(D96<>D97,D97,"") | P97: =IF(F96<>F97,F97,"")
A98: F1B113031 | B98: SADIQ RAMADHOAN | C98: TPBU05201 | D98: BAHASA INGGRIS I | E98: 20171 | F98: TPB | G98: K | H98: 0 | I98: 0 | J98: 20201 | K98: =COUNTIF('rEKAP kls MK'!$A$2:$A$35,Worksheet!C98) -> 0 | L98: =IF(A97<>A98,A98,"") -> F1B113031 | M98: =IF(B97<>B98,B98,"") -> SADIQ RAMADHOAN | O98: =IF(D97<>D98,D98,"") | P98: =IF(F97<>F98,F98,"")
A99: F1B114020 | B99: IMRAN | C99: TPBU05201 | D99: BAHASA INGGRIS I | E99: 20171 | F99: TPB | G99: B | H99: 3 | I99: 0 | J99: 20201 | K99: =COUNTIF('rEKAP kls MK'!$A$2:$A$35,Worksheet!C99) -> 0 | L99: =IF(A98<>A99,A99,"") -> F1B114020 | M99: =IF(B98<>B99,B99,"") -> IMRAN | O99: =IF(D98<>D99,D99,"") | P99: =IF(F98<>F99,F99,"")
A100: F1B115030 | B100: MUHAMMAD FIQRIL | C100: TPBU05201 | D100: BAHASA INGGRIS I | E100: 20171 | F100: TPB | G100: K | H100: 0 | I100: 0 | J100: 20201 | K100: =COUNTIF('rEKAP kls MK'!$A$2:$A$35,Worksheet!C100) -> 0 | L100: =IF(A99<>A100,A100,"") -> F1B115030 | M100: =IF(B99<>B100,B100,"") -> MUHAMMAD FIQRIL | O100: =IF(D99<>D100,D100,"") | P100: =IF(F99<>F100,F100,"")
A101: F1B117001 | B101: ABI LASKAR | C101: TPBU05201 | D101: BAHASA INGGRIS I | E101: 20171 | F101: TPB | G101: A | H101: 4 | I101: 0 | J101: 20201 | K101: =COUNTIF('rEKAP kls MK'!$A$2:$A$35,Worksheet!C101) -> 0 | L101: =IF(A100<>A101,A101,"") -> F1B117001 | M101: =IF(B100<>B101,B101,"") -> ABI LASKAR | O101: =IF(D100<>D101,D101,"") | P101: =IF(F100<>F101,F101,"")
...

Sheet rEKAP MHS
A1: NIM | B1: Nama | C1: Semester | D1: SKS | E1: IP Semester | F1: SKS Kumulatif | G1: IP Kumulatif | H1: Status | I1: Kode Prodi | K1: tambah sks | M1: SKS * IPS | N1: SKS * IPK | P1: SKS | Q1: IP Semester | R1: SKS Kumulatif | S1: IP Kumulatif | T1: Status | U1: Kode Prodi
A2: F1B110010 | B2: GHAZI AKBAR | C2: 20171 | D2: =VLOOKUP(A2,[1]Worksheet!$A$2:$I$423,4,0) -> 0 | E2: =VLOOKUP(A2,[1]Worksheet!$A$2:$I$423,5,0) -> 0 | F2: =VLOOKUP(A2,[1]Worksheet!$A$2:$I$423,6,0) -> 197 | G2: =VLOOKUP(A2,[1]Worksheet!$A$2:$I$423,7,0) -> 2.02 | K2: 6 | M2: =D2*E2 -> 0 | N2: =F2*G2 -> 397.94 | P2: =K2+D2 -> 6 | Q2: =M2/P2 -> 0 | R2: =F2+K2 -> 203 | S2: =N2/R2 -> 1.9602956
A3: F1B110016 | B3: HAMDANI | C3: 20171 | D3: =VLOOKUP(A3,[1]Worksheet!$A$2:$I$423,4,0) -> 4 | E3: =VLOOKUP(A3,[1]Worksheet!$A$2:$I$423,5,0) -> 3.5 | F3: =VLOOKUP(A3,[1]Worksheet!$A$2:$I$423,6,0) -> 189 | G3: =VLOOKUP(A3,[1]Worksheet!$A$2:$I$423,7,0) -> 2.02 | M3: =D3*E3 -> 14 | N3: =F3*G3 -> 381.78 | P3: =K3+D3 -> 4 | Q3: =M3/P3 -> 3.5 | R3: =F3+K3 -> 189 | S3: =N3/R3 -> 2.02
A4: F1B110018 | B4: SAMSUL HADI | C4: 20171 | D4: =VLOOKUP(A4,[1]Worksheet!$A$2:$I$423,4,0) -> 0 | E4: =VLOOKUP(A4,[1]Worksheet!$A$2:$I$423,5,0) -> 0 | F4: =VLOOKUP(A4,[1]Worksheet!$A$2:$I$423,6,0) -> 207 | G4: =VLOOKUP(A4,[1]Worksheet!$A$2:$I$423,7,0) -> 1.86 | K4: 4 | M4: =D4*E4 -> 0 | N4: =F4*G4 -> 385.02 | P4: =K4+D4 -> 4 | Q4: =M4/P4 -> 0 | R4: =F4+K4 -> 211 | S4: =N4/R4 -> 1.8247393
A5: F1B110028 | B5: ERWIN PRATAMA HADI | C5: 20171 | D5: =VLOOKUP(A5,[1]Worksheet!$A$2:$I$423,4,0) -> 4 | E5: =VLOOKUP(A5,[1]Worksheet!$A$2:$I$423,5,0) -> 3.5 | F5: =VLOOKUP(A5,[1]Worksheet!$A$2:$I$423,6,0) -> 181 | G5: =VLOOKUP(A5,[1]Worksheet!$A$2:$I$423,7,0) -> 2.89 | M5: =D5*E5 -> 14 | N5: =F5*G5 -> 523.09 | P5: =K5+D5 -> 4 | Q5: =M5/P5 -> 3.5 | R5: =F5+K5 -> 181 | S5: =N5/R5 -> 2.89
A6: F1B110033 | B6: LALU MAYENDRA ISKANDAR | C6: 20171 | D6: =VLOOKUP(A6,[1]Worksheet!$A$2:$I$423,4,0) -> 4 | E6: =VLOOKUP(A6,[1]Worksheet!$A$2:$I$423,5,0) -> 3 | F6: =VLOOKUP(A6,[1]Worksheet!$A$2:$I$423,6,0) -> 208 | G6: =VLOOKUP(A6,[1]Worksheet!$A$2:$I$423,7,0) -> 2.3 | M6: =D6*E6 -> 12 | N6: =F6*G6 -> 478.4 | P6: =K6+D6 -> 4 | Q6: =M6/P6 -> 3 | R6: =F6+K6 -> 208 | S6: =N6/R6 -> 2.3
A7: F1B110034 | B7: RADIMAS DHAWNIEL P. | C7: 20171 | D7: =VLOOKUP(A7,[1]Worksheet!$A$2:$I$423,4,0) -> 4 | E7: =VLOOKUP(A7,[1]Worksheet!$A$2:$I$423,5,0) -> 4 | F7: =VLOOKUP(A7,[1]Worksheet!$A$2:$I$423,6,0) -> 189 | G7: =VLOOKUP(A7,[1]Worksheet!$A$2:$I$423,7,0) -> 2.43 | M7: =D7*E7 -> 16 | N7: =F7*G7 -> 459.27 | P7: =K7+D7 -> 4 | Q7: =M7/P7 -> 4 | R7: =F7+K7 -> 189 | S7: =N7/R7 -> 2.43
A8: F1B110036 | B8: M AZMI NOPIANDI | C8: 20171 | D8: =VLOOKUP(A8,[1]Worksheet!$A$2:$I$423,4,0) -> 4 | E8: =VLOOKUP(A8,[1]Worksheet!$A$2:$I$423,5,0) -> 3.5 | F8: =VLOOKUP(A8,[1]Worksheet!$A$2:$I$423,6,0) -> 197 | G8: =VLOOKUP(A8,[1]Worksheet!$A$2:$I$423,7,0) -> 2.16 | M8: =D8*E8 -> 14 | N8: =F8*G8 -> 425.52 | P8: =K8+D8 -> 4 | Q8: =M8/P8 -> 3.5 | R8: =F8+K8 -> 197 | S8: =N8/R8 -> 2.16
A9: F1B110044 | B9: ASMIWATI | C9: 20171 | D9: =VLOOKUP(A9,[1]Worksheet!$A$2:$I$423,4,0) -> 4 | E9: =VLOOKUP(A9,[1]Worksheet!$A$2:$I$423,5,0) -> 3.5 | F9: =VLOOKUP(A9,[1]Worksheet!$A$2:$I$423,6,0) -> 194 | G9: =VLOOKUP(A9,[1]Worksheet!$A$2:$I$423,7,0) -> 2.13 | M9: =D9*E9 -> 14 | N9: =F9*G9 -> 413.22 | P9: =K9+D9 -> 4 | Q9: =M9/P9 -> 3.5 | R9: =F9+K9 -> 194 | S9: =N9/R9 -> 2.13
A10: F1B110053 | B10: SADDAM KADIR RANGGO | C10: 20171 | D10: =VLOOKUP(A10,[1]Worksheet!$A$2:$I$423,4,0) -> 4 | E10: =VLOOKUP(A10,[1]Worksheet!$A$2:$I$423,5,0) -> 2.5 | F10: =VLOOKUP(A10,[1]Worksheet!$A$2:$I$423,6,0) -> 216 | G10: =VLOOKUP(A10,[1]Worksheet!$A$2:$I$423,7,0) -> 1.95 | M10: =D10*E10 -> 10 | N10: =F10*G10 -> 421.2 | P10: =K10+D10 -> 4 | Q10: =M10/P10 -> 2.5 | R10: =F10+K10 -> 216 | S10: =N10/R10 -> 1.95
A11: F1B110056 | B11: GALANG SAPUTRA | C11: 20171 | D11: =VLOOKUP(A11,[1]Worksheet!$A$2:$I$423,4,0) -> 4 | E11: =VLOOKUP(A11,[1]Worksheet!$A$2:$I$423,5,0) -> 3 | F11: =VLOOKUP(A11,[1]Worksheet!$A$2:$I$423,6,0) -> 185 | G11: =VLOOKUP(A11,[1]Worksheet!$A$2:$I$423,7,0) -> 2.39 | M11: =D11*E11 -> 12 | N11: =F11*G11 -> 442.15 | P11: =K11+D11 -> 4 | Q11: =M11/P11 -> 3 | R11: =F11+K11 -> 185 | S11: =N11/R11 -> 2.39
A12: F1B110057 | B12: YULIA PRADEWI | C12: 20171 | D12: =VLOOKUP(A12,[1]Worksheet!$A$2:$I$423,4,0) -> 4 | E12: =VLOOKUP(A12,[1]Worksheet!$A$2:$I$423,5,0) -> 3.5 | F12: =VLOOKUP(A12,[1]Worksheet!$A$2:$I$423,6,0) -> 181 | G12: =VLOOKUP(A12,[1]Worksheet!$A$2:$I$423,7,0) -> 2.47 | M12: =D12*E12 -> 14 | N12: =F12*G12 -> 447.07 | P12: =K12+D12 -> 4 | Q12: =M12/P12 -> 3.5 | R12: =F12+K12 -> 181 | S12: =N12/R12 -> 2.47
A13: F1B110062 | B13: SINGGIH RAMADHONI | C13: 20171 | D13: =VLOOKUP(A13,[1]Worksheet!$A$2:$I$423,4,0) -> 4 | E13: =VLOOKUP(A13,[1]Worksheet!$A$2:$I$423,5,0) -> 4 | F13: =VLOOKUP(A13,[1]Worksheet!$A$2:$I$423,6,0) -> 198 | G13: =VLOOKUP(A13,[1]Worksheet!$A$2:$I$423,7,0) -> 2.5 | M13: =D13*E13 -> 16 | N13: =F13*G13 -> 495 | P13: =K13+D13 -> 4 | Q13: =M13/P13 -> 4 | R13: =F13+K13 -> 198 | S13: =N13/R13 -> 2.5
A14: F1B110063 | B14: DANANG M ARIEF S P | C14: 20171 | D14: =VLOOKUP(A14,[1]Worksheet!$A$2:$I$423,4,0) -> 4 | E14: =VLOOKUP(A14,[1]Worksheet!$A$2:$I$423,5,0) -> 3.5 | F14: =VLOOKUP(A14,[1]Worksheet!$A$2:$I$423,6,0) -> 209 | G14: =VLOOKUP(A14,[1]Worksheet!$A$2:$I$423,7,0) -> 2.22 | M14: =D14*E14 -> 14 | N14: =F14*G14 -> 463.98 | P14: =K14+D14 -> 4 | Q14: =M14/P14 -> 3.5 | R14: =F14+K14 -> 209 | S14: =N14/R14 -> 2.22
A15: F1B110068 | B15: SUPARLAN ARDYANSYAH | C15: 20171 | D15: =VLOOKUP(A15,[1]Worksheet!$A$2:$I$423,4,0) -> 0 | E15: =VLOOKUP(A15,[1]Worksheet!$A$2:$I$423,5,0) -> 0 | F15: =VLOOKUP(A15,[1]Worksheet!$A$2:$I$423,6,0) -> 187 | G15: =VLOOKUP(A15,[1]Worksheet!$A$2:$I$423,7,0) -> 2.33 | K15: 6 | M15: =D15*E15 -> 0 | N15: =F15*G15 -> 435.71 | P15: =K15+D15 -> 6 | Q15: =M15/P15 -> 0 | R15: =F15+K15 -> 193 | S15: =N15/R15 -> 2.2575648
A16: F1B110071 | B16: TRENDY NIAGAWAN | C16: 20171 | D16: =VLOOKUP(A16,[1]Worksheet!$A$2:$I$423,4,0) -> 4 | E16: =VLOOKUP(A16,[1]Worksheet!$A$2:$I$423,5,0) -> 4 | F16: =VLOOKUP(A16,[1]Worksheet!$A$2:$I$423,6,0) -> 202 | G16: =VLOOKUP(A16,[1]Worksheet!$A$2:$I$423,7,0) -> 1.93 | M16: =D16*E16 -> 16 | N16: =F16*G16 -> 389.86 | P16: =K16+D16 -> 4 | Q16: =M16/P16 -> 4 | R16: =F16+K16 -> 202 | S16: =N16/R16 -> 1.93
A17: F1B110073 | B17: MUHAMAD JOHAN K | C17: 20171 | D17: =VLOOKUP(A17,[1]Worksheet!$A$2:$I$423,4,0) -> 4 | E17: =VLOOKUP(A17,[1]Worksheet!$A$2:$I$423,5,0) -> 3.5 | F17: =VLOOKUP(A17,[1]Worksheet!$A$2:$I$423,6,0) -> 208 | G17: =VLOOKUP(A17,[1]Worksheet!$A$2:$I$423,7,0) -> 2.26 | M17: =D17*E17 -> 14 | N17: =F17*G17 -> 470.08 | P17: =K17+D17 -> 4 | Q17: =M17/P17 -> 3.5 | R17: =F17+K17 -> 208 | S17: =N17/R17 -> 2.26
A18: F1B110076 | B18: LALU ARDYPATI | C18: 20171 | D18: =VLOOKUP(A18,[1]Worksheet!$A$2:$I$423,4,0) -> 4 | E18: =VLOOKUP(A18,[1]Worksheet!$A$2:$I$423,5,0) -> 2.38 | F18: =VLOOKUP(A18,[1]Worksheet!$A$2:$I$423,6,0) -> 198 | G18: =VLOOKUP(A18,[1]Worksheet!$A$2:$I$423,7,0) -> 1.77 | K18: 4 | M18: =D18*E18 -> 9.52 | N18: =F18*G18 -> 350.46 | P18: =K18+D18 -> 8 | Q18: =M18/P18 -> 1.19 | R18: =F18+K18 -> 202 | S18: =N18/R18 -> 1.7349505
A19: F1B110077 | B19: KHAIRUL ANAM | C19: 20171 | D19: =VLOOKUP(A19,[1]Worksheet!$A$2:$I$423,4,0) -> 4 | E19: =VLOOKUP(A19,[1]Worksheet!$A$2:$I$423,5,0) -> 3.5 | F19: =VLOOKUP(A19,[1]Worksheet!$A$2:$I$423,6,0) -> 210 | G19: =VLOOKUP(A19,[1]Worksheet!$A$2:$I$423,7,0) -> 1.99 | M19: =D19*E19 -> 14 | N19: =F19*G19 -> 417.9 | P19: =K19+D19 -> 4 | Q19: =M19/P19 -> 3.5 | R19: =F19+K19 -> 210 | S19: =N19/R19 -> 1.99
A20: F1B110078 | B20: SUPRIADI | C20: 20171 | D20: =VLOOKUP(A20,[1]Worksheet!$A$2:$I$423,4,0) -> 4 | E20: =VLOOKUP(A20,[1]Worksheet!$A$2:$I$423,5,0) -> 3.5 | F20: =VLOOKUP(A20,[1]Worksheet!$A$2:$I$423,6,0) -> 199 | G20: =VLOOKUP(A20,[1]Worksheet!$A$2:$I$423,7,0) -> 2.32 | M20: =D20*E20 -> 14 | N20: =F20*G20 -> 461.68 | P20: =K20+D20 -> 4 | Q20: =M20/P20 -> 3.5 | R20: =F20+K20 -> 199 | S20: =N20/R20 -> 2.32
A21: F1B111002 | B21: Agus Budi Nurcahyono | C21: 20171 | D21: =VLOOKUP(A21,[1]Worksheet!$A$2:$I$423,4,0) -> 0 | E21: =VLOOKUP(A21,[1]Worksheet!$A$2:$I$423,5,0) -> 0 | F21: =VLOOKUP(A21,[1]Worksheet!$A$2:$I$423,6,0) -> 166 | G21: =VLOOKUP(A21,[1]Worksheet!$A$2:$I$423,7,0) -> 2.66 | K21: 4 | M21: =D21*E21 -> 0 | N21: =F21*G21 -> 441.56 | P21: =K21+D21 -> 4 | Q21: =M21/P21 -> 0 | R21: =F21+K21 -> 170 | S21: =N21/R21 -> 2.5974118
A22: F1B111004 | B22: Ahmadi | C22: 20171 | D22: =VLOOKUP(A22,[1]Worksheet!$A$2:$I$423,4,0) -> 11 | E22: =VLOOKUP(A22,[1]Worksheet!$A$2:$I$423,5,0) -> 2.18 | F22: =VLOOKUP(A22,[1]Worksheet!$A$2:$I$423,6,0) -> 182 | G22: =VLOOKUP(A22,[1]Worksheet!$A$2:$I$423,7,0) -> 2.17 | M22: =D22*E22 -> 23.98 | N22: =F22*G22 -> 394.94 | P22: =K22+D22 -> 11 | Q22: =M22/P22 -> 2.18 | R22: =F22+K22 -> 182 | S22: =N22/R22 -> 2.17
A23: F1B111006 | B23: Alfan Aditya | C23: 20171 | D23: =VLOOKUP(A23,[1]Worksheet!$A$2:$I$423,4,0) -> 0 | E23: =VLOOKUP(A23,[1]Worksheet!$A$2:$I$423,5,0) -> 0 | F23: =VLOOKUP(A23,[1]Worksheet!$A$2:$I$423,6,0) -> 196 | G23: =VLOOKUP(A23,[1]Worksheet!$A$2:$I$423,7,0) -> 2.42 | K23: 4 | M23: =D23*E23 -> 0 | N23: =F23*G23 -> 474.32 | P23: =K23+D23 -> 4 | Q23: =M23/P23 -> 0 | R23: =F23+K23 -> 200 | S23: =N23/R23 -> 2.3716
A24: F1B111007 | B24: Andika Nugraha | C24: 20171 | D24: =VLOOKUP(A24,[1]Worksheet!$A$2:$I$423,4,0) -> 0 | E24: =VLOOKUP(A24,[1]Worksheet!$A$2:$I$423,5,0) -> 0 | F24: =VLOOKUP(A24,[1]Worksheet!$A$2:$I$423,6,0) -> 177 | G24: =VLOOKUP(A24,[1]Worksheet!$A$2:$I$423,7,0) -> 2.3 | K24: 4 | M24: =D24*E24 -> 0 | N24: =F24*G24 -> 407.1 | P24: =K24+D24 -> 4 | Q24: =M24/P24 -> 0 | R24: =F24+K24 -> 181 | S24: =N24/R24 -> 2.2491713
A25: F1B111008 | B25: Arif Hidayatullah | C25: 20171 | D25: =VLOOKUP(A25,[1]Worksheet!$A$2:$I$423,4,0) -> 0 | E25: =VLOOKUP(A25,[1]Worksheet!$A$2:$I$423,5,0) -> 0 | F25: =VLOOKUP(A25,[1]Worksheet!$A$2:$I$423,6,0) -> 160 | G25: =VLOOKUP(A25,[1]Worksheet!$A$2:$I$423,7,0) -> 2.88 | K25: 4 | M25: =D25*E25 -> 0 | N25: =F25*G25 -> 460.8 | P25: =K25+D25 -> 4 | Q25: =M25/P25 -> 0 | R25: =F25+K25 -> 164 | S25: =N25/R25 -> 2.8097561
A26: F1B111012 | B26: Baiq Ifi Nawal Akifi | C26: 20171 | D26: =VLOOKUP(A26,[1]Worksheet!$A$2:$I$423,4,0) -> 4 | E26: =VLOOKUP(A26,[1]Worksheet!$A$2:$I$423,5,0) -> 4 | F26: =VLOOKUP(A26,[1]Worksheet!$A$2:$I$423,6,0) -> 171 | G26: =VLOOKUP(A26,[1]Worksheet!$A$2:$I$423,7,0) -> 2.51 | M26: =D26*E26 -> 16 | N26: =F26*G26 -> 429.21 | P26: =K26+D26 -> 4 | Q26: =M26/P26 -> 4 | R26: =F26+K26 -> 171 | S26: =N26/R26 -> 2.51
A27: F1B111015 | B27: Dwi Kurniawan P. | C27: 20171 | D27: =VLOOKUP(A27,[1]Worksheet!$A$2:$I$423,4,0) -> 4 | E27: =VLOOKUP(A27,[1]Worksheet!$A$2:$I$423,5,0) -> 4 | F27: =VLOOKUP(A27,[1]Worksheet!$A$2:$I$423,6,0) -> 174 | G27: =VLOOKUP(A27,[1]Worksheet!$A$2:$I$423,7,0) -> 2.49 | M27: =D27*E27 -> 16 | N27: =F27*G27 -> 433.26 | P27: =K27+D27 -> 4 | Q27: =M27/P27 -> 4 | R27: =F27+K27 -> 174 | S27: =N27/R27 -> 2.49
A28: F1B111019 | B28: Fathurrahman | C28: 20171 | D28: =VLOOKUP(A28,[1]Worksheet!$A$2:$I$423,4,0) -> 4 | E28: =VLOOKUP(A28,[1]Worksheet!$A$2:$I$423,5,0) -> 4 | F28: =VLOOKUP(A28,[1]Worksheet!$A$2:$I$423,6,0) -> 174 | G28: =VLOOKUP(A28,[1]Worksheet!$A$2:$I$423,7,0) -> 2.79 | M28: =D28*E28 -> 16 | N28: =F28*G28 -> 485.46 | P28: =K28+D28 -> 4 | Q28: =M28/P28 -> 4 | R28: =F28+K28 -> 174 | S28: =N28/R28 -> 2.79
A29: F1B111020 | B29: Ghalib Mansur Thalib | C29: 20171 | D29: =VLOOKUP(A29,[1]Worksheet!$A$2:$I$423,4,0) -> 7 | E29: =VLOOKUP(A29,[1]Worksheet!$A$2:$I$423,5,0) -> 0 | F29: =VLOOKUP(A29,[1]Worksheet!$A$2:$I$423,6,0) -> 159 | G29: =VLOOKUP(A29,[1]Worksheet!$A$2:$I$423,7,0) -> 1.6 | M29: =D29*E29 -> 0 | N29: =F29*G29 -> 254.4 | P29: =K29+D29 -> 7 | Q29: =M29/P29 -> 0 | R29: =F29+K29 -> 159 | S29: =N29/R29 -> 1.6
A30: F1B111021 | B30: Haerurrozi | C30: 20171 | D30: =VLOOKUP(A30,[1]Worksheet!$A$2:$I$423,4,0) -> 0 | E30: =VLOOKUP(A30,[1]Worksheet!$A$2:$I$423,5,0) -> 0 | F30: =VLOOKUP(A30,[1]Worksheet!$A$2:$I$423,6,0) -> 163 | G30: =VLOOKUP(A30,[1]Worksheet!$A$2:$I$423,7,0) -> 2.62 | K30: 4 | M30: =D30*E30 -> 0 | N30: =F30*G30 -> 427.06 | P30: =K30+D30 -> 4 | Q30: =M30/P30 -> 0 | R30: =F30+K30 -> 167 | S30: =N30/R30 -> 2.5572455
A31: F1B111024 | B31: Hulaipi | C31: 20171 | D31: =VLOOKUP(A31,[1]Worksheet!$A$2:$I$423,4,0) -> 4 | E31: =VLOOKUP(A31,[1]Worksheet!$A$2:$I$423,5,0) -> 3.5 | F31: =VLOOKUP(A31,[1]Worksheet!$A$2:$I$423,6,0) -> 160 | G31: =VLOOKUP(A31,[1]Worksheet!$A$2:$I$423,7,0) -> 2.94 | M31: =D31*E31 -> 14 | N31: =F31*G31 -> 470.4 | P31: =K31+D31 -> 4 | Q31: =M31/P31 -> 3.5 | R31: =F31+K31 -> 160 | S31: =N31/R31 -> 2.94
A32: F1B111025 | B32: Husnul Kahpi | C32: 20171 | D32: =VLOOKUP(A32,[1]Worksheet!$A$2:$I$423,4,0) -> 4 | E32: =VLOOKUP(A32,[1]Worksheet!$A$2:$I$423,5,0) -> 3.5 | F32: =VLOOKUP(A32,[1]Worksheet!$A$2:$I$423,6,0) -> 180 | G32: =VLOOKUP(A32,[1]Worksheet!$A$2:$I$423,7,0) -> 2.36 | M32: =D32*E32 -> 14 | N32: =F32*G32 -> 424.8 | P32: =K32+D32 -> 4 | Q32: =M32/P32 -> 3.5 | R32: =F32+K32 -> 180 | S32: =N32/R32 -> 2.36
A33: F1B111026 | B33: I Ketut Astana | C33: 20171 | D33: =VLOOKUP(A33,[1]Worksheet!$A$2:$I$423,4,0) -> 4 | E33: =VLOOKUP(A33,[1]Worksheet!$A$2:$I$423,5,0) -> 3.5 | F33: =VLOOKUP(A33,[1]Worksheet!$A$2:$I$423,6,0) -> 191 | G33: =VLOOKUP(A33,[1]Worksheet!$A$2:$I$423,7,0) -> 2.44 | M33: =D33*E33 -> 14 | N33: =F33*G33 -> 466.04 | P33: =K33+D33 -> 4 | Q33: =M33/P33 -> 3.5 | R33: =F33+K33 -> 191 | S33: =N33/R33 -> 2.44
A34: F1B111027 | B34: I Made Sulastra | C34: 20171 | D34: =VLOOKUP(A34,[1]Worksheet!$A$2:$I$423,4,0) -> 0 | E34: =VLOOKUP(A34,[1]Worksheet!$A$2:$I$423,5,0) -> 0 | F34: =VLOOKUP(A34,[1]Worksheet!$A$2:$I$423,6,0) -> 166 | G34: =VLOOKUP(A34,[1]Worksheet!$A$2:$I$423,7,0) -> 2.75 | K34: 4 | M34: =D34*E34 -> 0 | N34: =F34*G34 -> 456.5 | P34: =K34+D34 -> 4 | Q34: =M34/P34 -> 0 | R34: =F34+K34 -> 170 | S34: =N34/R34 -> 2.6852941
A35: F1B111030 | B35: Islahudin | C35: 20171 | D35: =VLOOKUP(A35,[1]Worksheet!$A$2:$I$423,4,0) -> 15 | E35: =VLOOKUP(A35,[1]Worksheet!$A$2:$I$423,5,0) -> 0 | F35: =VLOOKUP(A35,[1]Worksheet!$A$2:$I$423,6,0) -> 192 | G35: =VLOOKUP(A35,[1]Worksheet!$A$2:$I$423,7,0) -> 1.65 | K35: 9 | M35: =D35*E35 -> 0 | N35: =F35*G35 -> 316.8 | P35: =K35+D35 -> 24 | Q35: =M35/P35 -> 0 | R35: =F35+K35 -> 201 | S35: =N35/R35 -> 1.5761194
A36: F1B111031 | B36: Ita Isnawati | C36: 20171 | D36: =VLOOKUP(A36,[1]Worksheet!$A$2:$I$423,4,0) -> 4 | E36: =VLOOKUP(A36,[1]Worksheet!$A$2:$I$423,5,0) -> 3.5 | F36: =VLOOKUP(A36,[1]Worksheet!$A$2:$I$423,6,0) -> 157 | G36: =VLOOKUP(A36,[1]Worksheet!$A$2:$I$423,7,0) -> 3.12 | M36: =D36*E36 -> 14 | N36: =F36*G36 -> 489.84 | P36: =K36+D36 -> 4 | Q36: =M36/P36 -> 3.5 | R36: =F36+K36 -> 157 | S36: =N36/R36 -> 3.12
A37: F1B111033 | B37: Jumait | C37: 20171 | D37: =VLOOKUP(A37,[1]Worksheet!$A$2:$I$423,4,0) -> 6 | E37: =VLOOKUP(A37,[1]Worksheet!$A$2:$I$423,5,0) -> 1.83 | F37: =VLOOKUP(A37,[1]Worksheet!$A$2:$I$423,6,0) -> 177 | G37: =VLOOKUP(A37,[1]Worksheet!$A$2:$I$423,7,0) -> 2.12 | K37: 4 | M37: =D37*E37 -> 10.98 | N37: =F37*G37 -> 375.24 | P37: =K37+D37 -> 10 | Q37: =M37/P37 -> 1.098 | R37: =F37+K37 -> 181 | S37: =N37/R37 -> 2.0731492
A38: F1B111034 | B38: Jusman Alfian Sofian | C38: 20171 | D38: =VLOOKUP(A38,[1]Worksheet!$A$2:$I$423,4,0) -> 0 | E38: =VLOOKUP(A38,[1]Worksheet!$A$2:$I$423,5,0) -> 0 | F38: =VLOOKUP(A38,[1]Worksheet!$A$2:$I$423,6,0) -> 206 | G38: =VLOOKUP(A38,[1]Worksheet!$A$2:$I$423,7,0) -> 2.05 | K38: 4 | M38: =D38*E38 -> 0 | N38: =F38*G38 -> 422.3 | P38: =K38+D38 -> 4 | Q38: =M38/P38 -> 0 | R38: =F38+K38 -> 210 | S38: =N38/R38 -> 2.0109524
A39: F1B111036 | B39: Lalu Anja Sukmana | C39: 20171 | D39: =VLOOKUP(A39,[1]Worksheet!$A$2:$I$423,4,0) -> 24 | E39: =VLOOKUP(A39,[1]Worksheet!$A$2:$I$423,5,0) -> 2.06 | F39: =VLOOKUP(A39,[1]Worksheet!$A$2:$I$423,6,0) -> 155 | G39: =VLOOKUP(A39,[1]Worksheet!$A$2:$I$423,7,0) -> 1.92 | M39: =D39*E39 -> 49.44 | N39: =F39*G39 -> 297.6 | P39: =K39+D39 -> 24 | Q39: =M39/P39 -> 2.06 | R39: =F39+K39 -> 155 | S39: =N39/R39 -> 1.92
A40: F1B111039 | B40: Lina Usmiati | C40: 20171 | D40: =VLOOKUP(A40,[1]Worksheet!$A$2:$I$423,4,0) -> 0 | E40: =VLOOKUP(A40,[1]Worksheet!$A$2:$I$423,5,0) -> 0 | F40: =VLOOKUP(A40,[1]Worksheet!$A$2:$I$423,6,0) -> 159 | G40: =VLOOKUP(A40,[1]Worksheet!$A$2:$I$423,7,0) -> 3.06 | K40: 4 | M40: =D40*E40 -> 0 | N40: =F40*G40 -> 486.54 | P40: =K40+D40 -> 4 | Q40: =M40/P40 -> 0 | R40: =F40+K40 -> 163 | S40: =N40/R40 -> 2.984908
...

Sheet nILAI T
A2: F1B110010 | B2: GHAZI AKBAR | C2: ES4143 | D2: PRAKTEK KERJA LAPANGAN | E2: 20171 | F2: S | G2: T | L2: F1B110010 | M2: GHAZI AKBAR | N2: 6
A3: F1B110010 | B3: GHAZI AKBAR | C3: ES4248 | D3: TUGAS AKHIR | E3: 20171 | F3: S | G3: T | L3: F1B110018 | M3: SAMSUL HADI | N3: 4
A4: F1B110018 | B4: SAMSUL HADI | C4: ES4248 | D4: TUGAS AKHIR | E4: 20171 | F4: S | G4: T | L4: F1B110068 | M4: SUPARLAN ARDYANSYAH | N4: 6
A5: F1B110068 | B5: SUPARLAN ARDYANSYAH | C5: ES4143 | D5: PRAKTEK KERJA LAPANGAN | E5: 20171 | F5: S | G5: T | L5: F1B110076 | M5: LALU ARDYPATI | N5: 4
A6: F1B110068 | B6: SUPARLAN ARDYANSYAH | C6: ES4248 | D6: TUGAS AKHIR | E6: 20171 | F6: S | G6: T | L6: F1B111002 | M6: Agus Budi Nurcahyono | N6: 4
A7: F1B110076 | B7: LALU ARDYPATI | C7: ES4248 | D7: TUGAS AKHIR | E7: 20171 | F7: S | G7: T | L7: F1B111006 | M7: Alfan Aditya | N7: 4
A8: F1B111002 | B8: Agus Budi Nurcahyono | C8: ES4248 | D8: TUGAS AKHIR | E8: 20171 | F8: S | G8: T | L8: F1B111007 | M8: Andika Nugraha | N8: 4
A9: F1B111006 | B9: Alfan Aditya | C9: ES4248 | D9: TUGAS AKHIR | E9: 20171 | F9: S | G9: T | L9: F1B111008 | M9: Arif Hidayatullah | N9: 4
A10: F1B111007 | B10: Andika Nugraha | C10: ES4248 | D10: TUGAS AKHIR | E10: 20171 | F10: S | G10: T | L10: F1B111021 | M10: Haerurrozi | N10: 4
A11: F1B111008 | B11: Arif Hidayatullah | C11: ES4248 | D11: TUGAS AKHIR | E11: 20171 | F11: S | G11: T | L11: F1B111027 | M11: I Made Sulastra | N11: 4
A12: F1B111021 | B12: Haerurrozi | C12: ES4248 | D12: TUGAS AKHIR | E12: 20171 | F12: S | G12: T | L12: F1B111030 | M12: Islahudin | N12: 9
A13: F1B111027 | B13: I Made Sulastra | C13: ES4248 | D13: TUGAS AKHIR | E13: 20171 | F13: S | G13: T | L13: F1B111033 | M13: Jumait | N13: 4
... A61: F1B114018 | B61: I GUSTI BAGUS HENDRA PRADIPTA | C61: ES4245 | D61: KULIAH KERJA NYATA (KKN) | E61: 20171 | F61: S | G61: T | L61: F1B116006 | M61: HAQRULLOH | N61: 1
A62: F1B114022 | B62: JUWITA ASRI | C62: ES4245 | D62: KULIAH KERJA NYATA (KKN) | E62: 20171 | F62: S | G62: T
A63: F1B114027 | B63: MUHAMMAD FEBRIAN RAMADAN | C63: ES4245 | D63: KULIAH KERJA NYATA (KKN) | E63: 20171 | F63: S | G63: T
A64: F1B114030 | B64: PUTRA RAHMAT RAMADAN | C64: ES4245 | D64: KULIAH KERJA NYATA (KKN) | E64: 20171 | F64: S | G64: T
A65: F1B115019 | B65: Jumriati | C65: EA3103 | D65: PEMBANGKIT TENAGA LISTRIK | E65: 20171 | F65: S | G65: T
A66: F1B116003 | B66: DONI PRANATA | C66: ES2123 | D66: PRAKTIKUM PENGUKURAN BESARAN LISTRIK | E66: 20171 | F66: S | G66: T
A67: F1B116006 | B67: HAQRULLOH | C67: ES2123 | D67: PRAKTIKUM PENGUKURAN BESARAN LISTRIK | E67: 20171 | F67: S | G67: T

Sheet rEKAP kls MK
A2: =VLOOKUP(B2,[2]Sheet1!$D$5:$L$185,9,0) -> ES1215 | B2: ALGORITMA DAN PEMROGRAMAN | C2: S | D2: =COUNTIF(Worksheet!$D$2:$D$1267,B2) -> 38 | E2: 7 | F2: =VLOOKUP(E2,[3]Sheet2!$A$6:$F$43,4,0) -> 0005106805 | G2: =VLOOKUP(E2,[3]Sheet2!$A$6:$F$43,6,0) -> Misbahuddin, ST., MT. | H2: 1 | I2: =VLOOKUP(A2,Worksheet!$C$2:$D$1267,2,0) -> ALGORITMA DAN PEMROGRAMAN | J2: =IF(B2=I2,1,0) -> 1
A3: =VLOOKUP(B3,[2]Sheet1!$D$5:$L$185,9,0) -> EA3101 | B3: ANALISA SISTEM TENAGA I | C3: S | D3: =COUNTIF(Worksheet!$D$2:$D$1267,B3) -> 10 | E3: 24 | F3: =VLOOKUP(E3,[3]Sheet2!$A$6:$F$43,4,0) -> 0004047303 | G3: =VLOOKUP(E3,[3]Sheet2!$A$6:$F$43,6,0) -> I Made Ari Nrartha, ST., MT. | H3: =H2+1 -> 2 | I3: =VLOOKUP(A3,Worksheet!$C$2:$D$1267,2,0) -> ANALISA SISTEM TENAGA I | J3: =IF(B3=I3,1,0) -> 1
A4: =VLOOKUP(B4,[2]Sheet1!$D$5:$L$185,9,0) -> ED3102 | B4: BASIS DATA | C4: S | D4: =COUNTIF(Worksheet!$D$2:$D$1267,B4) -> 16 | E4: 35 | F4: =VLOOKUP(E4,[3]Sheet2!$A$6:$F$43,4,0) -> 0010038303 | G4: =VLOOKUP(E4,[3]Sheet2!$A$6:$F$43,6,0) -> L. A. Syamsul Irfan Akbar, ST., M.Eng. | H4: =H3+1 -> 3 | I4: =VLOOKUP(A4,Worksheet!$C$2:$D$1267,2,0) -> BASIS DATA | J4: =IF(B4=I4,1,0) -> 1
A5: =VLOOKUP(B5,[2]Sheet1!$D$5:$L$185,9,0) -> ES2124 | B5: DASAR ELEKTRONIKA | C5: S | D5: =COUNTIF(Worksheet!$D$2:$D$1267,B5) -> 35 | E5: 26 | F5: =VLOOKUP(E5,[3]Sheet2!$A$6:$F$43,4,0) -> 0023077104 | G5: =VLOOKUP(E5,[3]Sheet2!$A$6:$F$43,6,0) -> Paniran, ST., MT. | H5: =H4+1 -> 4 | I5: =VLOOKUP(A5,Worksheet!$C$2:$D$1267,2,0) -> DASAR ELEKTRONIKA | J5: =IF(B5=I5,1,0) -> 1
A6: =VLOOKUP(B6,[2]Sheet1!$D$5:$L$185,9,0) -> ES1108 | B6: DASAR TEKNOLOGI INFORMASI | C6: S | D6: =COUNTIF(Worksheet!$D$2:$D$1267,B6) -> 38 | E6: 35 | F6: =VLOOKUP(E6,[3]Sheet2!$A$6:$F$43,4,0) -> 0010038303 | G6: =VLOOKUP(E6,[3]Sheet2!$A$6:$F$43,6,0) -> L. A. Syamsul Irfan Akbar, ST., M.Eng. | H6: =H5+1 -> 5 | I6: =VLOOKUP(A6,Worksheet!$C$2:$D$1267,2,0) -> DASAR TEKNOLOGI INFORMASI | J6: =IF(B6=I6,1,0) -> 1
A7: =VLOOKUP(B7,[2]Sheet1!$D$5:$L$185,9,0) -> ES2125 | B7: DASAR TENAGA LISTRIK | C7: S | D7: =COUNTIF(Worksheet!$D$2:$D$1267,B7) -> 33 | E7: 12 | F7: =VLOOKUP(E7,[3]Sheet2!$A$6:$F$43,4,0) -> 0026027405 | G7: =VLOOKUP(E7,[3]Sheet2!$A$6:$F$43,6,0) -> Ida Bagus Fery Citarsa, ST., MT. | H7: =H6+1 -> 6 | I7: =VLOOKUP(A7,Worksheet!$C$2:$D$1267,2,0) -> DASAR TENAGA LISTRIK | J7: =IF(B7=I7,1,0) -> 1
A8: =VLOOKUP(B8,[2]Sheet1!$D$5:$L$185,9,0) -> ES2125 | B8: DASAR TENAGA LISTRIK | C8: S | D8: =COUNTIF(Worksheet!$D$2:$D$1267,B8) -> 33 | E8: 13 | F8: =VLOOKUP(E8,[3]Sheet2!$A$6:$F$43,4,0) -> 0011027105 | G8: =VLOOKUP(E8,[3]Sheet2!$A$6:$F$43,6,0) -> Agung Budi Muljono, ST., MT. | H8: =H7+1 -> 7 | I8: =VLOOKUP(A8,Worksheet!$C$2:$D$1267,2,0) -> DASAR TENAGA LISTRIK | J8: =IF(B8=I8,1,0) -> 1
A9: =VLOOKUP(B9,[2]Sheet1!$D$5:$L$185,9,0) -> ES2233 | B9: EKONOMI TEKNIK | C9: S | D9: =COUNTIF(Worksheet!$D$2:$D$1267,B9) -> 22 | E9: 5 | F9: =VLOOKUP(E9,[3]Sheet2!$A$6:$F$43,4,0) -> 0031126704 | G9: =VLOOKUP(E9,[3]Sheet2!$A$6:$F$43,6,0) -> Sultan, ST., MT. | H9: =H8+1 -> 8 | I9: =VLOOKUP(A9,Worksheet!$C$2:$D$1267,2,0) -> EKONOMI TEKNIK | J9: =IF(B9=I9,1,0) -> 1
A10: =VLOOKUP(B10,[2]Sheet1!$D$5:$L$185,9,0) -> ES2233 | B10: EKONOMI TEKNIK | C10: S | D10: =COUNTIF(Worksheet!$D$2:$D$1267,B10) -> 22 | E10: 10 | F10: =VLOOKUP(E10,[3]Sheet2!$A$6:$F$43,4,0) -> 0023087003 | G10: =VLOOKUP(E10,[3]Sheet2!$A$6:$F$43,6,0) -> Dr. Ida Ayu Sri Adnyani, ST., MErg. | H10: =H9+1 -> 9 | I10: =VLOOKUP(A10,Worksheet!$C$2:$D$1267,2,0) -> EKONOMI TEKNIK | J10: =IF(B10=I10,1,0) -> 1
A11: =VLOOKUP(B11,[2]Sheet1!$D$5:$L$185,9,0) -> EA4115 | B11: ELEKTRONIKA DAYA | C11: S | D11: =COUNTIF(Worksheet!$D$2:$D$1267,B11) -> 8 | E11: 8 | F11: =VLOOKUP(E11,[3]Sheet2!$A$6:$F$43,4,0) -> 0008097004 | G11: =VLOOKUP(E11,[3]Sheet2!$A$6:$F$43,6,0) -> I Nyoman Wahyu S., ST., M.Sc., Ph.D. | H11: =H10+1 -> 10 | I11: =VLOOKUP(A11,Worksheet!$C$2:$D$1267,2,0) -> ELEKTRONIKA DAYA | J11: =IF(B11=I11,1,0) -> 1
A12: =VLOOKUP(B12,[2]Sheet1!$D$5:$L$185,9,0) -> EA4004 | B12: KECERDASAN BUATAN DALAM STL | C12: S | D12: =COUNTIF(Worksheet!$D$2:$D$1267,B12) -> 12 | E12: 14 | F12: =VLOOKUP(E12,[3]Sheet2!$A$6:$F$43,4,0) -> 0009057201 | G12: =VLOOKUP(E12,[3]Sheet2!$A$6:$F$43,6,0) -> Abdul Natsir, ST., MT. | H12: =H11+1 -> 11 | I12: =VLOOKUP(A12,Worksheet!$C$2:$D$1267,2,0) -> KECERDASAN BUATAN DALAM STL | J12: =IF(B12=I12,1,0) -> 1
A13: =VLOOKUP(B13,[2]Sheet1!$D$5:$L$185,9,0) -> EA4112 | B13: MANAJEMEN OPERASI SISTEM TENAGA | C13: S | D13: =COUNTIF(Worksheet!$D$2:$D$1267,B13) -> 12 | E13: 24 | F13: =VLOOKUP(E13,[3]Sheet2!$A$6:$F$43,4,0) -> 0004047303 | G13: =VLOOKUP(E13,[3]Sheet2!$A$6:$F$43,6,0) -> I Made Ari Nrartha, ST., MT. | H13: =H12+1 -> 12 | I13: =VLOOKUP(A13,Worksheet!$C$2:$D$1267,2,0) -> MANAJEMEN OPERASI SISTEM TENAGA | J13: =IF(B13=I13,1,0) -> 1
A14: =VLOOKUP(B14,[2]Sheet1!$D$5:$L$185,9,0) -> ED3101 | B14: MATEMATIKA DISKRIT | C14: S | D14: =COUNTIF(Worksheet!$D$2:$D$1267,B14) -> 15 | E14: 7 | F14: =VLOOKUP(E14,[3]Sheet2!$A$6:$F$43,4,0) -> 0005106805 | G14: =VLOOKUP(E14,[3]Sheet2!$A$6:$F$43,6,0) -> Misbahuddin, ST., MT. | H14: =H13+1 -> 13 | I14: =VLOOKUP(A14,Worksheet!$C$2:$D$1267,2,0) -> MATEMATIKA DISKRIT | J14: =IF(B14=I14,1,0) -> 1
... A35: =VLOOKUP(B35,[2]Sheet1!$D$5:$L$185,9,0) -> EA3104 | B35: TRANSMISI TENAGA LISTRIK | C35: S | D35: =COUNTIF(Worksheet!$D$2:$D$1267,B35) -> 11 | E35: 13 | F35: =VLOOKUP(E35,[3]Sheet2!$A$6:$F$43,4,0) -> 0011027105 | G35: =VLOOKUP(E35,[3]Sheet2!$A$6:$F$43,6,0) -> Agung Budi Muljono, ST., MT. | H35: =H34+1 -> 34 | I35: =VLOOKUP(A35,Worksheet!$C$2:$D$1267,2,0) -> TRANSMISI TENAGA LISTRIK | J35: =IF(B35=I35,1,0) -> 1
A36: =VLOOKUP(B36,[2]Sheet1!$D$5:$L$185,9,0) -> ED4013 | B36: TEKNIK NEURO FUZZY | C36: P | D36: =COUNTIF(Worksheet!$D$2:$D$1267,B36) -> 4 | I36: =VLOOKUP(A36,Worksheet!$C$2:$D$1267,2,0) -> TEKNIK NEURO FUZZY | J36: =IF(B36=I36,1,0) -> 1
A37: =VLOOKUP(B37,[2]Sheet1!$D$5:$L$185,9,0) -> EA4002 | B37: GEJALA MEDAN TINGGI | C37: P | D37: =COUNTIF(Worksheet!$D$2:$D$1267,B37) -> 3 | I37: =VLOOKUP(A37,Worksheet!$C$2:$D$1267,2,0) -> GEJALA MEDAN TINGGI | J37: =IF(B37=I37,1,0) -> 1
A38: =VLOOKUP(B38,[2]Sheet1!$D$5:$L$185,9,0) -> EB4115 | B38: TEKNIK KENDALI DIGITAL | C38: P | D38: =COUNTIF(Worksheet!$D$2:$D$1267,B38) -> 3 | I38: =VLOOKUP(A38,Worksheet!$C$2:$D$1267,2,0) -> TEKNIK KENDALI DIGITAL | J38: =IF(B38=I38,1,0) -> 1
A39: =VLOOKUP(B39,[2]Sheet1!$D$5:$L$185,9,0) -> EB3103 | B39: ELEKTRONIKA DIGITAL | C39: P | D39: =COUNTIF(Worksheet!$D$2:$D$1267,B39) -> 2 | I39: =VLOOKUP(A39,Worksheet!$C$2:$D$1267,2,0) -> ELEKTRONIKA DIGITAL | J39: =IF(B39=I39,1,0) -> 1
A40: =VLOOKUP(B40,[2]Sheet1!$D$5:$L$185,9,0) -> EB4112 | B40: PERANCANGAN SISTEM ELEKTRONIKA | C40: P | D40: =COUNTIF(Worksheet!$D$2:$D$1267,B40) -> 2 | I40: =VLOOKUP(A40,Worksheet!$C$2:$D$1267,2,0) -> PERANCANGAN SISTEM ELEKTRONIKA | J40: =IF(B40=I40,1,0) -> 1
A41: =VLOOKUP(B41,[2]Sheet1!$D$5:$L$185,9,0) -> EB3105 | B41: ELEKTRONIKA ANALOG | C41: P | D41: =COUNTIF(Worksheet!$D$2:$D$1267,B41) -> 1 | I41: =VLOOKUP(A41,Worksheet!$C$2:$D$1267,2,0) -> ELEKTRONIKA ANALOG | J41: =IF(B41=I41,1,0) -> 1
A42: =VLOOKUP(B42,[2]Sheet1!$D$5:$L$185,9,0) -> EB4003 | B42: JARINGAN SYARAF TIRUAN | C42: P | D42: =COUNTIF(Worksheet!$D$2:$D$1267,B42) -> 1 | I42: =VLOOKUP(A42,Worksheet!$C$2:$D$1267,2,0) -> JARINGAN SYARAF TIRUAN | J42: =IF(B42=I42,1,0) -> 1
A43: =VLOOKUP(B43,[2]Sheet1!$D$5:$L$185,9,0) -> EB4007 | B43: PENGOLAHAN CITRA DIGITAL | C43: P | D43: =COUNTIF(Worksheet!$D$2:$D$1267,B43) -> 1 | I43: =VLOOKUP(A43,Worksheet!$C$2:$D$1267,2,0) -> PENGOLAHAN CITRA DIGITAL | J43: =IF(B43=I43,1,0) -> 1
A44: =VLOOKUP(B44,[2]Sheet1!$D$5:$L$185,9,0) -> EB3101 | B44: RANGKAIAN ELEKTRONIKA | C44: P | D44: =COUNTIF(Worksheet!$D$2:$D$1267,B44) -> 1 | I44: =VLOOKUP(A44,Worksheet!$C$2:$D$1267,2,0) -> RANGKAIAN ELEKTRONIKA | J44: =IF(B44=I44,1,0) -> 1
A45: =VLOOKUP(B45,[2]Sheet1!$D$5:$L$185,9,0) -> EC3102 | B45: SISTEM TELEKOMUNIKASI | C45: P | D45: =COUNTIF(Worksheet!$D$2:$D$1267,B45) -> 1 | I45: =VLOOKUP(A45,Worksheet!$C$2:$D$1267,2,0) -> SISTEM TELEKOMUNIKASI | J45: =IF(B45=I45,1,0) -> 1
A46: =VLOOKUP(B46,[2]Sheet1!$D$5:$L$185,9,0) -> ED4010 | B46: PROYEK PERANGKAT LUNAK | C46: P | D46: =COUNTIF(Worksheet!$D$2:$D$1267,B46) -> 6 | I46: =VLOOKUP(A46,Worksheet!$C$2:$D$1267,2,0) -> PROYEK PERANGKAT LUNAK | J46: =IF(B46=I46,1,0) -> 1
A47: =VLOOKUP(B47,[2]Sheet1!$D$5:$L$185,9,0) -> ES4248 | B47: TUGAS AKHIR | C47: R | D47: =COUNTIF(Worksheet!$D$2:$D$1267,B47) -> 75 | I47: =VLOOKUP(A47,Worksheet!$C$2:$D$1267,2,0) -> TUGAS AKHIR | J47: =IF(B47=I47,1,0) -> 1
... A53: =VLOOKUP(B53,[2]Sheet1!$D$5:$L$185,9,0) -> ES4143 | B53: PRAKTEK KERJA LAPANGAN | C53: R | D53: =COUNTIF(Worksheet!$D$2:$D$1267,B53) -> 16 | I53: =VLOOKUP(A53,Worksheet!$C$2:$D$1267,2,0) -> PRAKTEK KERJA LAPANGAN | J53: =IF(B53=I53,1,0) -> 1
A54: EA4114 | B54: PRAK. PROTEKSI SISTEM TENAGA | C54: R | D54: =COUNTIF(Worksheet!$D$2:$D$1267,B54) -> 11 | I54: =VLOOKUP(A54,Worksheet!$C$2:$D$1267,2,0) -> PRAK. PROTEKSI SISTEM TENAGA | J54: =IF(B54=I54,1,0) -> 1
A55: EA4117 | B55: PRAK. TRANSMISI & DISTRIBUSI | C55: R | D55: =COUNTIF(Worksheet!$D$2:$D$1267,B55) -> 10 | I55: =VLOOKUP(A55,Worksheet!$C$2:$D$1267,2,0) -> PRAK. TRANSMISI & DISTRIBUSI | J55: =IF(B55=I55,1,0) -> 1
A56: =VLOOKUP(B56,[2]Sheet1!$D$5:$L$185,9,0) -> ED4112 | B56: PRAKTIKUM ALGORITMA DAN STRUKTUR DATA | C56: R | D56: =COUNTIF(Worksheet!$D$2:$D$1267,B56) -> 10 | I56: =VLOOKUP(A56,Worksheet!$C$2:$D$1267,2,0) -> PRAKTIKUM ALGORITMA DAN STRUKTUR DATA | J56: =IF(B56=I56,1,0) -> 1
A57: =VLOOKUP(B57,[2]Sheet1!$D$5:$L$185,9,0) -> ED4113 | B57: PRAKTIKUM BASIS DATA | C57: R | D57: =COUNTIF(Worksheet!$D$2:$D$1267,B57) -> 10 | I57: =VLOOKUP(A57,Worksheet!$C$2:$D$1267,2,0) -> PRAKTIKUM BASIS DATA | J57: =IF(B57=I57,1,0) -> 1
A58: =VLOOKUP(B58,[2]Sheet1!$D$5:$L$185,9,0) -> ED4114 | B58: PRAKTIKUM JARINGAN KOMPUTER | C58: R | D58: =COUNTIF(Worksheet!$D$2:$D$1267,B58) -> 10 | I58: =VLOOKUP(A58,Worksheet!$C$2:$D$1267,2,0) -> PRAKTIKUM JARINGAN KOMPUTER | J58: =IF(B58=I58,1,0) -> 1
A59: EA4116 | B59: PRAK. ELEKTRONIKA DAYA | C59: R | D59: =COUNTIF(Worksheet!$D$2:$D$1267,B59) -> 6 | I59: =VLOOKUP(A59,Worksheet!$C$2:$D$1267,2,0) -> PRAK. ELEKTRONIKA DAYA | J59: =IF(B59=I59,1,0) -> 1
A60: =VLOOKUP(B60,[2]Sheet1!$D$5:$L$185,9,0) -> EB3104 | B60: PRAKTIKUM ELEKTRONIKA DIGITAL | C60: R | D60: =COUNTIF(Worksheet!$D$2:$D$1267,B60) -> 2 | I60: =VLOOKUP(A60,Worksheet!$C$2:$D$1267,2,0) -> PRAKTIKUM ELEKTRONIKA DIGITAL | J60: =IF(B60=I60,1,0) -> 1
A61: =VLOOKUP(B61,[2]Sheet1!$D$5:$L$185,9,0) -> EB3102 | B61: PRAKTIKUM RANGKAIAN ELEKTRONIKA | C61: R | D61: =COUNTIF(Worksheet!$D$2:$D$1267,B61) -> 2 | I61: =VLOOKUP(A61,Worksheet!$C$2:$D$1267,2,0) -> PRAKTIKUM RANGKAIAN ELEKTRONIKA | J61: =IF(B61=I61,1,0) -> 1
A62: =VLOOKUP(B62,[2]Sheet1!$D$5:$L$185,9,0) -> EB4113 | B62: PRAKTIKUM PENGOLAHAN SINYAL DIGITAL | C62: R | D62: =COUNTIF(Worksheet!$D$2:$D$1267,B62) -> 1 | I62: =VLOOKUP(A62,Worksheet!$C$2:$D$1267,2,0) -> PRAKTIKUM PENGOLAHAN SINYAL DIGITAL | J62: =IF(B62=I62,1,0) -> 1
A63: =VLOOKUP(B63,[2]Sheet1!$D$5:$L$185,9,0) -> EC4114 | B63: PRAKTIKUM SISTEM TELEKOMUNIKASI | C63: R | D63: =COUNTIF(Worksheet!$D$2:$D$1267,B63) -> 1 | I63: =VLOOKUP(A63,Worksheet!$C$2:$D$1267,2,0) -> PRAKTIKUM SISTEM TELEKOMUNIKASI | J63: =IF(B63=I63,1,0) -> 1
B64: FISIKA DASAR | C64: TPB | D64: =COUNTIF(Worksheet!$D$2:$D$1267,B64) -> 50 | J64: =IF(B64=I64,1,0) -> 0
B65: BAHASA INGGRIS I | C65: TPB | D65: =COUNTIF(Worksheet!$D$2:$D$1267,B65) -> 48 | J65: =IF(B65=I65,1,0) -> 0
B66: MATEMATIKA DASAR | C66: TPB | D66: =COUNTIF(Worksheet!$D$2:$D$1267,B66) -> 47 | J66: =IF(B66=I66,1,0) -> 0
...
